[2025-01-25T17:09:42.657+0000] {local_task_job_runner.py:123} INFO - ::group::Pre task execution logs
[2025-01-25T17:09:42.821+0000] {taskinstance.py:2613} INFO - Dependencies all met for dep_context=non-requeueable deps ti=<TaskInstance: fetch_and_store_ebooks.create_table scheduled__2025-01-04T00:00:00+00:00 [queued]>
[2025-01-25T17:09:42.893+0000] {taskinstance.py:2613} INFO - Dependencies all met for dep_context=requeueable deps ti=<TaskInstance: fetch_and_store_ebooks.create_table scheduled__2025-01-04T00:00:00+00:00 [queued]>
[2025-01-25T17:09:42.903+0000] {taskinstance.py:2866} INFO - Starting attempt 2 of 2
[2025-01-25T17:09:43.105+0000] {taskinstance.py:2889} INFO - Executing <Task(PostgresOperator): create_table> on 2025-01-04 00:00:00+00:00
[2025-01-25T17:09:43.151+0000] {warnings.py:112} WARNING - /home/***/.local/lib/python3.12/site-packages/***/task/task_runner/standard_task_runner.py:70: DeprecationWarning: This process (pid=3922) is multi-threaded, use of fork() may lead to deadlocks in the child.
  pid = os.fork()

[2025-01-25T17:09:43.186+0000] {standard_task_runner.py:72} INFO - Started process 3949 to run task
[2025-01-25T17:09:43.173+0000] {standard_task_runner.py:104} INFO - Running: ['***', 'tasks', 'run', 'fetch_and_store_ebooks', 'create_table', 'scheduled__2025-01-04T00:00:00+00:00', '--job-id', '480', '--raw', '--subdir', 'DAGS_FOLDER/app.py', '--cfg-path', '/tmp/tmphl9jdis2']
[2025-01-25T17:09:43.246+0000] {standard_task_runner.py:105} INFO - Job 480: Subtask create_table
[2025-01-25T17:09:47.436+0000] {task_command.py:467} INFO - Running <TaskInstance: fetch_and_store_ebooks.create_table scheduled__2025-01-04T00:00:00+00:00 [running]> on host 50ab235b552a
[2025-01-25T17:09:48.972+0000] {taskinstance.py:3132} INFO - Exporting env vars: AIRFLOW_CTX_DAG_OWNER='***' AIRFLOW_CTX_DAG_ID='fetch_and_store_ebooks' AIRFLOW_CTX_TASK_ID='create_table' AIRFLOW_CTX_EXECUTION_DATE='2025-01-04T00:00:00+00:00' AIRFLOW_CTX_TRY_NUMBER='2' AIRFLOW_CTX_DAG_RUN_ID='scheduled__2025-01-04T00:00:00+00:00'
[2025-01-25T17:09:48.984+0000] {logging_mixin.py:190} INFO - Task instance is in running state
[2025-01-25T17:09:49.001+0000] {logging_mixin.py:190} INFO -  Previous state of the Task instance: queued
[2025-01-25T17:09:49.011+0000] {logging_mixin.py:190} INFO - Current task name:create_table state:running start_date:2025-01-25 17:09:42.826353+00:00
[2025-01-25T17:09:49.022+0000] {logging_mixin.py:190} INFO - Dag name:fetch_and_store_ebooks and current dag run status:running
[2025-01-25T17:09:49.028+0000] {taskinstance.py:731} INFO - ::endgroup::
[2025-01-25T17:09:49.033+0000] {sql.py:278} INFO - Executing: 
    CREATE TABLE IF NOT EXISTS ebooks (
        id SERIAL PRIMARY KEY,
        judul TEXT NOT NULL,
        penulis TEXT,
        link TEXT
    );
    
[2025-01-25T17:09:49.109+0000] {base.py:84} INFO - Retrieving connection 'ebooks_connection'
[2025-01-25T17:09:49.192+0000] {base.py:84} INFO - Retrieving connection 'ebooks_connection'
[2025-01-25T17:09:49.269+0000] {taskinstance.py:3311} ERROR - Task failed with exception
Traceback (most recent call last):
  File "/home/airflow/.local/lib/python3.12/site-packages/airflow/models/taskinstance.py", line 767, in _execute_task
    result = _execute_callable(context=context, **execute_callable_kwargs)
             ^^^^^^^^^^^^^^^^^^^^^^^^^^^^^^^^^^^^^^^^^^^^^^^^^^^^^^^^^^^^^
  File "/home/airflow/.local/lib/python3.12/site-packages/airflow/models/taskinstance.py", line 733, in _execute_callable
    return ExecutionCallableRunner(
           ^^^^^^^^^^^^^^^^^^^^^^^^
  File "/home/airflow/.local/lib/python3.12/site-packages/airflow/utils/operator_helpers.py", line 252, in run
    return self.func(*args, **kwargs)
           ^^^^^^^^^^^^^^^^^^^^^^^^^^
  File "/home/airflow/.local/lib/python3.12/site-packages/airflow/models/baseoperator.py", line 422, in wrapper
    return func(self, *args, **kwargs)
           ^^^^^^^^^^^^^^^^^^^^^^^^^^^
  File "/home/airflow/.local/lib/python3.12/site-packages/airflow/providers/common/sql/operators/sql.py", line 284, in execute
    output = hook.run(
             ^^^^^^^^^
  File "/home/airflow/.local/lib/python3.12/site-packages/airflow/providers/common/sql/hooks/sql.py", line 494, in run
    with self._create_autocommit_connection(autocommit) as conn:
         ^^^^^^^^^^^^^^^^^^^^^^^^^^^^^^^^^^^^^^^^^^^^^^
  File "/usr/local/lib/python3.12/contextlib.py", line 137, in __enter__
    return next(self.gen)
           ^^^^^^^^^^^^^^
  File "/home/airflow/.local/lib/python3.12/site-packages/airflow/providers/common/sql/hooks/sql.py", line 618, in _create_autocommit_connection
    with closing(self.get_conn()) as conn:
                 ^^^^^^^^^^^^^^^
  File "/home/airflow/.local/lib/python3.12/site-packages/airflow/providers/postgres/hooks/postgres.py", line 189, in get_conn
    self.conn = psycopg2.connect(**conn_args)
                ^^^^^^^^^^^^^^^^^^^^^^^^^^^^^
  File "/home/airflow/.local/lib/python3.12/site-packages/psycopg2/__init__.py", line 122, in connect
    conn = _connect(dsn, connection_factory=connection_factory, **kwasync)
           ^^^^^^^^^^^^^^^^^^^^^^^^^^^^^^^^^^^^^^^^^^^^^^^^^^^^^^^^^^^^^^^
psycopg2.OperationalError: connection to server at "localhost" (::1), port 5432 failed: Connection refused
	Is the server running on that host and accepting TCP/IP connections?
connection to server at "localhost" (127.0.0.1), port 5432 failed: Connection refused
	Is the server running on that host and accepting TCP/IP connections?

[2025-01-25T17:09:49.627+0000] {logging_mixin.py:190} INFO - Task instance in failure state
[2025-01-25T17:09:49.631+0000] {logging_mixin.py:190} INFO - Task start:2025-01-25 17:09:42.826353+00:00 end:2025-01-25 17:09:49.624890+00:00 duration:6.798537
[2025-01-25T17:09:49.642+0000] {logging_mixin.py:190} INFO - Task:<Task(PostgresOperator): create_table> dag:<DAG: fetch_and_store_ebooks> dagrun:<DagRun fetch_and_store_ebooks @ 2025-01-04 00:00:00+00:00: scheduled__2025-01-04T00:00:00+00:00, state:running, queued_at: 2025-01-25 17:02:00.811963+00:00. externally triggered: False>
[2025-01-25T17:09:49.653+0000] {logging_mixin.py:190} INFO - Failure caused by connection to server at "localhost" (::1), port 5432 failed: Connection refused
	Is the server running on that host and accepting TCP/IP connections?
connection to server at "localhost" (127.0.0.1), port 5432 failed: Connection refused
	Is the server running on that host and accepting TCP/IP connections?
[2025-01-25T17:09:49.660+0000] {taskinstance.py:1225} INFO - Marking task as FAILED. dag_id=fetch_and_store_ebooks, task_id=create_table, run_id=scheduled__2025-01-04T00:00:00+00:00, execution_date=20250104T000000, start_date=20250125T170942, end_date=20250125T170949
[2025-01-25T17:09:49.995+0000] {taskinstance.py:340} INFO - ::group::Post task execution logs
[2025-01-25T17:09:50.019+0000] {standard_task_runner.py:124} ERROR - Failed to execute job 480 for task create_table (connection to server at "localhost" (::1), port 5432 failed: Connection refused
	Is the server running on that host and accepting TCP/IP connections?
connection to server at "localhost" (127.0.0.1), port 5432 failed: Connection refused
	Is the server running on that host and accepting TCP/IP connections?
; 3949)
Traceback (most recent call last):
  File "/home/airflow/.local/lib/python3.12/site-packages/airflow/task/task_runner/standard_task_runner.py", line 117, in _start_by_fork
    ret = args.func(args, dag=self.dag)
          ^^^^^^^^^^^^^^^^^^^^^^^^^^^^^
  File "/home/airflow/.local/lib/python3.12/site-packages/airflow/cli/cli_config.py", line 49, in command
    return func(*args, **kwargs)
           ^^^^^^^^^^^^^^^^^^^^^
  File "/home/airflow/.local/lib/python3.12/site-packages/airflow/utils/cli.py", line 116, in wrapper
    return f(*args, **kwargs)
           ^^^^^^^^^^^^^^^^^^
  File "/home/airflow/.local/lib/python3.12/site-packages/airflow/cli/commands/task_command.py", line 483, in task_run
    task_return_code = _run_task_by_selected_method(args, _dag, ti)
                       ^^^^^^^^^^^^^^^^^^^^^^^^^^^^^^^^^^^^^^^^^^^^
  File "/home/airflow/.local/lib/python3.12/site-packages/airflow/cli/commands/task_command.py", line 256, in _run_task_by_selected_method
    return _run_raw_task(args, ti)
           ^^^^^^^^^^^^^^^^^^^^^^^
  File "/home/airflow/.local/lib/python3.12/site-packages/airflow/cli/commands/task_command.py", line 341, in _run_raw_task
    return ti._run_raw_task(
           ^^^^^^^^^^^^^^^^^
  File "/home/airflow/.local/lib/python3.12/site-packages/airflow/utils/session.py", line 97, in wrapper
    return func(*args, session=session, **kwargs)
           ^^^^^^^^^^^^^^^^^^^^^^^^^^^^^^^^^^^^^^
  File "/home/airflow/.local/lib/python3.12/site-packages/airflow/models/taskinstance.py", line 3005, in _run_raw_task
    return _run_raw_task(
           ^^^^^^^^^^^^^^
  File "/home/airflow/.local/lib/python3.12/site-packages/airflow/models/taskinstance.py", line 273, in _run_raw_task
    TaskInstance._execute_task_with_callbacks(
  File "/home/airflow/.local/lib/python3.12/site-packages/airflow/models/taskinstance.py", line 3159, in _execute_task_with_callbacks
    result = self._execute_task(context, task_orig)
             ^^^^^^^^^^^^^^^^^^^^^^^^^^^^^^^^^^^^^^
  File "/home/airflow/.local/lib/python3.12/site-packages/airflow/models/taskinstance.py", line 3183, in _execute_task
    return _execute_task(self, context, task_orig)
           ^^^^^^^^^^^^^^^^^^^^^^^^^^^^^^^^^^^^^^^
  File "/home/airflow/.local/lib/python3.12/site-packages/airflow/models/taskinstance.py", line 767, in _execute_task
    result = _execute_callable(context=context, **execute_callable_kwargs)
             ^^^^^^^^^^^^^^^^^^^^^^^^^^^^^^^^^^^^^^^^^^^^^^^^^^^^^^^^^^^^^
  File "/home/airflow/.local/lib/python3.12/site-packages/airflow/models/taskinstance.py", line 733, in _execute_callable
    return ExecutionCallableRunner(
           ^^^^^^^^^^^^^^^^^^^^^^^^
  File "/home/airflow/.local/lib/python3.12/site-packages/airflow/utils/operator_helpers.py", line 252, in run
    return self.func(*args, **kwargs)
           ^^^^^^^^^^^^^^^^^^^^^^^^^^
  File "/home/airflow/.local/lib/python3.12/site-packages/airflow/models/baseoperator.py", line 422, in wrapper
    return func(self, *args, **kwargs)
           ^^^^^^^^^^^^^^^^^^^^^^^^^^^
  File "/home/airflow/.local/lib/python3.12/site-packages/airflow/providers/common/sql/operators/sql.py", line 284, in execute
    output = hook.run(
             ^^^^^^^^^
  File "/home/airflow/.local/lib/python3.12/site-packages/airflow/providers/common/sql/hooks/sql.py", line 494, in run
    with self._create_autocommit_connection(autocommit) as conn:
         ^^^^^^^^^^^^^^^^^^^^^^^^^^^^^^^^^^^^^^^^^^^^^^
  File "/usr/local/lib/python3.12/contextlib.py", line 137, in __enter__
    return next(self.gen)
           ^^^^^^^^^^^^^^
  File "/home/airflow/.local/lib/python3.12/site-packages/airflow/providers/common/sql/hooks/sql.py", line 618, in _create_autocommit_connection
    with closing(self.get_conn()) as conn:
                 ^^^^^^^^^^^^^^^
  File "/home/airflow/.local/lib/python3.12/site-packages/airflow/providers/postgres/hooks/postgres.py", line 189, in get_conn
    self.conn = psycopg2.connect(**conn_args)
                ^^^^^^^^^^^^^^^^^^^^^^^^^^^^^
  File "/home/airflow/.local/lib/python3.12/site-packages/psycopg2/__init__.py", line 122, in connect
    conn = _connect(dsn, connection_factory=connection_factory, **kwasync)
           ^^^^^^^^^^^^^^^^^^^^^^^^^^^^^^^^^^^^^^^^^^^^^^^^^^^^^^^^^^^^^^^
psycopg2.OperationalError: connection to server at "localhost" (::1), port 5432 failed: Connection refused
	Is the server running on that host and accepting TCP/IP connections?
connection to server at "localhost" (127.0.0.1), port 5432 failed: Connection refused
	Is the server running on that host and accepting TCP/IP connections?

[2025-01-25T17:09:50.485+0000] {local_task_job_runner.py:266} INFO - Task exited with return code 1
[2025-01-25T17:09:50.822+0000] {taskinstance.py:3895} INFO - 0 downstream tasks scheduled from follow-on schedule check
[2025-01-25T17:09:50.877+0000] {local_task_job_runner.py:245} INFO - ::endgroup::
[2025-01-26T06:40:01.694+0000] {local_task_job_runner.py:123} INFO - ::group::Pre task execution logs
[2025-01-26T06:40:01.759+0000] {taskinstance.py:2613} INFO - Dependencies all met for dep_context=non-requeueable deps ti=<TaskInstance: fetch_and_store_ebooks.create_table scheduled__2025-01-04T00:00:00+00:00 [queued]>
[2025-01-26T06:40:01.790+0000] {taskinstance.py:2613} INFO - Dependencies all met for dep_context=requeueable deps ti=<TaskInstance: fetch_and_store_ebooks.create_table scheduled__2025-01-04T00:00:00+00:00 [queued]>
[2025-01-26T06:40:01.792+0000] {taskinstance.py:2866} INFO - Starting attempt 2 of 2
[2025-01-26T06:40:01.847+0000] {taskinstance.py:2889} INFO - Executing <Task(PostgresOperator): create_table> on 2025-01-04 00:00:00+00:00
[2025-01-26T06:40:01.864+0000] {warnings.py:112} WARNING - /home/***/.local/lib/python3.12/site-packages/***/task/task_runner/standard_task_runner.py:70: DeprecationWarning: This process (pid=579) is multi-threaded, use of fork() may lead to deadlocks in the child.
  pid = os.fork()

[2025-01-26T06:40:01.868+0000] {standard_task_runner.py:72} INFO - Started process 587 to run task
[2025-01-26T06:40:01.871+0000] {standard_task_runner.py:104} INFO - Running: ['***', 'tasks', 'run', 'fetch_and_store_ebooks', 'create_table', 'scheduled__2025-01-04T00:00:00+00:00', '--job-id', '571', '--raw', '--subdir', 'DAGS_FOLDER/app.py', '--cfg-path', '/tmp/tmpcbh8f3sy']
[2025-01-26T06:40:01.875+0000] {standard_task_runner.py:105} INFO - Job 571: Subtask create_table
[2025-01-26T06:40:02.654+0000] {task_command.py:467} INFO - Running <TaskInstance: fetch_and_store_ebooks.create_table scheduled__2025-01-04T00:00:00+00:00 [running]> on host 34edd304782d
[2025-01-26T06:40:02.991+0000] {taskinstance.py:3132} INFO - Exporting env vars: AIRFLOW_CTX_DAG_OWNER='***' AIRFLOW_CTX_DAG_ID='fetch_and_store_ebooks' AIRFLOW_CTX_TASK_ID='create_table' AIRFLOW_CTX_EXECUTION_DATE='2025-01-04T00:00:00+00:00' AIRFLOW_CTX_TRY_NUMBER='2' AIRFLOW_CTX_DAG_RUN_ID='scheduled__2025-01-04T00:00:00+00:00'
[2025-01-26T06:40:02.995+0000] {logging_mixin.py:190} INFO - Task instance is in running state
[2025-01-26T06:40:02.997+0000] {logging_mixin.py:190} INFO -  Previous state of the Task instance: queued
[2025-01-26T06:40:02.999+0000] {logging_mixin.py:190} INFO - Current task name:create_table state:running start_date:2025-01-26 06:40:01.761294+00:00
[2025-01-26T06:40:03.001+0000] {logging_mixin.py:190} INFO - Dag name:fetch_and_store_ebooks and current dag run status:running
[2025-01-26T06:40:03.003+0000] {taskinstance.py:731} INFO - ::endgroup::
[2025-01-26T06:40:03.005+0000] {sql.py:278} INFO - Executing: 
    CREATE TABLE IF NOT EXISTS ebooks (
        id SERIAL PRIMARY KEY,
        judul TEXT NOT NULL,
        penulis TEXT,
        link TEXT
    );
    
[2025-01-26T06:40:03.038+0000] {base.py:84} INFO - Retrieving connection 'ebooks_connection'
[2025-01-26T06:40:03.067+0000] {base.py:84} INFO - Retrieving connection 'ebooks_connection'
[2025-01-26T06:40:03.296+0000] {sql.py:553} INFO - Running statement: 
    CREATE TABLE IF NOT EXISTS ebooks (
        id SERIAL PRIMARY KEY,
        judul TEXT NOT NULL,
        penulis TEXT,
        link TEXT
    );
    , parameters: None
[2025-01-26T06:40:03.306+0000] {taskinstance.py:3311} ERROR - Task failed with exception
Traceback (most recent call last):
  File "/home/airflow/.local/lib/python3.12/site-packages/airflow/models/taskinstance.py", line 767, in _execute_task
    result = _execute_callable(context=context, **execute_callable_kwargs)
             ^^^^^^^^^^^^^^^^^^^^^^^^^^^^^^^^^^^^^^^^^^^^^^^^^^^^^^^^^^^^^
  File "/home/airflow/.local/lib/python3.12/site-packages/airflow/models/taskinstance.py", line 733, in _execute_callable
    return ExecutionCallableRunner(
           ^^^^^^^^^^^^^^^^^^^^^^^^
  File "/home/airflow/.local/lib/python3.12/site-packages/airflow/utils/operator_helpers.py", line 252, in run
    return self.func(*args, **kwargs)
           ^^^^^^^^^^^^^^^^^^^^^^^^^^
  File "/home/airflow/.local/lib/python3.12/site-packages/airflow/models/baseoperator.py", line 422, in wrapper
    return func(self, *args, **kwargs)
           ^^^^^^^^^^^^^^^^^^^^^^^^^^^
  File "/home/airflow/.local/lib/python3.12/site-packages/airflow/providers/common/sql/operators/sql.py", line 284, in execute
    output = hook.run(
             ^^^^^^^^^
  File "/home/airflow/.local/lib/python3.12/site-packages/airflow/providers/common/sql/hooks/sql.py", line 498, in run
    self._run_command(cur, sql_statement, parameters)
  File "/home/airflow/.local/lib/python3.12/site-packages/airflow/providers/common/sql/hooks/sql.py", line 558, in _run_command
    cur.execute(sql_statement)
psycopg2.errors.InsufficientPrivilege: permission denied for schema public
LINE 2:     CREATE TABLE IF NOT EXISTS ebooks (
                                       ^

[2025-01-26T06:40:03.341+0000] {logging_mixin.py:190} INFO - Task instance in failure state
[2025-01-26T06:40:03.343+0000] {logging_mixin.py:190} INFO - Task start:2025-01-26 06:40:01.761294+00:00 end:2025-01-26 06:40:03.340379+00:00 duration:1.579085
[2025-01-26T06:40:03.345+0000] {logging_mixin.py:190} INFO - Task:<Task(PostgresOperator): create_table> dag:<DAG: fetch_and_store_ebooks> dagrun:<DagRun fetch_and_store_ebooks @ 2025-01-04 00:00:00+00:00: scheduled__2025-01-04T00:00:00+00:00, state:running, queued_at: 2025-01-26 06:33:29.655243+00:00. externally triggered: False>
[2025-01-26T06:40:03.347+0000] {logging_mixin.py:190} INFO - Failure caused by permission denied for schema public
LINE 2:     CREATE TABLE IF NOT EXISTS ebooks (
                                       ^
[2025-01-26T06:40:03.349+0000] {taskinstance.py:1225} INFO - Marking task as FAILED. dag_id=fetch_and_store_ebooks, task_id=create_table, run_id=scheduled__2025-01-04T00:00:00+00:00, execution_date=20250104T000000, start_date=20250126T064001, end_date=20250126T064003
[2025-01-26T06:40:03.609+0000] {taskinstance.py:340} INFO - ::group::Post task execution logs
[2025-01-26T06:40:03.612+0000] {standard_task_runner.py:124} ERROR - Failed to execute job 571 for task create_table (permission denied for schema public
LINE 2:     CREATE TABLE IF NOT EXISTS ebooks (
                                       ^
; 587)
Traceback (most recent call last):
  File "/home/airflow/.local/lib/python3.12/site-packages/airflow/task/task_runner/standard_task_runner.py", line 117, in _start_by_fork
    ret = args.func(args, dag=self.dag)
          ^^^^^^^^^^^^^^^^^^^^^^^^^^^^^
  File "/home/airflow/.local/lib/python3.12/site-packages/airflow/cli/cli_config.py", line 49, in command
    return func(*args, **kwargs)
           ^^^^^^^^^^^^^^^^^^^^^
  File "/home/airflow/.local/lib/python3.12/site-packages/airflow/utils/cli.py", line 116, in wrapper
    return f(*args, **kwargs)
           ^^^^^^^^^^^^^^^^^^
  File "/home/airflow/.local/lib/python3.12/site-packages/airflow/cli/commands/task_command.py", line 483, in task_run
    task_return_code = _run_task_by_selected_method(args, _dag, ti)
                       ^^^^^^^^^^^^^^^^^^^^^^^^^^^^^^^^^^^^^^^^^^^^
  File "/home/airflow/.local/lib/python3.12/site-packages/airflow/cli/commands/task_command.py", line 256, in _run_task_by_selected_method
    return _run_raw_task(args, ti)
           ^^^^^^^^^^^^^^^^^^^^^^^
  File "/home/airflow/.local/lib/python3.12/site-packages/airflow/cli/commands/task_command.py", line 341, in _run_raw_task
    return ti._run_raw_task(
           ^^^^^^^^^^^^^^^^^
  File "/home/airflow/.local/lib/python3.12/site-packages/airflow/utils/session.py", line 97, in wrapper
    return func(*args, session=session, **kwargs)
           ^^^^^^^^^^^^^^^^^^^^^^^^^^^^^^^^^^^^^^
  File "/home/airflow/.local/lib/python3.12/site-packages/airflow/models/taskinstance.py", line 3005, in _run_raw_task
    return _run_raw_task(
           ^^^^^^^^^^^^^^
  File "/home/airflow/.local/lib/python3.12/site-packages/airflow/models/taskinstance.py", line 273, in _run_raw_task
    TaskInstance._execute_task_with_callbacks(
  File "/home/airflow/.local/lib/python3.12/site-packages/airflow/models/taskinstance.py", line 3159, in _execute_task_with_callbacks
    result = self._execute_task(context, task_orig)
             ^^^^^^^^^^^^^^^^^^^^^^^^^^^^^^^^^^^^^^
  File "/home/airflow/.local/lib/python3.12/site-packages/airflow/models/taskinstance.py", line 3183, in _execute_task
    return _execute_task(self, context, task_orig)
           ^^^^^^^^^^^^^^^^^^^^^^^^^^^^^^^^^^^^^^^
  File "/home/airflow/.local/lib/python3.12/site-packages/airflow/models/taskinstance.py", line 767, in _execute_task
    result = _execute_callable(context=context, **execute_callable_kwargs)
             ^^^^^^^^^^^^^^^^^^^^^^^^^^^^^^^^^^^^^^^^^^^^^^^^^^^^^^^^^^^^^
  File "/home/airflow/.local/lib/python3.12/site-packages/airflow/models/taskinstance.py", line 733, in _execute_callable
    return ExecutionCallableRunner(
           ^^^^^^^^^^^^^^^^^^^^^^^^
  File "/home/airflow/.local/lib/python3.12/site-packages/airflow/utils/operator_helpers.py", line 252, in run
    return self.func(*args, **kwargs)
           ^^^^^^^^^^^^^^^^^^^^^^^^^^
  File "/home/airflow/.local/lib/python3.12/site-packages/airflow/models/baseoperator.py", line 422, in wrapper
    return func(self, *args, **kwargs)
           ^^^^^^^^^^^^^^^^^^^^^^^^^^^
  File "/home/airflow/.local/lib/python3.12/site-packages/airflow/providers/common/sql/operators/sql.py", line 284, in execute
    output = hook.run(
             ^^^^^^^^^
  File "/home/airflow/.local/lib/python3.12/site-packages/airflow/providers/common/sql/hooks/sql.py", line 498, in run
    self._run_command(cur, sql_statement, parameters)
  File "/home/airflow/.local/lib/python3.12/site-packages/airflow/providers/common/sql/hooks/sql.py", line 558, in _run_command
    cur.execute(sql_statement)
psycopg2.errors.InsufficientPrivilege: permission denied for schema public
LINE 2:     CREATE TABLE IF NOT EXISTS ebooks (
                                       ^

[2025-01-26T06:40:03.713+0000] {local_task_job_runner.py:266} INFO - Task exited with return code 1
[2025-01-26T06:40:04.157+0000] {taskinstance.py:3895} INFO - 0 downstream tasks scheduled from follow-on schedule check
[2025-01-26T06:40:04.207+0000] {local_task_job_runner.py:245} INFO - ::endgroup::
[2025-01-26T07:28:15.197+0000] {local_task_job_runner.py:123} INFO - ::group::Pre task execution logs
[2025-01-26T07:28:15.355+0000] {taskinstance.py:2613} INFO - Dependencies all met for dep_context=non-requeueable deps ti=<TaskInstance: fetch_and_store_ebooks.create_table scheduled__2025-01-04T00:00:00+00:00 [queued]>
[2025-01-26T07:28:15.413+0000] {taskinstance.py:2613} INFO - Dependencies all met for dep_context=requeueable deps ti=<TaskInstance: fetch_and_store_ebooks.create_table scheduled__2025-01-04T00:00:00+00:00 [queued]>
[2025-01-26T07:28:15.429+0000] {taskinstance.py:2866} INFO - Starting attempt 2 of 2
[2025-01-26T07:28:16.134+0000] {taskinstance.py:2889} INFO - Executing <Task(PostgresOperator): create_table> on 2025-01-04 00:00:00+00:00
[2025-01-26T07:28:16.180+0000] {warnings.py:112} WARNING - /home/***/.local/lib/python3.12/site-packages/***/task/task_runner/standard_task_runner.py:70: DeprecationWarning: This process (pid=1427) is multi-threaded, use of fork() may lead to deadlocks in the child.
  pid = os.fork()

[2025-01-26T07:28:16.190+0000] {standard_task_runner.py:72} INFO - Started process 1448 to run task
[2025-01-26T07:28:16.208+0000] {standard_task_runner.py:104} INFO - Running: ['***', 'tasks', 'run', 'fetch_and_store_ebooks', 'create_table', 'scheduled__2025-01-04T00:00:00+00:00', '--job-id', '657', '--raw', '--subdir', 'DAGS_FOLDER/app.py', '--cfg-path', '/tmp/tmp5toc9uzv']
[2025-01-26T07:28:16.215+0000] {standard_task_runner.py:105} INFO - Job 657: Subtask create_table
[2025-01-26T07:28:16.639+0000] {task_command.py:467} INFO - Running <TaskInstance: fetch_and_store_ebooks.create_table scheduled__2025-01-04T00:00:00+00:00 [running]> on host 34edd304782d
[2025-01-26T07:28:17.331+0000] {taskinstance.py:3132} INFO - Exporting env vars: AIRFLOW_CTX_DAG_OWNER='***' AIRFLOW_CTX_DAG_ID='fetch_and_store_ebooks' AIRFLOW_CTX_TASK_ID='create_table' AIRFLOW_CTX_EXECUTION_DATE='2025-01-04T00:00:00+00:00' AIRFLOW_CTX_TRY_NUMBER='2' AIRFLOW_CTX_DAG_RUN_ID='scheduled__2025-01-04T00:00:00+00:00'
[2025-01-26T07:28:17.338+0000] {logging_mixin.py:190} INFO - Task instance is in running state
[2025-01-26T07:28:17.344+0000] {logging_mixin.py:190} INFO -  Previous state of the Task instance: queued
[2025-01-26T07:28:17.348+0000] {logging_mixin.py:190} INFO - Current task name:create_table state:running start_date:2025-01-26 07:28:15.371025+00:00
[2025-01-26T07:28:17.350+0000] {logging_mixin.py:190} INFO - Dag name:fetch_and_store_ebooks and current dag run status:running
[2025-01-26T07:28:17.358+0000] {taskinstance.py:731} INFO - ::endgroup::
[2025-01-26T07:28:17.360+0000] {sql.py:278} INFO - Executing: 
    CREATE TABLE IF NOT EXISTS ebooks (
        id SERIAL PRIMARY KEY,
        judul TEXT NOT NULL,
        penulis TEXT,
        link TEXT
    );
    
[2025-01-26T07:28:17.487+0000] {base.py:84} INFO - Retrieving connection 'ebooks_connection'
[2025-01-26T07:28:17.705+0000] {base.py:84} INFO - Retrieving connection 'ebooks_connection'
[2025-01-26T07:28:17.974+0000] {sql.py:553} INFO - Running statement: 
    CREATE TABLE IF NOT EXISTS ebooks (
        id SERIAL PRIMARY KEY,
        judul TEXT NOT NULL,
        penulis TEXT,
        link TEXT
    );
    , parameters: None
[2025-01-26T07:28:18.001+0000] {taskinstance.py:3311} ERROR - Task failed with exception
Traceback (most recent call last):
  File "/home/airflow/.local/lib/python3.12/site-packages/airflow/models/taskinstance.py", line 767, in _execute_task
    result = _execute_callable(context=context, **execute_callable_kwargs)
             ^^^^^^^^^^^^^^^^^^^^^^^^^^^^^^^^^^^^^^^^^^^^^^^^^^^^^^^^^^^^^
  File "/home/airflow/.local/lib/python3.12/site-packages/airflow/models/taskinstance.py", line 733, in _execute_callable
    return ExecutionCallableRunner(
           ^^^^^^^^^^^^^^^^^^^^^^^^
  File "/home/airflow/.local/lib/python3.12/site-packages/airflow/utils/operator_helpers.py", line 252, in run
    return self.func(*args, **kwargs)
           ^^^^^^^^^^^^^^^^^^^^^^^^^^
  File "/home/airflow/.local/lib/python3.12/site-packages/airflow/models/baseoperator.py", line 422, in wrapper
    return func(self, *args, **kwargs)
           ^^^^^^^^^^^^^^^^^^^^^^^^^^^
  File "/home/airflow/.local/lib/python3.12/site-packages/airflow/providers/common/sql/operators/sql.py", line 284, in execute
    output = hook.run(
             ^^^^^^^^^
  File "/home/airflow/.local/lib/python3.12/site-packages/airflow/providers/common/sql/hooks/sql.py", line 498, in run
    self._run_command(cur, sql_statement, parameters)
  File "/home/airflow/.local/lib/python3.12/site-packages/airflow/providers/common/sql/hooks/sql.py", line 558, in _run_command
    cur.execute(sql_statement)
psycopg2.errors.InsufficientPrivilege: permission denied for schema public
LINE 2:     CREATE TABLE IF NOT EXISTS ebooks (
                                       ^

[2025-01-26T07:28:18.273+0000] {logging_mixin.py:190} INFO - Task instance in failure state
[2025-01-26T07:28:18.290+0000] {logging_mixin.py:190} INFO - Task start:2025-01-26 07:28:15.371025+00:00 end:2025-01-26 07:28:18.258123+00:00 duration:2.887098
[2025-01-26T07:28:18.314+0000] {logging_mixin.py:190} INFO - Task:<Task(PostgresOperator): create_table> dag:<DAG: fetch_and_store_ebooks> dagrun:<DagRun fetch_and_store_ebooks @ 2025-01-04 00:00:00+00:00: scheduled__2025-01-04T00:00:00+00:00, state:running, queued_at: 2025-01-26 07:21:29.507946+00:00. externally triggered: False>
[2025-01-26T07:28:18.341+0000] {logging_mixin.py:190} INFO - Failure caused by permission denied for schema public
LINE 2:     CREATE TABLE IF NOT EXISTS ebooks (
                                       ^
[2025-01-26T07:28:18.361+0000] {taskinstance.py:1225} INFO - Marking task as FAILED. dag_id=fetch_and_store_ebooks, task_id=create_table, run_id=scheduled__2025-01-04T00:00:00+00:00, execution_date=20250104T000000, start_date=20250126T072815, end_date=20250126T072818
[2025-01-26T07:28:18.529+0000] {taskinstance.py:340} INFO - ::group::Post task execution logs
[2025-01-26T07:28:18.539+0000] {standard_task_runner.py:124} ERROR - Failed to execute job 657 for task create_table (permission denied for schema public
LINE 2:     CREATE TABLE IF NOT EXISTS ebooks (
                                       ^
; 1448)
Traceback (most recent call last):
  File "/home/airflow/.local/lib/python3.12/site-packages/airflow/task/task_runner/standard_task_runner.py", line 117, in _start_by_fork
    ret = args.func(args, dag=self.dag)
          ^^^^^^^^^^^^^^^^^^^^^^^^^^^^^
  File "/home/airflow/.local/lib/python3.12/site-packages/airflow/cli/cli_config.py", line 49, in command
    return func(*args, **kwargs)
           ^^^^^^^^^^^^^^^^^^^^^
  File "/home/airflow/.local/lib/python3.12/site-packages/airflow/utils/cli.py", line 116, in wrapper
    return f(*args, **kwargs)
           ^^^^^^^^^^^^^^^^^^
  File "/home/airflow/.local/lib/python3.12/site-packages/airflow/cli/commands/task_command.py", line 483, in task_run
    task_return_code = _run_task_by_selected_method(args, _dag, ti)
                       ^^^^^^^^^^^^^^^^^^^^^^^^^^^^^^^^^^^^^^^^^^^^
  File "/home/airflow/.local/lib/python3.12/site-packages/airflow/cli/commands/task_command.py", line 256, in _run_task_by_selected_method
    return _run_raw_task(args, ti)
           ^^^^^^^^^^^^^^^^^^^^^^^
  File "/home/airflow/.local/lib/python3.12/site-packages/airflow/cli/commands/task_command.py", line 341, in _run_raw_task
    return ti._run_raw_task(
           ^^^^^^^^^^^^^^^^^
  File "/home/airflow/.local/lib/python3.12/site-packages/airflow/utils/session.py", line 97, in wrapper
    return func(*args, session=session, **kwargs)
           ^^^^^^^^^^^^^^^^^^^^^^^^^^^^^^^^^^^^^^
  File "/home/airflow/.local/lib/python3.12/site-packages/airflow/models/taskinstance.py", line 3005, in _run_raw_task
    return _run_raw_task(
           ^^^^^^^^^^^^^^
  File "/home/airflow/.local/lib/python3.12/site-packages/airflow/models/taskinstance.py", line 273, in _run_raw_task
    TaskInstance._execute_task_with_callbacks(
  File "/home/airflow/.local/lib/python3.12/site-packages/airflow/models/taskinstance.py", line 3159, in _execute_task_with_callbacks
    result = self._execute_task(context, task_orig)
             ^^^^^^^^^^^^^^^^^^^^^^^^^^^^^^^^^^^^^^
  File "/home/airflow/.local/lib/python3.12/site-packages/airflow/models/taskinstance.py", line 3183, in _execute_task
    return _execute_task(self, context, task_orig)
           ^^^^^^^^^^^^^^^^^^^^^^^^^^^^^^^^^^^^^^^
  File "/home/airflow/.local/lib/python3.12/site-packages/airflow/models/taskinstance.py", line 767, in _execute_task
    result = _execute_callable(context=context, **execute_callable_kwargs)
             ^^^^^^^^^^^^^^^^^^^^^^^^^^^^^^^^^^^^^^^^^^^^^^^^^^^^^^^^^^^^^
  File "/home/airflow/.local/lib/python3.12/site-packages/airflow/models/taskinstance.py", line 733, in _execute_callable
    return ExecutionCallableRunner(
           ^^^^^^^^^^^^^^^^^^^^^^^^
  File "/home/airflow/.local/lib/python3.12/site-packages/airflow/utils/operator_helpers.py", line 252, in run
    return self.func(*args, **kwargs)
           ^^^^^^^^^^^^^^^^^^^^^^^^^^
  File "/home/airflow/.local/lib/python3.12/site-packages/airflow/models/baseoperator.py", line 422, in wrapper
    return func(self, *args, **kwargs)
           ^^^^^^^^^^^^^^^^^^^^^^^^^^^
  File "/home/airflow/.local/lib/python3.12/site-packages/airflow/providers/common/sql/operators/sql.py", line 284, in execute
    output = hook.run(
             ^^^^^^^^^
  File "/home/airflow/.local/lib/python3.12/site-packages/airflow/providers/common/sql/hooks/sql.py", line 498, in run
    self._run_command(cur, sql_statement, parameters)
  File "/home/airflow/.local/lib/python3.12/site-packages/airflow/providers/common/sql/hooks/sql.py", line 558, in _run_command
    cur.execute(sql_statement)
psycopg2.errors.InsufficientPrivilege: permission denied for schema public
LINE 2:     CREATE TABLE IF NOT EXISTS ebooks (
                                       ^

[2025-01-26T07:28:18.712+0000] {local_task_job_runner.py:266} INFO - Task exited with return code 1
[2025-01-26T07:28:18.932+0000] {taskinstance.py:3895} INFO - 0 downstream tasks scheduled from follow-on schedule check
[2025-01-26T07:28:18.976+0000] {local_task_job_runner.py:245} INFO - ::endgroup::
[2025-01-26T07:53:51.648+0000] {local_task_job_runner.py:123} INFO - ::group::Pre task execution logs
[2025-01-26T07:53:51.782+0000] {taskinstance.py:2613} INFO - Dependencies all met for dep_context=non-requeueable deps ti=<TaskInstance: fetch_and_store_ebooks.create_table scheduled__2025-01-04T00:00:00+00:00 [queued]>
[2025-01-26T07:53:51.840+0000] {taskinstance.py:2613} INFO - Dependencies all met for dep_context=requeueable deps ti=<TaskInstance: fetch_and_store_ebooks.create_table scheduled__2025-01-04T00:00:00+00:00 [queued]>
[2025-01-26T07:53:51.851+0000] {taskinstance.py:2866} INFO - Starting attempt 2 of 2
[2025-01-26T07:53:51.986+0000] {taskinstance.py:2889} INFO - Executing <Task(PostgresOperator): create_table> on 2025-01-04 00:00:00+00:00
[2025-01-26T07:53:52.055+0000] {warnings.py:112} WARNING - /home/***/.local/lib/python3.12/site-packages/***/task/task_runner/standard_task_runner.py:70: DeprecationWarning: This process (pid=2113) is multi-threaded, use of fork() may lead to deadlocks in the child.
  pid = os.fork()

[2025-01-26T07:53:52.080+0000] {standard_task_runner.py:72} INFO - Started process 2149 to run task
[2025-01-26T07:53:52.069+0000] {standard_task_runner.py:104} INFO - Running: ['***', 'tasks', 'run', 'fetch_and_store_ebooks', 'create_table', 'scheduled__2025-01-04T00:00:00+00:00', '--job-id', '757', '--raw', '--subdir', 'DAGS_FOLDER/app.py', '--cfg-path', '/tmp/tmprb11i48w']
[2025-01-26T07:53:52.093+0000] {standard_task_runner.py:105} INFO - Job 757: Subtask create_table
[2025-01-26T07:53:52.384+0000] {task_command.py:467} INFO - Running <TaskInstance: fetch_and_store_ebooks.create_table scheduled__2025-01-04T00:00:00+00:00 [running]> on host 34edd304782d
[2025-01-26T07:53:52.978+0000] {taskinstance.py:3132} INFO - Exporting env vars: AIRFLOW_CTX_DAG_OWNER='***' AIRFLOW_CTX_DAG_ID='fetch_and_store_ebooks' AIRFLOW_CTX_TASK_ID='create_table' AIRFLOW_CTX_EXECUTION_DATE='2025-01-04T00:00:00+00:00' AIRFLOW_CTX_TRY_NUMBER='2' AIRFLOW_CTX_DAG_RUN_ID='scheduled__2025-01-04T00:00:00+00:00'
[2025-01-26T07:53:52.991+0000] {logging_mixin.py:190} INFO - Task instance is in running state
[2025-01-26T07:53:52.995+0000] {logging_mixin.py:190} INFO -  Previous state of the Task instance: queued
[2025-01-26T07:53:52.997+0000] {logging_mixin.py:190} INFO - Current task name:create_table state:running start_date:2025-01-26 07:53:51.788647+00:00
[2025-01-26T07:53:52.999+0000] {logging_mixin.py:190} INFO - Dag name:fetch_and_store_ebooks and current dag run status:running
[2025-01-26T07:53:53.001+0000] {taskinstance.py:731} INFO - ::endgroup::
[2025-01-26T07:53:53.004+0000] {sql.py:278} INFO - Executing: 
    CREATE TABLE IF NOT EXISTS ebooks (
        id SERIAL PRIMARY KEY,
        judul TEXT NOT NULL,
        penulis TEXT,
        link TEXT
    );
    
[2025-01-26T07:53:53.045+0000] {base.py:84} INFO - Retrieving connection 'ebooks_connection'
[2025-01-26T07:53:53.074+0000] {base.py:84} INFO - Retrieving connection 'ebooks_connection'
[2025-01-26T07:53:53.282+0000] {sql.py:553} INFO - Running statement: 
    CREATE TABLE IF NOT EXISTS ebooks (
        id SERIAL PRIMARY KEY,
        judul TEXT NOT NULL,
        penulis TEXT,
        link TEXT
    );
    , parameters: None
[2025-01-26T07:53:53.296+0000] {taskinstance.py:3311} ERROR - Task failed with exception
Traceback (most recent call last):
  File "/home/airflow/.local/lib/python3.12/site-packages/airflow/models/taskinstance.py", line 767, in _execute_task
    result = _execute_callable(context=context, **execute_callable_kwargs)
             ^^^^^^^^^^^^^^^^^^^^^^^^^^^^^^^^^^^^^^^^^^^^^^^^^^^^^^^^^^^^^
  File "/home/airflow/.local/lib/python3.12/site-packages/airflow/models/taskinstance.py", line 733, in _execute_callable
    return ExecutionCallableRunner(
           ^^^^^^^^^^^^^^^^^^^^^^^^
  File "/home/airflow/.local/lib/python3.12/site-packages/airflow/utils/operator_helpers.py", line 252, in run
    return self.func(*args, **kwargs)
           ^^^^^^^^^^^^^^^^^^^^^^^^^^
  File "/home/airflow/.local/lib/python3.12/site-packages/airflow/models/baseoperator.py", line 422, in wrapper
    return func(self, *args, **kwargs)
           ^^^^^^^^^^^^^^^^^^^^^^^^^^^
  File "/home/airflow/.local/lib/python3.12/site-packages/airflow/providers/common/sql/operators/sql.py", line 284, in execute
    output = hook.run(
             ^^^^^^^^^
  File "/home/airflow/.local/lib/python3.12/site-packages/airflow/providers/common/sql/hooks/sql.py", line 498, in run
    self._run_command(cur, sql_statement, parameters)
  File "/home/airflow/.local/lib/python3.12/site-packages/airflow/providers/common/sql/hooks/sql.py", line 558, in _run_command
    cur.execute(sql_statement)
psycopg2.errors.InsufficientPrivilege: permission denied for schema public
LINE 2:     CREATE TABLE IF NOT EXISTS ebooks (
                                       ^

[2025-01-26T07:53:53.349+0000] {logging_mixin.py:190} INFO - Task instance in failure state
[2025-01-26T07:53:53.352+0000] {logging_mixin.py:190} INFO - Task start:2025-01-26 07:53:51.788647+00:00 end:2025-01-26 07:53:53.346892+00:00 duration:1.558245
[2025-01-26T07:53:53.355+0000] {logging_mixin.py:190} INFO - Task:<Task(PostgresOperator): create_table> dag:<DAG: fetch_and_store_ebooks> dagrun:<DagRun fetch_and_store_ebooks @ 2025-01-04 00:00:00+00:00: scheduled__2025-01-04T00:00:00+00:00, state:running, queued_at: 2025-01-26 07:46:49.889452+00:00. externally triggered: False>
[2025-01-26T07:53:53.357+0000] {logging_mixin.py:190} INFO - Failure caused by permission denied for schema public
LINE 2:     CREATE TABLE IF NOT EXISTS ebooks (
                                       ^
[2025-01-26T07:53:53.360+0000] {taskinstance.py:1225} INFO - Marking task as FAILED. dag_id=fetch_and_store_ebooks, task_id=create_table, run_id=scheduled__2025-01-04T00:00:00+00:00, execution_date=20250104T000000, start_date=20250126T075351, end_date=20250126T075353
[2025-01-26T07:53:53.428+0000] {taskinstance.py:340} INFO - ::group::Post task execution logs
[2025-01-26T07:53:53.431+0000] {standard_task_runner.py:124} ERROR - Failed to execute job 757 for task create_table (permission denied for schema public
LINE 2:     CREATE TABLE IF NOT EXISTS ebooks (
                                       ^
; 2149)
Traceback (most recent call last):
  File "/home/airflow/.local/lib/python3.12/site-packages/airflow/task/task_runner/standard_task_runner.py", line 117, in _start_by_fork
    ret = args.func(args, dag=self.dag)
          ^^^^^^^^^^^^^^^^^^^^^^^^^^^^^
  File "/home/airflow/.local/lib/python3.12/site-packages/airflow/cli/cli_config.py", line 49, in command
    return func(*args, **kwargs)
           ^^^^^^^^^^^^^^^^^^^^^
  File "/home/airflow/.local/lib/python3.12/site-packages/airflow/utils/cli.py", line 116, in wrapper
    return f(*args, **kwargs)
           ^^^^^^^^^^^^^^^^^^
  File "/home/airflow/.local/lib/python3.12/site-packages/airflow/cli/commands/task_command.py", line 483, in task_run
    task_return_code = _run_task_by_selected_method(args, _dag, ti)
                       ^^^^^^^^^^^^^^^^^^^^^^^^^^^^^^^^^^^^^^^^^^^^
  File "/home/airflow/.local/lib/python3.12/site-packages/airflow/cli/commands/task_command.py", line 256, in _run_task_by_selected_method
    return _run_raw_task(args, ti)
           ^^^^^^^^^^^^^^^^^^^^^^^
  File "/home/airflow/.local/lib/python3.12/site-packages/airflow/cli/commands/task_command.py", line 341, in _run_raw_task
    return ti._run_raw_task(
           ^^^^^^^^^^^^^^^^^
  File "/home/airflow/.local/lib/python3.12/site-packages/airflow/utils/session.py", line 97, in wrapper
    return func(*args, session=session, **kwargs)
           ^^^^^^^^^^^^^^^^^^^^^^^^^^^^^^^^^^^^^^
  File "/home/airflow/.local/lib/python3.12/site-packages/airflow/models/taskinstance.py", line 3005, in _run_raw_task
    return _run_raw_task(
           ^^^^^^^^^^^^^^
  File "/home/airflow/.local/lib/python3.12/site-packages/airflow/models/taskinstance.py", line 273, in _run_raw_task
    TaskInstance._execute_task_with_callbacks(
  File "/home/airflow/.local/lib/python3.12/site-packages/airflow/models/taskinstance.py", line 3159, in _execute_task_with_callbacks
    result = self._execute_task(context, task_orig)
             ^^^^^^^^^^^^^^^^^^^^^^^^^^^^^^^^^^^^^^
  File "/home/airflow/.local/lib/python3.12/site-packages/airflow/models/taskinstance.py", line 3183, in _execute_task
    return _execute_task(self, context, task_orig)
           ^^^^^^^^^^^^^^^^^^^^^^^^^^^^^^^^^^^^^^^
  File "/home/airflow/.local/lib/python3.12/site-packages/airflow/models/taskinstance.py", line 767, in _execute_task
    result = _execute_callable(context=context, **execute_callable_kwargs)
             ^^^^^^^^^^^^^^^^^^^^^^^^^^^^^^^^^^^^^^^^^^^^^^^^^^^^^^^^^^^^^
  File "/home/airflow/.local/lib/python3.12/site-packages/airflow/models/taskinstance.py", line 733, in _execute_callable
    return ExecutionCallableRunner(
           ^^^^^^^^^^^^^^^^^^^^^^^^
  File "/home/airflow/.local/lib/python3.12/site-packages/airflow/utils/operator_helpers.py", line 252, in run
    return self.func(*args, **kwargs)
           ^^^^^^^^^^^^^^^^^^^^^^^^^^
  File "/home/airflow/.local/lib/python3.12/site-packages/airflow/models/baseoperator.py", line 422, in wrapper
    return func(self, *args, **kwargs)
           ^^^^^^^^^^^^^^^^^^^^^^^^^^^
  File "/home/airflow/.local/lib/python3.12/site-packages/airflow/providers/common/sql/operators/sql.py", line 284, in execute
    output = hook.run(
             ^^^^^^^^^
  File "/home/airflow/.local/lib/python3.12/site-packages/airflow/providers/common/sql/hooks/sql.py", line 498, in run
    self._run_command(cur, sql_statement, parameters)
  File "/home/airflow/.local/lib/python3.12/site-packages/airflow/providers/common/sql/hooks/sql.py", line 558, in _run_command
    cur.execute(sql_statement)
psycopg2.errors.InsufficientPrivilege: permission denied for schema public
LINE 2:     CREATE TABLE IF NOT EXISTS ebooks (
                                       ^

[2025-01-26T07:53:53.492+0000] {local_task_job_runner.py:266} INFO - Task exited with return code 1
[2025-01-26T07:53:53.625+0000] {taskinstance.py:3895} INFO - 0 downstream tasks scheduled from follow-on schedule check
[2025-01-26T07:53:53.690+0000] {local_task_job_runner.py:245} INFO - ::endgroup::
[2025-01-26T09:11:30.491+0000] {local_task_job_runner.py:123} INFO - ::group::Pre task execution logs
[2025-01-26T09:11:30.693+0000] {taskinstance.py:2613} INFO - Dependencies all met for dep_context=non-requeueable deps ti=<TaskInstance: fetch_and_store_ebooks.create_table scheduled__2025-01-04T00:00:00+00:00 [queued]>
[2025-01-26T09:11:30.804+0000] {taskinstance.py:2613} INFO - Dependencies all met for dep_context=requeueable deps ti=<TaskInstance: fetch_and_store_ebooks.create_table scheduled__2025-01-04T00:00:00+00:00 [queued]>
[2025-01-26T09:11:30.818+0000] {taskinstance.py:2866} INFO - Starting attempt 2 of 2
[2025-01-26T09:11:31.817+0000] {taskinstance.py:2889} INFO - Executing <Task(PostgresOperator): create_table> on 2025-01-04 00:00:00+00:00
[2025-01-26T09:11:31.852+0000] {warnings.py:112} WARNING - /home/***/.local/lib/python3.12/site-packages/***/task/task_runner/standard_task_runner.py:70: DeprecationWarning: This process (pid=3796) is multi-threaded, use of fork() may lead to deadlocks in the child.
  pid = os.fork()

[2025-01-26T09:11:31.866+0000] {standard_task_runner.py:72} INFO - Started process 3820 to run task
[2025-01-26T09:11:31.878+0000] {standard_task_runner.py:104} INFO - Running: ['***', 'tasks', 'run', 'fetch_and_store_ebooks', 'create_table', 'scheduled__2025-01-04T00:00:00+00:00', '--job-id', '969', '--raw', '--subdir', 'DAGS_FOLDER/app.py', '--cfg-path', '/tmp/tmpkhr_ggi6']
[2025-01-26T09:11:31.897+0000] {standard_task_runner.py:105} INFO - Job 969: Subtask create_table
[2025-01-26T09:11:32.520+0000] {task_command.py:467} INFO - Running <TaskInstance: fetch_and_store_ebooks.create_table scheduled__2025-01-04T00:00:00+00:00 [running]> on host 34edd304782d
[2025-01-26T09:11:33.235+0000] {taskinstance.py:3132} INFO - Exporting env vars: AIRFLOW_CTX_DAG_OWNER='***' AIRFLOW_CTX_DAG_ID='fetch_and_store_ebooks' AIRFLOW_CTX_TASK_ID='create_table' AIRFLOW_CTX_EXECUTION_DATE='2025-01-04T00:00:00+00:00' AIRFLOW_CTX_TRY_NUMBER='2' AIRFLOW_CTX_DAG_RUN_ID='scheduled__2025-01-04T00:00:00+00:00'
[2025-01-26T09:11:33.274+0000] {logging_mixin.py:190} INFO - Task instance is in running state
[2025-01-26T09:11:33.286+0000] {logging_mixin.py:190} INFO -  Previous state of the Task instance: queued
[2025-01-26T09:11:33.319+0000] {logging_mixin.py:190} INFO - Current task name:create_table state:running start_date:2025-01-26 09:11:30.701741+00:00
[2025-01-26T09:11:33.321+0000] {logging_mixin.py:190} INFO - Dag name:fetch_and_store_ebooks and current dag run status:running
[2025-01-26T09:11:33.323+0000] {taskinstance.py:731} INFO - ::endgroup::
[2025-01-26T09:11:33.335+0000] {sql.py:278} INFO - Executing: 
    CREATE TABLE IF NOT EXISTS ebooks (
        id SERIAL PRIMARY KEY,
        judul TEXT NOT NULL,
        penulis TEXT,
        link TEXT
    );
    
[2025-01-26T09:11:33.419+0000] {base.py:84} INFO - Retrieving connection 'ebooks_connection'
[2025-01-26T09:11:33.544+0000] {base.py:84} INFO - Retrieving connection 'ebooks_connection'
[2025-01-26T09:11:34.111+0000] {sql.py:553} INFO - Running statement: 
    CREATE TABLE IF NOT EXISTS ebooks (
        id SERIAL PRIMARY KEY,
        judul TEXT NOT NULL,
        penulis TEXT,
        link TEXT
    );
    , parameters: None
[2025-01-26T09:11:34.208+0000] {taskinstance.py:3311} ERROR - Task failed with exception
Traceback (most recent call last):
  File "/home/airflow/.local/lib/python3.12/site-packages/airflow/models/taskinstance.py", line 767, in _execute_task
    result = _execute_callable(context=context, **execute_callable_kwargs)
             ^^^^^^^^^^^^^^^^^^^^^^^^^^^^^^^^^^^^^^^^^^^^^^^^^^^^^^^^^^^^^
  File "/home/airflow/.local/lib/python3.12/site-packages/airflow/models/taskinstance.py", line 733, in _execute_callable
    return ExecutionCallableRunner(
           ^^^^^^^^^^^^^^^^^^^^^^^^
  File "/home/airflow/.local/lib/python3.12/site-packages/airflow/utils/operator_helpers.py", line 252, in run
    return self.func(*args, **kwargs)
           ^^^^^^^^^^^^^^^^^^^^^^^^^^
  File "/home/airflow/.local/lib/python3.12/site-packages/airflow/models/baseoperator.py", line 422, in wrapper
    return func(self, *args, **kwargs)
           ^^^^^^^^^^^^^^^^^^^^^^^^^^^
  File "/home/airflow/.local/lib/python3.12/site-packages/airflow/providers/common/sql/operators/sql.py", line 284, in execute
    output = hook.run(
             ^^^^^^^^^
  File "/home/airflow/.local/lib/python3.12/site-packages/airflow/providers/common/sql/hooks/sql.py", line 498, in run
    self._run_command(cur, sql_statement, parameters)
  File "/home/airflow/.local/lib/python3.12/site-packages/airflow/providers/common/sql/hooks/sql.py", line 558, in _run_command
    cur.execute(sql_statement)
psycopg2.errors.InsufficientPrivilege: permission denied for schema public
LINE 2:     CREATE TABLE IF NOT EXISTS ebooks (
                                       ^

[2025-01-26T09:11:34.289+0000] {logging_mixin.py:190} INFO - Task instance in failure state
[2025-01-26T09:11:34.302+0000] {logging_mixin.py:190} INFO - Task start:2025-01-26 09:11:30.701741+00:00 end:2025-01-26 09:11:34.287409+00:00 duration:3.585668
[2025-01-26T09:11:34.306+0000] {logging_mixin.py:190} INFO - Task:<Task(PostgresOperator): create_table> dag:<DAG: fetch_and_store_ebooks> dagrun:<DagRun fetch_and_store_ebooks @ 2025-01-04 00:00:00+00:00: scheduled__2025-01-04T00:00:00+00:00, state:running, queued_at: 2025-01-26 09:04:52.184794+00:00. externally triggered: False>
[2025-01-26T09:11:34.318+0000] {logging_mixin.py:190} INFO - Failure caused by permission denied for schema public
LINE 2:     CREATE TABLE IF NOT EXISTS ebooks (
                                       ^
[2025-01-26T09:11:34.322+0000] {taskinstance.py:1225} INFO - Marking task as FAILED. dag_id=fetch_and_store_ebooks, task_id=create_table, run_id=scheduled__2025-01-04T00:00:00+00:00, execution_date=20250104T000000, start_date=20250126T091130, end_date=20250126T091134
[2025-01-26T09:11:35.332+0000] {taskinstance.py:340} INFO - ::group::Post task execution logs
[2025-01-26T09:11:35.348+0000] {standard_task_runner.py:124} ERROR - Failed to execute job 969 for task create_table (permission denied for schema public
LINE 2:     CREATE TABLE IF NOT EXISTS ebooks (
                                       ^
; 3820)
Traceback (most recent call last):
  File "/home/airflow/.local/lib/python3.12/site-packages/airflow/task/task_runner/standard_task_runner.py", line 117, in _start_by_fork
    ret = args.func(args, dag=self.dag)
          ^^^^^^^^^^^^^^^^^^^^^^^^^^^^^
  File "/home/airflow/.local/lib/python3.12/site-packages/airflow/cli/cli_config.py", line 49, in command
    return func(*args, **kwargs)
           ^^^^^^^^^^^^^^^^^^^^^
  File "/home/airflow/.local/lib/python3.12/site-packages/airflow/utils/cli.py", line 116, in wrapper
    return f(*args, **kwargs)
           ^^^^^^^^^^^^^^^^^^
  File "/home/airflow/.local/lib/python3.12/site-packages/airflow/cli/commands/task_command.py", line 483, in task_run
    task_return_code = _run_task_by_selected_method(args, _dag, ti)
                       ^^^^^^^^^^^^^^^^^^^^^^^^^^^^^^^^^^^^^^^^^^^^
  File "/home/airflow/.local/lib/python3.12/site-packages/airflow/cli/commands/task_command.py", line 256, in _run_task_by_selected_method
    return _run_raw_task(args, ti)
           ^^^^^^^^^^^^^^^^^^^^^^^
  File "/home/airflow/.local/lib/python3.12/site-packages/airflow/cli/commands/task_command.py", line 341, in _run_raw_task
    return ti._run_raw_task(
           ^^^^^^^^^^^^^^^^^
  File "/home/airflow/.local/lib/python3.12/site-packages/airflow/utils/session.py", line 97, in wrapper
    return func(*args, session=session, **kwargs)
           ^^^^^^^^^^^^^^^^^^^^^^^^^^^^^^^^^^^^^^
  File "/home/airflow/.local/lib/python3.12/site-packages/airflow/models/taskinstance.py", line 3005, in _run_raw_task
    return _run_raw_task(
           ^^^^^^^^^^^^^^
  File "/home/airflow/.local/lib/python3.12/site-packages/airflow/models/taskinstance.py", line 273, in _run_raw_task
    TaskInstance._execute_task_with_callbacks(
  File "/home/airflow/.local/lib/python3.12/site-packages/airflow/models/taskinstance.py", line 3159, in _execute_task_with_callbacks
    result = self._execute_task(context, task_orig)
             ^^^^^^^^^^^^^^^^^^^^^^^^^^^^^^^^^^^^^^
  File "/home/airflow/.local/lib/python3.12/site-packages/airflow/models/taskinstance.py", line 3183, in _execute_task
    return _execute_task(self, context, task_orig)
           ^^^^^^^^^^^^^^^^^^^^^^^^^^^^^^^^^^^^^^^
  File "/home/airflow/.local/lib/python3.12/site-packages/airflow/models/taskinstance.py", line 767, in _execute_task
    result = _execute_callable(context=context, **execute_callable_kwargs)
             ^^^^^^^^^^^^^^^^^^^^^^^^^^^^^^^^^^^^^^^^^^^^^^^^^^^^^^^^^^^^^
  File "/home/airflow/.local/lib/python3.12/site-packages/airflow/models/taskinstance.py", line 733, in _execute_callable
    return ExecutionCallableRunner(
           ^^^^^^^^^^^^^^^^^^^^^^^^
  File "/home/airflow/.local/lib/python3.12/site-packages/airflow/utils/operator_helpers.py", line 252, in run
    return self.func(*args, **kwargs)
           ^^^^^^^^^^^^^^^^^^^^^^^^^^
  File "/home/airflow/.local/lib/python3.12/site-packages/airflow/models/baseoperator.py", line 422, in wrapper
    return func(self, *args, **kwargs)
           ^^^^^^^^^^^^^^^^^^^^^^^^^^^
  File "/home/airflow/.local/lib/python3.12/site-packages/airflow/providers/common/sql/operators/sql.py", line 284, in execute
    output = hook.run(
             ^^^^^^^^^
  File "/home/airflow/.local/lib/python3.12/site-packages/airflow/providers/common/sql/hooks/sql.py", line 498, in run
    self._run_command(cur, sql_statement, parameters)
  File "/home/airflow/.local/lib/python3.12/site-packages/airflow/providers/common/sql/hooks/sql.py", line 558, in _run_command
    cur.execute(sql_statement)
psycopg2.errors.InsufficientPrivilege: permission denied for schema public
LINE 2:     CREATE TABLE IF NOT EXISTS ebooks (
                                       ^

[2025-01-26T09:11:35.466+0000] {local_task_job_runner.py:266} INFO - Task exited with return code 1
[2025-01-26T09:11:35.835+0000] {taskinstance.py:3895} INFO - 0 downstream tasks scheduled from follow-on schedule check
[2025-01-26T09:11:36.030+0000] {local_task_job_runner.py:245} INFO - ::endgroup::
