[2025-01-25T17:03:57.198+0000] {local_task_job_runner.py:123} INFO - ::group::Pre task execution logs
[2025-01-25T17:03:57.336+0000] {taskinstance.py:2613} INFO - Dependencies all met for dep_context=non-requeueable deps ti=<TaskInstance: fetch_and_store_ebooks.create_table scheduled__2025-01-12T00:00:00+00:00 [queued]>
[2025-01-25T17:03:57.419+0000] {taskinstance.py:2613} INFO - Dependencies all met for dep_context=requeueable deps ti=<TaskInstance: fetch_and_store_ebooks.create_table scheduled__2025-01-12T00:00:00+00:00 [queued]>
[2025-01-25T17:03:57.427+0000] {taskinstance.py:2866} INFO - Starting attempt 1 of 2
[2025-01-25T17:03:57.585+0000] {taskinstance.py:2889} INFO - Executing <Task(PostgresOperator): create_table> on 2025-01-12 00:00:00+00:00
[2025-01-25T17:03:57.674+0000] {warnings.py:112} WARNING - /home/***/.local/lib/python3.12/site-packages/***/task/task_runner/standard_task_runner.py:70: DeprecationWarning: This process (pid=3773) is multi-threaded, use of fork() may lead to deadlocks in the child.
  pid = os.fork()

[2025-01-25T17:03:57.680+0000] {standard_task_runner.py:72} INFO - Started process 3810 to run task
[2025-01-25T17:03:57.688+0000] {standard_task_runner.py:104} INFO - Running: ['***', 'tasks', 'run', 'fetch_and_store_ebooks', 'create_table', 'scheduled__2025-01-12T00:00:00+00:00', '--job-id', '460', '--raw', '--subdir', 'DAGS_FOLDER/app.py', '--cfg-path', '/tmp/tmp7ryolvd7']
[2025-01-25T17:03:57.720+0000] {standard_task_runner.py:105} INFO - Job 460: Subtask create_table
[2025-01-25T17:04:00.688+0000] {task_command.py:467} INFO - Running <TaskInstance: fetch_and_store_ebooks.create_table scheduled__2025-01-12T00:00:00+00:00 [running]> on host 50ab235b552a
[2025-01-25T17:04:01.579+0000] {taskinstance.py:3132} INFO - Exporting env vars: AIRFLOW_CTX_DAG_OWNER='***' AIRFLOW_CTX_DAG_ID='fetch_and_store_ebooks' AIRFLOW_CTX_TASK_ID='create_table' AIRFLOW_CTX_EXECUTION_DATE='2025-01-12T00:00:00+00:00' AIRFLOW_CTX_TRY_NUMBER='1' AIRFLOW_CTX_DAG_RUN_ID='scheduled__2025-01-12T00:00:00+00:00'
[2025-01-25T17:04:01.596+0000] {logging_mixin.py:190} INFO - Task instance is in running state
[2025-01-25T17:04:01.606+0000] {logging_mixin.py:190} INFO -  Previous state of the Task instance: queued
[2025-01-25T17:04:01.609+0000] {logging_mixin.py:190} INFO - Current task name:create_table state:running start_date:2025-01-25 17:03:57.357821+00:00
[2025-01-25T17:04:01.633+0000] {logging_mixin.py:190} INFO - Dag name:fetch_and_store_ebooks and current dag run status:running
[2025-01-25T17:04:01.647+0000] {taskinstance.py:731} INFO - ::endgroup::
[2025-01-25T17:04:01.666+0000] {sql.py:278} INFO - Executing: 
    CREATE TABLE IF NOT EXISTS ebooks (
        id SERIAL PRIMARY KEY,
        judul TEXT NOT NULL,
        penulis TEXT,
        link TEXT
    );
    
[2025-01-25T17:04:01.771+0000] {base.py:84} INFO - Retrieving connection 'ebooks_connection'
[2025-01-25T17:04:01.963+0000] {base.py:84} INFO - Retrieving connection 'ebooks_connection'
[2025-01-25T17:04:01.986+0000] {taskinstance.py:3311} ERROR - Task failed with exception
Traceback (most recent call last):
  File "/home/airflow/.local/lib/python3.12/site-packages/airflow/models/taskinstance.py", line 767, in _execute_task
    result = _execute_callable(context=context, **execute_callable_kwargs)
             ^^^^^^^^^^^^^^^^^^^^^^^^^^^^^^^^^^^^^^^^^^^^^^^^^^^^^^^^^^^^^
  File "/home/airflow/.local/lib/python3.12/site-packages/airflow/models/taskinstance.py", line 733, in _execute_callable
    return ExecutionCallableRunner(
           ^^^^^^^^^^^^^^^^^^^^^^^^
  File "/home/airflow/.local/lib/python3.12/site-packages/airflow/utils/operator_helpers.py", line 252, in run
    return self.func(*args, **kwargs)
           ^^^^^^^^^^^^^^^^^^^^^^^^^^
  File "/home/airflow/.local/lib/python3.12/site-packages/airflow/models/baseoperator.py", line 422, in wrapper
    return func(self, *args, **kwargs)
           ^^^^^^^^^^^^^^^^^^^^^^^^^^^
  File "/home/airflow/.local/lib/python3.12/site-packages/airflow/providers/common/sql/operators/sql.py", line 284, in execute
    output = hook.run(
             ^^^^^^^^^
  File "/home/airflow/.local/lib/python3.12/site-packages/airflow/providers/common/sql/hooks/sql.py", line 494, in run
    with self._create_autocommit_connection(autocommit) as conn:
         ^^^^^^^^^^^^^^^^^^^^^^^^^^^^^^^^^^^^^^^^^^^^^^
  File "/usr/local/lib/python3.12/contextlib.py", line 137, in __enter__
    return next(self.gen)
           ^^^^^^^^^^^^^^
  File "/home/airflow/.local/lib/python3.12/site-packages/airflow/providers/common/sql/hooks/sql.py", line 618, in _create_autocommit_connection
    with closing(self.get_conn()) as conn:
                 ^^^^^^^^^^^^^^^
  File "/home/airflow/.local/lib/python3.12/site-packages/airflow/providers/postgres/hooks/postgres.py", line 189, in get_conn
    self.conn = psycopg2.connect(**conn_args)
                ^^^^^^^^^^^^^^^^^^^^^^^^^^^^^
  File "/home/airflow/.local/lib/python3.12/site-packages/psycopg2/__init__.py", line 122, in connect
    conn = _connect(dsn, connection_factory=connection_factory, **kwasync)
           ^^^^^^^^^^^^^^^^^^^^^^^^^^^^^^^^^^^^^^^^^^^^^^^^^^^^^^^^^^^^^^^
psycopg2.OperationalError: connection to server at "localhost" (::1), port 5432 failed: Connection refused
	Is the server running on that host and accepting TCP/IP connections?
connection to server at "localhost" (127.0.0.1), port 5432 failed: Connection refused
	Is the server running on that host and accepting TCP/IP connections?

[2025-01-25T17:04:02.254+0000] {logging_mixin.py:190} INFO - Task instance in failure state
[2025-01-25T17:04:02.257+0000] {logging_mixin.py:190} INFO - Task start:2025-01-25 17:03:57.357821+00:00 end:2025-01-25 17:04:02.251260+00:00 duration:4.893439
[2025-01-25T17:04:02.262+0000] {logging_mixin.py:190} INFO - Task:<Task(PostgresOperator): create_table> dag:<DAG: fetch_and_store_ebooks> dagrun:<DagRun fetch_and_store_ebooks @ 2025-01-12 00:00:00+00:00: scheduled__2025-01-12T00:00:00+00:00, state:running, queued_at: 2025-01-25 17:02:07.885961+00:00. externally triggered: False>
[2025-01-25T17:04:02.271+0000] {logging_mixin.py:190} INFO - Failure caused by connection to server at "localhost" (::1), port 5432 failed: Connection refused
	Is the server running on that host and accepting TCP/IP connections?
connection to server at "localhost" (127.0.0.1), port 5432 failed: Connection refused
	Is the server running on that host and accepting TCP/IP connections?
[2025-01-25T17:04:02.282+0000] {taskinstance.py:1225} INFO - Marking task as UP_FOR_RETRY. dag_id=fetch_and_store_ebooks, task_id=create_table, run_id=scheduled__2025-01-12T00:00:00+00:00, execution_date=20250112T000000, start_date=20250125T170357, end_date=20250125T170402
[2025-01-25T17:04:02.519+0000] {taskinstance.py:340} INFO - ::group::Post task execution logs
[2025-01-25T17:04:02.537+0000] {standard_task_runner.py:124} ERROR - Failed to execute job 460 for task create_table (connection to server at "localhost" (::1), port 5432 failed: Connection refused
	Is the server running on that host and accepting TCP/IP connections?
connection to server at "localhost" (127.0.0.1), port 5432 failed: Connection refused
	Is the server running on that host and accepting TCP/IP connections?
; 3810)
Traceback (most recent call last):
  File "/home/airflow/.local/lib/python3.12/site-packages/airflow/task/task_runner/standard_task_runner.py", line 117, in _start_by_fork
    ret = args.func(args, dag=self.dag)
          ^^^^^^^^^^^^^^^^^^^^^^^^^^^^^
  File "/home/airflow/.local/lib/python3.12/site-packages/airflow/cli/cli_config.py", line 49, in command
    return func(*args, **kwargs)
           ^^^^^^^^^^^^^^^^^^^^^
  File "/home/airflow/.local/lib/python3.12/site-packages/airflow/utils/cli.py", line 116, in wrapper
    return f(*args, **kwargs)
           ^^^^^^^^^^^^^^^^^^
  File "/home/airflow/.local/lib/python3.12/site-packages/airflow/cli/commands/task_command.py", line 483, in task_run
    task_return_code = _run_task_by_selected_method(args, _dag, ti)
                       ^^^^^^^^^^^^^^^^^^^^^^^^^^^^^^^^^^^^^^^^^^^^
  File "/home/airflow/.local/lib/python3.12/site-packages/airflow/cli/commands/task_command.py", line 256, in _run_task_by_selected_method
    return _run_raw_task(args, ti)
           ^^^^^^^^^^^^^^^^^^^^^^^
  File "/home/airflow/.local/lib/python3.12/site-packages/airflow/cli/commands/task_command.py", line 341, in _run_raw_task
    return ti._run_raw_task(
           ^^^^^^^^^^^^^^^^^
  File "/home/airflow/.local/lib/python3.12/site-packages/airflow/utils/session.py", line 97, in wrapper
    return func(*args, session=session, **kwargs)
           ^^^^^^^^^^^^^^^^^^^^^^^^^^^^^^^^^^^^^^
  File "/home/airflow/.local/lib/python3.12/site-packages/airflow/models/taskinstance.py", line 3005, in _run_raw_task
    return _run_raw_task(
           ^^^^^^^^^^^^^^
  File "/home/airflow/.local/lib/python3.12/site-packages/airflow/models/taskinstance.py", line 273, in _run_raw_task
    TaskInstance._execute_task_with_callbacks(
  File "/home/airflow/.local/lib/python3.12/site-packages/airflow/models/taskinstance.py", line 3159, in _execute_task_with_callbacks
    result = self._execute_task(context, task_orig)
             ^^^^^^^^^^^^^^^^^^^^^^^^^^^^^^^^^^^^^^
  File "/home/airflow/.local/lib/python3.12/site-packages/airflow/models/taskinstance.py", line 3183, in _execute_task
    return _execute_task(self, context, task_orig)
           ^^^^^^^^^^^^^^^^^^^^^^^^^^^^^^^^^^^^^^^
  File "/home/airflow/.local/lib/python3.12/site-packages/airflow/models/taskinstance.py", line 767, in _execute_task
    result = _execute_callable(context=context, **execute_callable_kwargs)
             ^^^^^^^^^^^^^^^^^^^^^^^^^^^^^^^^^^^^^^^^^^^^^^^^^^^^^^^^^^^^^
  File "/home/airflow/.local/lib/python3.12/site-packages/airflow/models/taskinstance.py", line 733, in _execute_callable
    return ExecutionCallableRunner(
           ^^^^^^^^^^^^^^^^^^^^^^^^
  File "/home/airflow/.local/lib/python3.12/site-packages/airflow/utils/operator_helpers.py", line 252, in run
    return self.func(*args, **kwargs)
           ^^^^^^^^^^^^^^^^^^^^^^^^^^
  File "/home/airflow/.local/lib/python3.12/site-packages/airflow/models/baseoperator.py", line 422, in wrapper
    return func(self, *args, **kwargs)
           ^^^^^^^^^^^^^^^^^^^^^^^^^^^
  File "/home/airflow/.local/lib/python3.12/site-packages/airflow/providers/common/sql/operators/sql.py", line 284, in execute
    output = hook.run(
             ^^^^^^^^^
  File "/home/airflow/.local/lib/python3.12/site-packages/airflow/providers/common/sql/hooks/sql.py", line 494, in run
    with self._create_autocommit_connection(autocommit) as conn:
         ^^^^^^^^^^^^^^^^^^^^^^^^^^^^^^^^^^^^^^^^^^^^^^
  File "/usr/local/lib/python3.12/contextlib.py", line 137, in __enter__
    return next(self.gen)
           ^^^^^^^^^^^^^^
  File "/home/airflow/.local/lib/python3.12/site-packages/airflow/providers/common/sql/hooks/sql.py", line 618, in _create_autocommit_connection
    with closing(self.get_conn()) as conn:
                 ^^^^^^^^^^^^^^^
  File "/home/airflow/.local/lib/python3.12/site-packages/airflow/providers/postgres/hooks/postgres.py", line 189, in get_conn
    self.conn = psycopg2.connect(**conn_args)
                ^^^^^^^^^^^^^^^^^^^^^^^^^^^^^
  File "/home/airflow/.local/lib/python3.12/site-packages/psycopg2/__init__.py", line 122, in connect
    conn = _connect(dsn, connection_factory=connection_factory, **kwasync)
           ^^^^^^^^^^^^^^^^^^^^^^^^^^^^^^^^^^^^^^^^^^^^^^^^^^^^^^^^^^^^^^^
psycopg2.OperationalError: connection to server at "localhost" (::1), port 5432 failed: Connection refused
	Is the server running on that host and accepting TCP/IP connections?
connection to server at "localhost" (127.0.0.1), port 5432 failed: Connection refused
	Is the server running on that host and accepting TCP/IP connections?

[2025-01-25T17:04:05.966+0000] {local_task_job_runner.py:266} INFO - Task exited with return code 1
[2025-01-25T17:04:06.260+0000] {taskinstance.py:3895} INFO - 0 downstream tasks scheduled from follow-on schedule check
[2025-01-25T17:04:06.290+0000] {local_task_job_runner.py:245} INFO - ::endgroup::
[2025-01-26T06:35:10.992+0000] {local_task_job_runner.py:123} INFO - ::group::Pre task execution logs
[2025-01-26T06:35:11.093+0000] {taskinstance.py:2613} INFO - Dependencies all met for dep_context=non-requeueable deps ti=<TaskInstance: fetch_and_store_ebooks.create_table scheduled__2025-01-12T00:00:00+00:00 [queued]>
[2025-01-26T06:35:11.139+0000] {taskinstance.py:2613} INFO - Dependencies all met for dep_context=requeueable deps ti=<TaskInstance: fetch_and_store_ebooks.create_table scheduled__2025-01-12T00:00:00+00:00 [queued]>
[2025-01-26T06:35:11.141+0000] {taskinstance.py:2866} INFO - Starting attempt 1 of 2
[2025-01-26T06:35:11.993+0000] {taskinstance.py:2889} INFO - Executing <Task(PostgresOperator): create_table> on 2025-01-12 00:00:00+00:00
[2025-01-26T06:35:12.086+0000] {warnings.py:112} WARNING - /home/***/.local/lib/python3.12/site-packages/***/task/task_runner/standard_task_runner.py:70: DeprecationWarning: This process (pid=464) is multi-threaded, use of fork() may lead to deadlocks in the child.
  pid = os.fork()

[2025-01-26T06:35:12.130+0000] {standard_task_runner.py:72} INFO - Started process 508 to run task
[2025-01-26T06:35:12.116+0000] {standard_task_runner.py:104} INFO - Running: ['***', 'tasks', 'run', 'fetch_and_store_ebooks', 'create_table', 'scheduled__2025-01-12T00:00:00+00:00', '--job-id', '564', '--raw', '--subdir', 'DAGS_FOLDER/app.py', '--cfg-path', '/tmp/tmpe_zuwtdz']
[2025-01-26T06:35:12.146+0000] {standard_task_runner.py:105} INFO - Job 564: Subtask create_table
[2025-01-26T06:35:12.668+0000] {task_command.py:467} INFO - Running <TaskInstance: fetch_and_store_ebooks.create_table scheduled__2025-01-12T00:00:00+00:00 [running]> on host 34edd304782d
[2025-01-26T06:35:13.355+0000] {taskinstance.py:3132} INFO - Exporting env vars: AIRFLOW_CTX_DAG_OWNER='***' AIRFLOW_CTX_DAG_ID='fetch_and_store_ebooks' AIRFLOW_CTX_TASK_ID='create_table' AIRFLOW_CTX_EXECUTION_DATE='2025-01-12T00:00:00+00:00' AIRFLOW_CTX_TRY_NUMBER='1' AIRFLOW_CTX_DAG_RUN_ID='scheduled__2025-01-12T00:00:00+00:00'
[2025-01-26T06:35:13.364+0000] {logging_mixin.py:190} INFO - Task instance is in running state
[2025-01-26T06:35:13.366+0000] {logging_mixin.py:190} INFO -  Previous state of the Task instance: queued
[2025-01-26T06:35:13.368+0000] {logging_mixin.py:190} INFO - Current task name:create_table state:running start_date:2025-01-26 06:35:11.098015+00:00
[2025-01-26T06:35:13.372+0000] {logging_mixin.py:190} INFO - Dag name:fetch_and_store_ebooks and current dag run status:running
[2025-01-26T06:35:13.374+0000] {taskinstance.py:731} INFO - ::endgroup::
[2025-01-26T06:35:13.379+0000] {sql.py:278} INFO - Executing: 
    CREATE TABLE IF NOT EXISTS ebooks (
        id SERIAL PRIMARY KEY,
        judul TEXT NOT NULL,
        penulis TEXT,
        link TEXT
    );
    
[2025-01-26T06:35:13.414+0000] {base.py:84} INFO - Retrieving connection 'ebooks_connection'
[2025-01-26T06:35:13.447+0000] {base.py:84} INFO - Retrieving connection 'ebooks_connection'
[2025-01-26T06:35:13.640+0000] {sql.py:553} INFO - Running statement: 
    CREATE TABLE IF NOT EXISTS ebooks (
        id SERIAL PRIMARY KEY,
        judul TEXT NOT NULL,
        penulis TEXT,
        link TEXT
    );
    , parameters: None
[2025-01-26T06:35:13.657+0000] {taskinstance.py:3311} ERROR - Task failed with exception
Traceback (most recent call last):
  File "/home/airflow/.local/lib/python3.12/site-packages/airflow/models/taskinstance.py", line 767, in _execute_task
    result = _execute_callable(context=context, **execute_callable_kwargs)
             ^^^^^^^^^^^^^^^^^^^^^^^^^^^^^^^^^^^^^^^^^^^^^^^^^^^^^^^^^^^^^
  File "/home/airflow/.local/lib/python3.12/site-packages/airflow/models/taskinstance.py", line 733, in _execute_callable
    return ExecutionCallableRunner(
           ^^^^^^^^^^^^^^^^^^^^^^^^
  File "/home/airflow/.local/lib/python3.12/site-packages/airflow/utils/operator_helpers.py", line 252, in run
    return self.func(*args, **kwargs)
           ^^^^^^^^^^^^^^^^^^^^^^^^^^
  File "/home/airflow/.local/lib/python3.12/site-packages/airflow/models/baseoperator.py", line 422, in wrapper
    return func(self, *args, **kwargs)
           ^^^^^^^^^^^^^^^^^^^^^^^^^^^
  File "/home/airflow/.local/lib/python3.12/site-packages/airflow/providers/common/sql/operators/sql.py", line 284, in execute
    output = hook.run(
             ^^^^^^^^^
  File "/home/airflow/.local/lib/python3.12/site-packages/airflow/providers/common/sql/hooks/sql.py", line 498, in run
    self._run_command(cur, sql_statement, parameters)
  File "/home/airflow/.local/lib/python3.12/site-packages/airflow/providers/common/sql/hooks/sql.py", line 558, in _run_command
    cur.execute(sql_statement)
psycopg2.errors.InsufficientPrivilege: permission denied for schema public
LINE 2:     CREATE TABLE IF NOT EXISTS ebooks (
                                       ^

[2025-01-26T06:35:13.717+0000] {logging_mixin.py:190} INFO - Task instance in failure state
[2025-01-26T06:35:13.720+0000] {logging_mixin.py:190} INFO - Task start:2025-01-26 06:35:11.098015+00:00 end:2025-01-26 06:35:13.715488+00:00 duration:2.617473
[2025-01-26T06:35:13.727+0000] {logging_mixin.py:190} INFO - Task:<Task(PostgresOperator): create_table> dag:<DAG: fetch_and_store_ebooks> dagrun:<DagRun fetch_and_store_ebooks @ 2025-01-12 00:00:00+00:00: scheduled__2025-01-12T00:00:00+00:00, state:running, queued_at: 2025-01-26 06:33:35.785346+00:00. externally triggered: False>
[2025-01-26T06:35:13.729+0000] {logging_mixin.py:190} INFO - Failure caused by permission denied for schema public
LINE 2:     CREATE TABLE IF NOT EXISTS ebooks (
                                       ^
[2025-01-26T06:35:13.731+0000] {taskinstance.py:1225} INFO - Marking task as UP_FOR_RETRY. dag_id=fetch_and_store_ebooks, task_id=create_table, run_id=scheduled__2025-01-12T00:00:00+00:00, execution_date=20250112T000000, start_date=20250126T063511, end_date=20250126T063513
[2025-01-26T06:35:13.805+0000] {taskinstance.py:340} INFO - ::group::Post task execution logs
[2025-01-26T06:35:13.807+0000] {standard_task_runner.py:124} ERROR - Failed to execute job 564 for task create_table (permission denied for schema public
LINE 2:     CREATE TABLE IF NOT EXISTS ebooks (
                                       ^
; 508)
Traceback (most recent call last):
  File "/home/airflow/.local/lib/python3.12/site-packages/airflow/task/task_runner/standard_task_runner.py", line 117, in _start_by_fork
    ret = args.func(args, dag=self.dag)
          ^^^^^^^^^^^^^^^^^^^^^^^^^^^^^
  File "/home/airflow/.local/lib/python3.12/site-packages/airflow/cli/cli_config.py", line 49, in command
    return func(*args, **kwargs)
           ^^^^^^^^^^^^^^^^^^^^^
  File "/home/airflow/.local/lib/python3.12/site-packages/airflow/utils/cli.py", line 116, in wrapper
    return f(*args, **kwargs)
           ^^^^^^^^^^^^^^^^^^
  File "/home/airflow/.local/lib/python3.12/site-packages/airflow/cli/commands/task_command.py", line 483, in task_run
    task_return_code = _run_task_by_selected_method(args, _dag, ti)
                       ^^^^^^^^^^^^^^^^^^^^^^^^^^^^^^^^^^^^^^^^^^^^
  File "/home/airflow/.local/lib/python3.12/site-packages/airflow/cli/commands/task_command.py", line 256, in _run_task_by_selected_method
    return _run_raw_task(args, ti)
           ^^^^^^^^^^^^^^^^^^^^^^^
  File "/home/airflow/.local/lib/python3.12/site-packages/airflow/cli/commands/task_command.py", line 341, in _run_raw_task
    return ti._run_raw_task(
           ^^^^^^^^^^^^^^^^^
  File "/home/airflow/.local/lib/python3.12/site-packages/airflow/utils/session.py", line 97, in wrapper
    return func(*args, session=session, **kwargs)
           ^^^^^^^^^^^^^^^^^^^^^^^^^^^^^^^^^^^^^^
  File "/home/airflow/.local/lib/python3.12/site-packages/airflow/models/taskinstance.py", line 3005, in _run_raw_task
    return _run_raw_task(
           ^^^^^^^^^^^^^^
  File "/home/airflow/.local/lib/python3.12/site-packages/airflow/models/taskinstance.py", line 273, in _run_raw_task
    TaskInstance._execute_task_with_callbacks(
  File "/home/airflow/.local/lib/python3.12/site-packages/airflow/models/taskinstance.py", line 3159, in _execute_task_with_callbacks
    result = self._execute_task(context, task_orig)
             ^^^^^^^^^^^^^^^^^^^^^^^^^^^^^^^^^^^^^^
  File "/home/airflow/.local/lib/python3.12/site-packages/airflow/models/taskinstance.py", line 3183, in _execute_task
    return _execute_task(self, context, task_orig)
           ^^^^^^^^^^^^^^^^^^^^^^^^^^^^^^^^^^^^^^^
  File "/home/airflow/.local/lib/python3.12/site-packages/airflow/models/taskinstance.py", line 767, in _execute_task
    result = _execute_callable(context=context, **execute_callable_kwargs)
             ^^^^^^^^^^^^^^^^^^^^^^^^^^^^^^^^^^^^^^^^^^^^^^^^^^^^^^^^^^^^^
  File "/home/airflow/.local/lib/python3.12/site-packages/airflow/models/taskinstance.py", line 733, in _execute_callable
    return ExecutionCallableRunner(
           ^^^^^^^^^^^^^^^^^^^^^^^^
  File "/home/airflow/.local/lib/python3.12/site-packages/airflow/utils/operator_helpers.py", line 252, in run
    return self.func(*args, **kwargs)
           ^^^^^^^^^^^^^^^^^^^^^^^^^^
  File "/home/airflow/.local/lib/python3.12/site-packages/airflow/models/baseoperator.py", line 422, in wrapper
    return func(self, *args, **kwargs)
           ^^^^^^^^^^^^^^^^^^^^^^^^^^^
  File "/home/airflow/.local/lib/python3.12/site-packages/airflow/providers/common/sql/operators/sql.py", line 284, in execute
    output = hook.run(
             ^^^^^^^^^
  File "/home/airflow/.local/lib/python3.12/site-packages/airflow/providers/common/sql/hooks/sql.py", line 498, in run
    self._run_command(cur, sql_statement, parameters)
  File "/home/airflow/.local/lib/python3.12/site-packages/airflow/providers/common/sql/hooks/sql.py", line 558, in _run_command
    cur.execute(sql_statement)
psycopg2.errors.InsufficientPrivilege: permission denied for schema public
LINE 2:     CREATE TABLE IF NOT EXISTS ebooks (
                                       ^

[2025-01-26T06:35:13.884+0000] {local_task_job_runner.py:266} INFO - Task exited with return code 1
[2025-01-26T06:35:13.999+0000] {taskinstance.py:3895} INFO - 0 downstream tasks scheduled from follow-on schedule check
[2025-01-26T06:35:14.040+0000] {local_task_job_runner.py:245} INFO - ::endgroup::
[2025-01-26T07:22:52.792+0000] {local_task_job_runner.py:123} INFO - ::group::Pre task execution logs
[2025-01-26T07:22:52.911+0000] {taskinstance.py:2613} INFO - Dependencies all met for dep_context=non-requeueable deps ti=<TaskInstance: fetch_and_store_ebooks.create_table scheduled__2025-01-12T00:00:00+00:00 [queued]>
[2025-01-26T07:22:53.054+0000] {taskinstance.py:2613} INFO - Dependencies all met for dep_context=requeueable deps ti=<TaskInstance: fetch_and_store_ebooks.create_table scheduled__2025-01-12T00:00:00+00:00 [queued]>
[2025-01-26T07:22:53.058+0000] {taskinstance.py:2866} INFO - Starting attempt 1 of 2
[2025-01-26T07:22:53.882+0000] {taskinstance.py:2889} INFO - Executing <Task(PostgresOperator): create_table> on 2025-01-12 00:00:00+00:00
[2025-01-26T07:22:53.914+0000] {warnings.py:112} WARNING - /home/***/.local/lib/python3.12/site-packages/***/task/task_runner/standard_task_runner.py:70: DeprecationWarning: This process (pid=1304) is multi-threaded, use of fork() may lead to deadlocks in the child.
  pid = os.fork()

[2025-01-26T07:22:53.920+0000] {standard_task_runner.py:72} INFO - Started process 1334 to run task
[2025-01-26T07:22:53.942+0000] {standard_task_runner.py:104} INFO - Running: ['***', 'tasks', 'run', 'fetch_and_store_ebooks', 'create_table', 'scheduled__2025-01-12T00:00:00+00:00', '--job-id', '644', '--raw', '--subdir', 'DAGS_FOLDER/app.py', '--cfg-path', '/tmp/tmpbqnb3ryg']
[2025-01-26T07:22:53.950+0000] {standard_task_runner.py:105} INFO - Job 644: Subtask create_table
[2025-01-26T07:22:54.412+0000] {task_command.py:467} INFO - Running <TaskInstance: fetch_and_store_ebooks.create_table scheduled__2025-01-12T00:00:00+00:00 [running]> on host 34edd304782d
[2025-01-26T07:22:55.204+0000] {taskinstance.py:3132} INFO - Exporting env vars: AIRFLOW_CTX_DAG_OWNER='***' AIRFLOW_CTX_DAG_ID='fetch_and_store_ebooks' AIRFLOW_CTX_TASK_ID='create_table' AIRFLOW_CTX_EXECUTION_DATE='2025-01-12T00:00:00+00:00' AIRFLOW_CTX_TRY_NUMBER='1' AIRFLOW_CTX_DAG_RUN_ID='scheduled__2025-01-12T00:00:00+00:00'
[2025-01-26T07:22:55.229+0000] {logging_mixin.py:190} INFO - Task instance is in running state
[2025-01-26T07:22:55.238+0000] {logging_mixin.py:190} INFO -  Previous state of the Task instance: queued
[2025-01-26T07:22:55.248+0000] {logging_mixin.py:190} INFO - Current task name:create_table state:running start_date:2025-01-26 07:22:52.932680+00:00
[2025-01-26T07:22:55.251+0000] {logging_mixin.py:190} INFO - Dag name:fetch_and_store_ebooks and current dag run status:running
[2025-01-26T07:22:55.257+0000] {taskinstance.py:731} INFO - ::endgroup::
[2025-01-26T07:22:55.262+0000] {sql.py:278} INFO - Executing: 
    CREATE TABLE IF NOT EXISTS ebooks (
        id SERIAL PRIMARY KEY,
        judul TEXT NOT NULL,
        penulis TEXT,
        link TEXT
    );
    
[2025-01-26T07:22:55.369+0000] {base.py:84} INFO - Retrieving connection 'ebooks_connection'
[2025-01-26T07:22:55.436+0000] {base.py:84} INFO - Retrieving connection 'ebooks_connection'
[2025-01-26T07:22:55.874+0000] {sql.py:553} INFO - Running statement: 
    CREATE TABLE IF NOT EXISTS ebooks (
        id SERIAL PRIMARY KEY,
        judul TEXT NOT NULL,
        penulis TEXT,
        link TEXT
    );
    , parameters: None
[2025-01-26T07:22:55.914+0000] {taskinstance.py:3311} ERROR - Task failed with exception
Traceback (most recent call last):
  File "/home/airflow/.local/lib/python3.12/site-packages/airflow/models/taskinstance.py", line 767, in _execute_task
    result = _execute_callable(context=context, **execute_callable_kwargs)
             ^^^^^^^^^^^^^^^^^^^^^^^^^^^^^^^^^^^^^^^^^^^^^^^^^^^^^^^^^^^^^
  File "/home/airflow/.local/lib/python3.12/site-packages/airflow/models/taskinstance.py", line 733, in _execute_callable
    return ExecutionCallableRunner(
           ^^^^^^^^^^^^^^^^^^^^^^^^
  File "/home/airflow/.local/lib/python3.12/site-packages/airflow/utils/operator_helpers.py", line 252, in run
    return self.func(*args, **kwargs)
           ^^^^^^^^^^^^^^^^^^^^^^^^^^
  File "/home/airflow/.local/lib/python3.12/site-packages/airflow/models/baseoperator.py", line 422, in wrapper
    return func(self, *args, **kwargs)
           ^^^^^^^^^^^^^^^^^^^^^^^^^^^
  File "/home/airflow/.local/lib/python3.12/site-packages/airflow/providers/common/sql/operators/sql.py", line 284, in execute
    output = hook.run(
             ^^^^^^^^^
  File "/home/airflow/.local/lib/python3.12/site-packages/airflow/providers/common/sql/hooks/sql.py", line 498, in run
    self._run_command(cur, sql_statement, parameters)
  File "/home/airflow/.local/lib/python3.12/site-packages/airflow/providers/common/sql/hooks/sql.py", line 558, in _run_command
    cur.execute(sql_statement)
psycopg2.errors.InsufficientPrivilege: permission denied for schema public
LINE 2:     CREATE TABLE IF NOT EXISTS ebooks (
                                       ^

[2025-01-26T07:22:56.065+0000] {logging_mixin.py:190} INFO - Task instance in failure state
[2025-01-26T07:22:56.074+0000] {logging_mixin.py:190} INFO - Task start:2025-01-26 07:22:52.932680+00:00 end:2025-01-26 07:22:56.063630+00:00 duration:3.13095
[2025-01-26T07:22:56.081+0000] {logging_mixin.py:190} INFO - Task:<Task(PostgresOperator): create_table> dag:<DAG: fetch_and_store_ebooks> dagrun:<DagRun fetch_and_store_ebooks @ 2025-01-12 00:00:00+00:00: scheduled__2025-01-12T00:00:00+00:00, state:running, queued_at: 2025-01-26 07:21:35.768446+00:00. externally triggered: False>
[2025-01-26T07:22:56.102+0000] {logging_mixin.py:190} INFO - Failure caused by permission denied for schema public
LINE 2:     CREATE TABLE IF NOT EXISTS ebooks (
                                       ^
[2025-01-26T07:22:56.130+0000] {taskinstance.py:1225} INFO - Marking task as UP_FOR_RETRY. dag_id=fetch_and_store_ebooks, task_id=create_table, run_id=scheduled__2025-01-12T00:00:00+00:00, execution_date=20250112T000000, start_date=20250126T072252, end_date=20250126T072256
[2025-01-26T07:22:56.298+0000] {taskinstance.py:340} INFO - ::group::Post task execution logs
[2025-01-26T07:22:56.301+0000] {standard_task_runner.py:124} ERROR - Failed to execute job 644 for task create_table (permission denied for schema public
LINE 2:     CREATE TABLE IF NOT EXISTS ebooks (
                                       ^
; 1334)
Traceback (most recent call last):
  File "/home/airflow/.local/lib/python3.12/site-packages/airflow/task/task_runner/standard_task_runner.py", line 117, in _start_by_fork
    ret = args.func(args, dag=self.dag)
          ^^^^^^^^^^^^^^^^^^^^^^^^^^^^^
  File "/home/airflow/.local/lib/python3.12/site-packages/airflow/cli/cli_config.py", line 49, in command
    return func(*args, **kwargs)
           ^^^^^^^^^^^^^^^^^^^^^
  File "/home/airflow/.local/lib/python3.12/site-packages/airflow/utils/cli.py", line 116, in wrapper
    return f(*args, **kwargs)
           ^^^^^^^^^^^^^^^^^^
  File "/home/airflow/.local/lib/python3.12/site-packages/airflow/cli/commands/task_command.py", line 483, in task_run
    task_return_code = _run_task_by_selected_method(args, _dag, ti)
                       ^^^^^^^^^^^^^^^^^^^^^^^^^^^^^^^^^^^^^^^^^^^^
  File "/home/airflow/.local/lib/python3.12/site-packages/airflow/cli/commands/task_command.py", line 256, in _run_task_by_selected_method
    return _run_raw_task(args, ti)
           ^^^^^^^^^^^^^^^^^^^^^^^
  File "/home/airflow/.local/lib/python3.12/site-packages/airflow/cli/commands/task_command.py", line 341, in _run_raw_task
    return ti._run_raw_task(
           ^^^^^^^^^^^^^^^^^
  File "/home/airflow/.local/lib/python3.12/site-packages/airflow/utils/session.py", line 97, in wrapper
    return func(*args, session=session, **kwargs)
           ^^^^^^^^^^^^^^^^^^^^^^^^^^^^^^^^^^^^^^
  File "/home/airflow/.local/lib/python3.12/site-packages/airflow/models/taskinstance.py", line 3005, in _run_raw_task
    return _run_raw_task(
           ^^^^^^^^^^^^^^
  File "/home/airflow/.local/lib/python3.12/site-packages/airflow/models/taskinstance.py", line 273, in _run_raw_task
    TaskInstance._execute_task_with_callbacks(
  File "/home/airflow/.local/lib/python3.12/site-packages/airflow/models/taskinstance.py", line 3159, in _execute_task_with_callbacks
    result = self._execute_task(context, task_orig)
             ^^^^^^^^^^^^^^^^^^^^^^^^^^^^^^^^^^^^^^
  File "/home/airflow/.local/lib/python3.12/site-packages/airflow/models/taskinstance.py", line 3183, in _execute_task
    return _execute_task(self, context, task_orig)
           ^^^^^^^^^^^^^^^^^^^^^^^^^^^^^^^^^^^^^^^
  File "/home/airflow/.local/lib/python3.12/site-packages/airflow/models/taskinstance.py", line 767, in _execute_task
    result = _execute_callable(context=context, **execute_callable_kwargs)
             ^^^^^^^^^^^^^^^^^^^^^^^^^^^^^^^^^^^^^^^^^^^^^^^^^^^^^^^^^^^^^
  File "/home/airflow/.local/lib/python3.12/site-packages/airflow/models/taskinstance.py", line 733, in _execute_callable
    return ExecutionCallableRunner(
           ^^^^^^^^^^^^^^^^^^^^^^^^
  File "/home/airflow/.local/lib/python3.12/site-packages/airflow/utils/operator_helpers.py", line 252, in run
    return self.func(*args, **kwargs)
           ^^^^^^^^^^^^^^^^^^^^^^^^^^
  File "/home/airflow/.local/lib/python3.12/site-packages/airflow/models/baseoperator.py", line 422, in wrapper
    return func(self, *args, **kwargs)
           ^^^^^^^^^^^^^^^^^^^^^^^^^^^
  File "/home/airflow/.local/lib/python3.12/site-packages/airflow/providers/common/sql/operators/sql.py", line 284, in execute
    output = hook.run(
             ^^^^^^^^^
  File "/home/airflow/.local/lib/python3.12/site-packages/airflow/providers/common/sql/hooks/sql.py", line 498, in run
    self._run_command(cur, sql_statement, parameters)
  File "/home/airflow/.local/lib/python3.12/site-packages/airflow/providers/common/sql/hooks/sql.py", line 558, in _run_command
    cur.execute(sql_statement)
psycopg2.errors.InsufficientPrivilege: permission denied for schema public
LINE 2:     CREATE TABLE IF NOT EXISTS ebooks (
                                       ^

[2025-01-26T07:22:56.453+0000] {local_task_job_runner.py:266} INFO - Task exited with return code 1
[2025-01-26T07:22:56.639+0000] {taskinstance.py:3895} INFO - 0 downstream tasks scheduled from follow-on schedule check
[2025-01-26T07:22:56.668+0000] {local_task_job_runner.py:245} INFO - ::endgroup::
[2025-01-26T07:48:17.038+0000] {local_task_job_runner.py:123} INFO - ::group::Pre task execution logs
[2025-01-26T07:48:17.282+0000] {taskinstance.py:2613} INFO - Dependencies all met for dep_context=non-requeueable deps ti=<TaskInstance: fetch_and_store_ebooks.create_table scheduled__2025-01-12T00:00:00+00:00 [queued]>
[2025-01-26T07:48:17.351+0000] {taskinstance.py:2613} INFO - Dependencies all met for dep_context=requeueable deps ti=<TaskInstance: fetch_and_store_ebooks.create_table scheduled__2025-01-12T00:00:00+00:00 [queued]>
[2025-01-26T07:48:17.353+0000] {taskinstance.py:2866} INFO - Starting attempt 1 of 2
[2025-01-26T07:48:17.961+0000] {taskinstance.py:2889} INFO - Executing <Task(PostgresOperator): create_table> on 2025-01-12 00:00:00+00:00
[2025-01-26T07:48:18.016+0000] {warnings.py:112} WARNING - /home/***/.local/lib/python3.12/site-packages/***/task/task_runner/standard_task_runner.py:70: DeprecationWarning: This process (pid=1966) is multi-threaded, use of fork() may lead to deadlocks in the child.
  pid = os.fork()

[2025-01-26T07:48:18.047+0000] {standard_task_runner.py:72} INFO - Started process 2001 to run task
[2025-01-26T07:48:18.094+0000] {standard_task_runner.py:104} INFO - Running: ['***', 'tasks', 'run', 'fetch_and_store_ebooks', 'create_table', 'scheduled__2025-01-12T00:00:00+00:00', '--job-id', '734', '--raw', '--subdir', 'DAGS_FOLDER/app.py', '--cfg-path', '/tmp/tmpca8s2wk3']
[2025-01-26T07:48:18.119+0000] {standard_task_runner.py:105} INFO - Job 734: Subtask create_table
[2025-01-26T07:48:18.561+0000] {task_command.py:467} INFO - Running <TaskInstance: fetch_and_store_ebooks.create_table scheduled__2025-01-12T00:00:00+00:00 [running]> on host 34edd304782d
[2025-01-26T07:48:19.911+0000] {taskinstance.py:3132} INFO - Exporting env vars: AIRFLOW_CTX_DAG_OWNER='***' AIRFLOW_CTX_DAG_ID='fetch_and_store_ebooks' AIRFLOW_CTX_TASK_ID='create_table' AIRFLOW_CTX_EXECUTION_DATE='2025-01-12T00:00:00+00:00' AIRFLOW_CTX_TRY_NUMBER='1' AIRFLOW_CTX_DAG_RUN_ID='scheduled__2025-01-12T00:00:00+00:00'
[2025-01-26T07:48:19.921+0000] {logging_mixin.py:190} INFO - Task instance is in running state
[2025-01-26T07:48:19.932+0000] {logging_mixin.py:190} INFO -  Previous state of the Task instance: queued
[2025-01-26T07:48:19.950+0000] {logging_mixin.py:190} INFO - Current task name:create_table state:running start_date:2025-01-26 07:48:17.299389+00:00
[2025-01-26T07:48:19.980+0000] {logging_mixin.py:190} INFO - Dag name:fetch_and_store_ebooks and current dag run status:running
[2025-01-26T07:48:19.992+0000] {taskinstance.py:731} INFO - ::endgroup::
[2025-01-26T07:48:19.994+0000] {sql.py:278} INFO - Executing: 
    CREATE TABLE IF NOT EXISTS ebooks (
        id SERIAL PRIMARY KEY,
        judul TEXT NOT NULL,
        penulis TEXT,
        link TEXT
    );
    
[2025-01-26T07:48:20.052+0000] {base.py:84} INFO - Retrieving connection 'ebooks_connection'
[2025-01-26T07:48:20.138+0000] {base.py:84} INFO - Retrieving connection 'ebooks_connection'
[2025-01-26T07:48:20.449+0000] {sql.py:553} INFO - Running statement: 
    CREATE TABLE IF NOT EXISTS ebooks (
        id SERIAL PRIMARY KEY,
        judul TEXT NOT NULL,
        penulis TEXT,
        link TEXT
    );
    , parameters: None
[2025-01-26T07:48:20.488+0000] {taskinstance.py:3311} ERROR - Task failed with exception
Traceback (most recent call last):
  File "/home/airflow/.local/lib/python3.12/site-packages/airflow/models/taskinstance.py", line 767, in _execute_task
    result = _execute_callable(context=context, **execute_callable_kwargs)
             ^^^^^^^^^^^^^^^^^^^^^^^^^^^^^^^^^^^^^^^^^^^^^^^^^^^^^^^^^^^^^
  File "/home/airflow/.local/lib/python3.12/site-packages/airflow/models/taskinstance.py", line 733, in _execute_callable
    return ExecutionCallableRunner(
           ^^^^^^^^^^^^^^^^^^^^^^^^
  File "/home/airflow/.local/lib/python3.12/site-packages/airflow/utils/operator_helpers.py", line 252, in run
    return self.func(*args, **kwargs)
           ^^^^^^^^^^^^^^^^^^^^^^^^^^
  File "/home/airflow/.local/lib/python3.12/site-packages/airflow/models/baseoperator.py", line 422, in wrapper
    return func(self, *args, **kwargs)
           ^^^^^^^^^^^^^^^^^^^^^^^^^^^
  File "/home/airflow/.local/lib/python3.12/site-packages/airflow/providers/common/sql/operators/sql.py", line 284, in execute
    output = hook.run(
             ^^^^^^^^^
  File "/home/airflow/.local/lib/python3.12/site-packages/airflow/providers/common/sql/hooks/sql.py", line 498, in run
    self._run_command(cur, sql_statement, parameters)
  File "/home/airflow/.local/lib/python3.12/site-packages/airflow/providers/common/sql/hooks/sql.py", line 558, in _run_command
    cur.execute(sql_statement)
psycopg2.errors.InsufficientPrivilege: permission denied for schema public
LINE 2:     CREATE TABLE IF NOT EXISTS ebooks (
                                       ^

[2025-01-26T07:48:20.652+0000] {logging_mixin.py:190} INFO - Task instance in failure state
[2025-01-26T07:48:20.658+0000] {logging_mixin.py:190} INFO - Task start:2025-01-26 07:48:17.299389+00:00 end:2025-01-26 07:48:20.650097+00:00 duration:3.350708
[2025-01-26T07:48:20.664+0000] {logging_mixin.py:190} INFO - Task:<Task(PostgresOperator): create_table> dag:<DAG: fetch_and_store_ebooks> dagrun:<DagRun fetch_and_store_ebooks @ 2025-01-12 00:00:00+00:00: scheduled__2025-01-12T00:00:00+00:00, state:running, queued_at: 2025-01-26 07:46:57.036676+00:00. externally triggered: False>
[2025-01-26T07:48:20.670+0000] {logging_mixin.py:190} INFO - Failure caused by permission denied for schema public
LINE 2:     CREATE TABLE IF NOT EXISTS ebooks (
                                       ^
[2025-01-26T07:48:20.679+0000] {taskinstance.py:1225} INFO - Marking task as UP_FOR_RETRY. dag_id=fetch_and_store_ebooks, task_id=create_table, run_id=scheduled__2025-01-12T00:00:00+00:00, execution_date=20250112T000000, start_date=20250126T074817, end_date=20250126T074820
[2025-01-26T07:48:21.557+0000] {taskinstance.py:340} INFO - ::group::Post task execution logs
[2025-01-26T07:48:21.570+0000] {standard_task_runner.py:124} ERROR - Failed to execute job 734 for task create_table (permission denied for schema public
LINE 2:     CREATE TABLE IF NOT EXISTS ebooks (
                                       ^
; 2001)
Traceback (most recent call last):
  File "/home/airflow/.local/lib/python3.12/site-packages/airflow/task/task_runner/standard_task_runner.py", line 117, in _start_by_fork
    ret = args.func(args, dag=self.dag)
          ^^^^^^^^^^^^^^^^^^^^^^^^^^^^^
  File "/home/airflow/.local/lib/python3.12/site-packages/airflow/cli/cli_config.py", line 49, in command
    return func(*args, **kwargs)
           ^^^^^^^^^^^^^^^^^^^^^
  File "/home/airflow/.local/lib/python3.12/site-packages/airflow/utils/cli.py", line 116, in wrapper
    return f(*args, **kwargs)
           ^^^^^^^^^^^^^^^^^^
  File "/home/airflow/.local/lib/python3.12/site-packages/airflow/cli/commands/task_command.py", line 483, in task_run
    task_return_code = _run_task_by_selected_method(args, _dag, ti)
                       ^^^^^^^^^^^^^^^^^^^^^^^^^^^^^^^^^^^^^^^^^^^^
  File "/home/airflow/.local/lib/python3.12/site-packages/airflow/cli/commands/task_command.py", line 256, in _run_task_by_selected_method
    return _run_raw_task(args, ti)
           ^^^^^^^^^^^^^^^^^^^^^^^
  File "/home/airflow/.local/lib/python3.12/site-packages/airflow/cli/commands/task_command.py", line 341, in _run_raw_task
    return ti._run_raw_task(
           ^^^^^^^^^^^^^^^^^
  File "/home/airflow/.local/lib/python3.12/site-packages/airflow/utils/session.py", line 97, in wrapper
    return func(*args, session=session, **kwargs)
           ^^^^^^^^^^^^^^^^^^^^^^^^^^^^^^^^^^^^^^
  File "/home/airflow/.local/lib/python3.12/site-packages/airflow/models/taskinstance.py", line 3005, in _run_raw_task
    return _run_raw_task(
           ^^^^^^^^^^^^^^
  File "/home/airflow/.local/lib/python3.12/site-packages/airflow/models/taskinstance.py", line 273, in _run_raw_task
    TaskInstance._execute_task_with_callbacks(
  File "/home/airflow/.local/lib/python3.12/site-packages/airflow/models/taskinstance.py", line 3159, in _execute_task_with_callbacks
    result = self._execute_task(context, task_orig)
             ^^^^^^^^^^^^^^^^^^^^^^^^^^^^^^^^^^^^^^
  File "/home/airflow/.local/lib/python3.12/site-packages/airflow/models/taskinstance.py", line 3183, in _execute_task
    return _execute_task(self, context, task_orig)
           ^^^^^^^^^^^^^^^^^^^^^^^^^^^^^^^^^^^^^^^
  File "/home/airflow/.local/lib/python3.12/site-packages/airflow/models/taskinstance.py", line 767, in _execute_task
    result = _execute_callable(context=context, **execute_callable_kwargs)
             ^^^^^^^^^^^^^^^^^^^^^^^^^^^^^^^^^^^^^^^^^^^^^^^^^^^^^^^^^^^^^
  File "/home/airflow/.local/lib/python3.12/site-packages/airflow/models/taskinstance.py", line 733, in _execute_callable
    return ExecutionCallableRunner(
           ^^^^^^^^^^^^^^^^^^^^^^^^
  File "/home/airflow/.local/lib/python3.12/site-packages/airflow/utils/operator_helpers.py", line 252, in run
    return self.func(*args, **kwargs)
           ^^^^^^^^^^^^^^^^^^^^^^^^^^
  File "/home/airflow/.local/lib/python3.12/site-packages/airflow/models/baseoperator.py", line 422, in wrapper
    return func(self, *args, **kwargs)
           ^^^^^^^^^^^^^^^^^^^^^^^^^^^
  File "/home/airflow/.local/lib/python3.12/site-packages/airflow/providers/common/sql/operators/sql.py", line 284, in execute
    output = hook.run(
             ^^^^^^^^^
  File "/home/airflow/.local/lib/python3.12/site-packages/airflow/providers/common/sql/hooks/sql.py", line 498, in run
    self._run_command(cur, sql_statement, parameters)
  File "/home/airflow/.local/lib/python3.12/site-packages/airflow/providers/common/sql/hooks/sql.py", line 558, in _run_command
    cur.execute(sql_statement)
psycopg2.errors.InsufficientPrivilege: permission denied for schema public
LINE 2:     CREATE TABLE IF NOT EXISTS ebooks (
                                       ^

[2025-01-26T07:48:21.704+0000] {local_task_job_runner.py:266} INFO - Task exited with return code 1
[2025-01-26T07:48:21.932+0000] {taskinstance.py:3895} INFO - 0 downstream tasks scheduled from follow-on schedule check
[2025-01-26T07:48:22.022+0000] {local_task_job_runner.py:245} INFO - ::endgroup::
[2025-01-26T08:52:32.112+0000] {local_task_job_runner.py:123} INFO - ::group::Pre task execution logs
[2025-01-26T08:52:32.271+0000] {taskinstance.py:2613} INFO - Dependencies all met for dep_context=non-requeueable deps ti=<TaskInstance: fetch_and_store_ebooks.create_table scheduled__2025-01-12T00:00:00+00:00 [queued]>
[2025-01-26T08:52:32.313+0000] {taskinstance.py:2613} INFO - Dependencies all met for dep_context=requeueable deps ti=<TaskInstance: fetch_and_store_ebooks.create_table scheduled__2025-01-12T00:00:00+00:00 [queued]>
[2025-01-26T08:52:32.317+0000] {taskinstance.py:2866} INFO - Starting attempt 1 of 2
[2025-01-26T08:52:32.438+0000] {taskinstance.py:2889} INFO - Executing <Task(PostgresOperator): create_table> on 2025-01-12 00:00:00+00:00
[2025-01-26T08:52:32.462+0000] {warnings.py:112} WARNING - /home/***/.local/lib/python3.12/site-packages/***/task/task_runner/standard_task_runner.py:70: DeprecationWarning: This process (pid=3276) is multi-threaded, use of fork() may lead to deadlocks in the child.
  pid = os.fork()

[2025-01-26T08:52:32.468+0000] {standard_task_runner.py:72} INFO - Started process 3317 to run task
[2025-01-26T08:52:32.475+0000] {standard_task_runner.py:104} INFO - Running: ['***', 'tasks', 'run', 'fetch_and_store_ebooks', 'create_table', 'scheduled__2025-01-12T00:00:00+00:00', '--job-id', '897', '--raw', '--subdir', 'DAGS_FOLDER/app.py', '--cfg-path', '/tmp/tmpdn3v59hu']
[2025-01-26T08:52:32.484+0000] {standard_task_runner.py:105} INFO - Job 897: Subtask create_table
[2025-01-26T08:52:32.961+0000] {task_command.py:467} INFO - Running <TaskInstance: fetch_and_store_ebooks.create_table scheduled__2025-01-12T00:00:00+00:00 [running]> on host 34edd304782d
[2025-01-26T08:52:33.849+0000] {taskinstance.py:3132} INFO - Exporting env vars: AIRFLOW_CTX_DAG_OWNER='***' AIRFLOW_CTX_DAG_ID='fetch_and_store_ebooks' AIRFLOW_CTX_TASK_ID='create_table' AIRFLOW_CTX_EXECUTION_DATE='2025-01-12T00:00:00+00:00' AIRFLOW_CTX_TRY_NUMBER='1' AIRFLOW_CTX_DAG_RUN_ID='scheduled__2025-01-12T00:00:00+00:00'
[2025-01-26T08:52:33.883+0000] {logging_mixin.py:190} INFO - Task instance is in running state
[2025-01-26T08:52:33.932+0000] {logging_mixin.py:190} INFO -  Previous state of the Task instance: queued
[2025-01-26T08:52:33.943+0000] {logging_mixin.py:190} INFO - Current task name:create_table state:running start_date:2025-01-26 08:52:32.273607+00:00
[2025-01-26T08:52:33.959+0000] {logging_mixin.py:190} INFO - Dag name:fetch_and_store_ebooks and current dag run status:running
[2025-01-26T08:52:33.990+0000] {taskinstance.py:731} INFO - ::endgroup::
[2025-01-26T08:52:34.006+0000] {sql.py:278} INFO - Executing: 
    CREATE TABLE IF NOT EXISTS ebooks (
        id SERIAL PRIMARY KEY,
        judul TEXT NOT NULL,
        penulis TEXT,
        link TEXT
    );
    
[2025-01-26T08:52:34.214+0000] {base.py:84} INFO - Retrieving connection 'ebooks_connection'
[2025-01-26T08:52:34.303+0000] {base.py:84} INFO - Retrieving connection 'ebooks_connection'
[2025-01-26T08:52:34.607+0000] {sql.py:553} INFO - Running statement: 
    CREATE TABLE IF NOT EXISTS ebooks (
        id SERIAL PRIMARY KEY,
        judul TEXT NOT NULL,
        penulis TEXT,
        link TEXT
    );
    , parameters: None
[2025-01-26T08:52:34.621+0000] {taskinstance.py:3311} ERROR - Task failed with exception
Traceback (most recent call last):
  File "/home/airflow/.local/lib/python3.12/site-packages/airflow/models/taskinstance.py", line 767, in _execute_task
    result = _execute_callable(context=context, **execute_callable_kwargs)
             ^^^^^^^^^^^^^^^^^^^^^^^^^^^^^^^^^^^^^^^^^^^^^^^^^^^^^^^^^^^^^
  File "/home/airflow/.local/lib/python3.12/site-packages/airflow/models/taskinstance.py", line 733, in _execute_callable
    return ExecutionCallableRunner(
           ^^^^^^^^^^^^^^^^^^^^^^^^
  File "/home/airflow/.local/lib/python3.12/site-packages/airflow/utils/operator_helpers.py", line 252, in run
    return self.func(*args, **kwargs)
           ^^^^^^^^^^^^^^^^^^^^^^^^^^
  File "/home/airflow/.local/lib/python3.12/site-packages/airflow/models/baseoperator.py", line 422, in wrapper
    return func(self, *args, **kwargs)
           ^^^^^^^^^^^^^^^^^^^^^^^^^^^
  File "/home/airflow/.local/lib/python3.12/site-packages/airflow/providers/common/sql/operators/sql.py", line 284, in execute
    output = hook.run(
             ^^^^^^^^^
  File "/home/airflow/.local/lib/python3.12/site-packages/airflow/providers/common/sql/hooks/sql.py", line 498, in run
    self._run_command(cur, sql_statement, parameters)
  File "/home/airflow/.local/lib/python3.12/site-packages/airflow/providers/common/sql/hooks/sql.py", line 558, in _run_command
    cur.execute(sql_statement)
psycopg2.errors.InsufficientPrivilege: permission denied for schema public
LINE 2:     CREATE TABLE IF NOT EXISTS ebooks (
                                       ^

[2025-01-26T08:52:34.696+0000] {logging_mixin.py:190} INFO - Task instance in failure state
[2025-01-26T08:52:34.699+0000] {logging_mixin.py:190} INFO - Task start:2025-01-26 08:52:32.273607+00:00 end:2025-01-26 08:52:34.693941+00:00 duration:2.420334
[2025-01-26T08:52:34.702+0000] {logging_mixin.py:190} INFO - Task:<Task(PostgresOperator): create_table> dag:<DAG: fetch_and_store_ebooks> dagrun:<DagRun fetch_and_store_ebooks @ 2025-01-12 00:00:00+00:00: scheduled__2025-01-12T00:00:00+00:00, state:running, queued_at: 2025-01-26 08:50:59.026295+00:00. externally triggered: False>
[2025-01-26T08:52:34.704+0000] {logging_mixin.py:190} INFO - Failure caused by permission denied for schema public
LINE 2:     CREATE TABLE IF NOT EXISTS ebooks (
                                       ^
[2025-01-26T08:52:34.711+0000] {taskinstance.py:1225} INFO - Marking task as UP_FOR_RETRY. dag_id=fetch_and_store_ebooks, task_id=create_table, run_id=scheduled__2025-01-12T00:00:00+00:00, execution_date=20250112T000000, start_date=20250126T085232, end_date=20250126T085234
[2025-01-26T08:52:34.939+0000] {taskinstance.py:340} INFO - ::group::Post task execution logs
[2025-01-26T08:52:34.949+0000] {standard_task_runner.py:124} ERROR - Failed to execute job 897 for task create_table (permission denied for schema public
LINE 2:     CREATE TABLE IF NOT EXISTS ebooks (
                                       ^
; 3317)
Traceback (most recent call last):
  File "/home/airflow/.local/lib/python3.12/site-packages/airflow/task/task_runner/standard_task_runner.py", line 117, in _start_by_fork
    ret = args.func(args, dag=self.dag)
          ^^^^^^^^^^^^^^^^^^^^^^^^^^^^^
  File "/home/airflow/.local/lib/python3.12/site-packages/airflow/cli/cli_config.py", line 49, in command
    return func(*args, **kwargs)
           ^^^^^^^^^^^^^^^^^^^^^
  File "/home/airflow/.local/lib/python3.12/site-packages/airflow/utils/cli.py", line 116, in wrapper
    return f(*args, **kwargs)
           ^^^^^^^^^^^^^^^^^^
  File "/home/airflow/.local/lib/python3.12/site-packages/airflow/cli/commands/task_command.py", line 483, in task_run
    task_return_code = _run_task_by_selected_method(args, _dag, ti)
                       ^^^^^^^^^^^^^^^^^^^^^^^^^^^^^^^^^^^^^^^^^^^^
  File "/home/airflow/.local/lib/python3.12/site-packages/airflow/cli/commands/task_command.py", line 256, in _run_task_by_selected_method
    return _run_raw_task(args, ti)
           ^^^^^^^^^^^^^^^^^^^^^^^
  File "/home/airflow/.local/lib/python3.12/site-packages/airflow/cli/commands/task_command.py", line 341, in _run_raw_task
    return ti._run_raw_task(
           ^^^^^^^^^^^^^^^^^
  File "/home/airflow/.local/lib/python3.12/site-packages/airflow/utils/session.py", line 97, in wrapper
    return func(*args, session=session, **kwargs)
           ^^^^^^^^^^^^^^^^^^^^^^^^^^^^^^^^^^^^^^
  File "/home/airflow/.local/lib/python3.12/site-packages/airflow/models/taskinstance.py", line 3005, in _run_raw_task
    return _run_raw_task(
           ^^^^^^^^^^^^^^
  File "/home/airflow/.local/lib/python3.12/site-packages/airflow/models/taskinstance.py", line 273, in _run_raw_task
    TaskInstance._execute_task_with_callbacks(
  File "/home/airflow/.local/lib/python3.12/site-packages/airflow/models/taskinstance.py", line 3159, in _execute_task_with_callbacks
    result = self._execute_task(context, task_orig)
             ^^^^^^^^^^^^^^^^^^^^^^^^^^^^^^^^^^^^^^
  File "/home/airflow/.local/lib/python3.12/site-packages/airflow/models/taskinstance.py", line 3183, in _execute_task
    return _execute_task(self, context, task_orig)
           ^^^^^^^^^^^^^^^^^^^^^^^^^^^^^^^^^^^^^^^
  File "/home/airflow/.local/lib/python3.12/site-packages/airflow/models/taskinstance.py", line 767, in _execute_task
    result = _execute_callable(context=context, **execute_callable_kwargs)
             ^^^^^^^^^^^^^^^^^^^^^^^^^^^^^^^^^^^^^^^^^^^^^^^^^^^^^^^^^^^^^
  File "/home/airflow/.local/lib/python3.12/site-packages/airflow/models/taskinstance.py", line 733, in _execute_callable
    return ExecutionCallableRunner(
           ^^^^^^^^^^^^^^^^^^^^^^^^
  File "/home/airflow/.local/lib/python3.12/site-packages/airflow/utils/operator_helpers.py", line 252, in run
    return self.func(*args, **kwargs)
           ^^^^^^^^^^^^^^^^^^^^^^^^^^
  File "/home/airflow/.local/lib/python3.12/site-packages/airflow/models/baseoperator.py", line 422, in wrapper
    return func(self, *args, **kwargs)
           ^^^^^^^^^^^^^^^^^^^^^^^^^^^
  File "/home/airflow/.local/lib/python3.12/site-packages/airflow/providers/common/sql/operators/sql.py", line 284, in execute
    output = hook.run(
             ^^^^^^^^^
  File "/home/airflow/.local/lib/python3.12/site-packages/airflow/providers/common/sql/hooks/sql.py", line 498, in run
    self._run_command(cur, sql_statement, parameters)
  File "/home/airflow/.local/lib/python3.12/site-packages/airflow/providers/common/sql/hooks/sql.py", line 558, in _run_command
    cur.execute(sql_statement)
psycopg2.errors.InsufficientPrivilege: permission denied for schema public
LINE 2:     CREATE TABLE IF NOT EXISTS ebooks (
                                       ^

[2025-01-26T08:52:35.161+0000] {local_task_job_runner.py:266} INFO - Task exited with return code 1
[2025-01-26T08:52:35.558+0000] {taskinstance.py:3895} INFO - 0 downstream tasks scheduled from follow-on schedule check
[2025-01-26T08:52:35.569+0000] {local_task_job_runner.py:245} INFO - ::endgroup::
[2025-01-26T08:59:29.165+0000] {local_task_job_runner.py:123} INFO - ::group::Pre task execution logs
[2025-01-26T08:59:29.347+0000] {taskinstance.py:2613} INFO - Dependencies all met for dep_context=non-requeueable deps ti=<TaskInstance: fetch_and_store_ebooks.create_table scheduled__2025-01-12T00:00:00+00:00 [queued]>
[2025-01-26T08:59:29.416+0000] {taskinstance.py:2613} INFO - Dependencies all met for dep_context=requeueable deps ti=<TaskInstance: fetch_and_store_ebooks.create_table scheduled__2025-01-12T00:00:00+00:00 [queued]>
[2025-01-26T08:59:29.434+0000] {taskinstance.py:2866} INFO - Starting attempt 1 of 2
[2025-01-26T08:59:29.634+0000] {taskinstance.py:2889} INFO - Executing <Task(PostgresOperator): create_table> on 2025-01-12 00:00:00+00:00
[2025-01-26T08:59:29.676+0000] {warnings.py:112} WARNING - /home/***/.local/lib/python3.12/site-packages/***/task/task_runner/standard_task_runner.py:70: DeprecationWarning: This process (pid=3490) is multi-threaded, use of fork() may lead to deadlocks in the child.
  pid = os.fork()

[2025-01-26T08:59:29.707+0000] {standard_task_runner.py:72} INFO - Started process 3521 to run task
[2025-01-26T08:59:29.703+0000] {standard_task_runner.py:104} INFO - Running: ['***', 'tasks', 'run', 'fetch_and_store_ebooks', 'create_table', 'scheduled__2025-01-12T00:00:00+00:00', '--job-id', '927', '--raw', '--subdir', 'DAGS_FOLDER/app.py', '--cfg-path', '/tmp/tmpvrk_9l9w']
[2025-01-26T08:59:29.739+0000] {standard_task_runner.py:105} INFO - Job 927: Subtask create_table
[2025-01-26T08:59:30.251+0000] {task_command.py:467} INFO - Running <TaskInstance: fetch_and_store_ebooks.create_table scheduled__2025-01-12T00:00:00+00:00 [running]> on host 34edd304782d
[2025-01-26T08:59:31.131+0000] {taskinstance.py:3132} INFO - Exporting env vars: AIRFLOW_CTX_DAG_OWNER='***' AIRFLOW_CTX_DAG_ID='fetch_and_store_ebooks' AIRFLOW_CTX_TASK_ID='create_table' AIRFLOW_CTX_EXECUTION_DATE='2025-01-12T00:00:00+00:00' AIRFLOW_CTX_TRY_NUMBER='1' AIRFLOW_CTX_DAG_RUN_ID='scheduled__2025-01-12T00:00:00+00:00'
[2025-01-26T08:59:31.139+0000] {logging_mixin.py:190} INFO - Task instance is in running state
[2025-01-26T08:59:31.148+0000] {logging_mixin.py:190} INFO -  Previous state of the Task instance: queued
[2025-01-26T08:59:31.151+0000] {logging_mixin.py:190} INFO - Current task name:create_table state:running start_date:2025-01-26 08:59:29.351326+00:00
[2025-01-26T08:59:31.154+0000] {logging_mixin.py:190} INFO - Dag name:fetch_and_store_ebooks and current dag run status:running
[2025-01-26T08:59:31.157+0000] {taskinstance.py:731} INFO - ::endgroup::
[2025-01-26T08:59:31.166+0000] {sql.py:278} INFO - Executing: 
    CREATE TABLE IF NOT EXISTS ebooks (
        id SERIAL PRIMARY KEY,
        judul TEXT NOT NULL,
        penulis TEXT,
        link TEXT
    );
    
[2025-01-26T08:59:31.286+0000] {base.py:84} INFO - Retrieving connection 'ebooks_connection'
[2025-01-26T08:59:31.345+0000] {base.py:84} INFO - Retrieving connection 'ebooks_connection'
[2025-01-26T08:59:31.635+0000] {sql.py:553} INFO - Running statement: 
    CREATE TABLE IF NOT EXISTS ebooks (
        id SERIAL PRIMARY KEY,
        judul TEXT NOT NULL,
        penulis TEXT,
        link TEXT
    );
    , parameters: None
[2025-01-26T08:59:31.700+0000] {taskinstance.py:3311} ERROR - Task failed with exception
Traceback (most recent call last):
  File "/home/airflow/.local/lib/python3.12/site-packages/airflow/models/taskinstance.py", line 767, in _execute_task
    result = _execute_callable(context=context, **execute_callable_kwargs)
             ^^^^^^^^^^^^^^^^^^^^^^^^^^^^^^^^^^^^^^^^^^^^^^^^^^^^^^^^^^^^^
  File "/home/airflow/.local/lib/python3.12/site-packages/airflow/models/taskinstance.py", line 733, in _execute_callable
    return ExecutionCallableRunner(
           ^^^^^^^^^^^^^^^^^^^^^^^^
  File "/home/airflow/.local/lib/python3.12/site-packages/airflow/utils/operator_helpers.py", line 252, in run
    return self.func(*args, **kwargs)
           ^^^^^^^^^^^^^^^^^^^^^^^^^^
  File "/home/airflow/.local/lib/python3.12/site-packages/airflow/models/baseoperator.py", line 422, in wrapper
    return func(self, *args, **kwargs)
           ^^^^^^^^^^^^^^^^^^^^^^^^^^^
  File "/home/airflow/.local/lib/python3.12/site-packages/airflow/providers/common/sql/operators/sql.py", line 284, in execute
    output = hook.run(
             ^^^^^^^^^
  File "/home/airflow/.local/lib/python3.12/site-packages/airflow/providers/common/sql/hooks/sql.py", line 498, in run
    self._run_command(cur, sql_statement, parameters)
  File "/home/airflow/.local/lib/python3.12/site-packages/airflow/providers/common/sql/hooks/sql.py", line 558, in _run_command
    cur.execute(sql_statement)
psycopg2.errors.InsufficientPrivilege: permission denied for schema public
LINE 2:     CREATE TABLE IF NOT EXISTS ebooks (
                                       ^

[2025-01-26T08:59:31.839+0000] {logging_mixin.py:190} INFO - Task instance in failure state
[2025-01-26T08:59:31.845+0000] {logging_mixin.py:190} INFO - Task start:2025-01-26 08:59:29.351326+00:00 end:2025-01-26 08:59:31.836341+00:00 duration:2.485015
[2025-01-26T08:59:31.884+0000] {logging_mixin.py:190} INFO - Task:<Task(PostgresOperator): create_table> dag:<DAG: fetch_and_store_ebooks> dagrun:<DagRun fetch_and_store_ebooks @ 2025-01-12 00:00:00+00:00: scheduled__2025-01-12T00:00:00+00:00, state:running, queued_at: 2025-01-26 08:57:52.387579+00:00. externally triggered: False>
[2025-01-26T08:59:31.886+0000] {logging_mixin.py:190} INFO - Failure caused by permission denied for schema public
LINE 2:     CREATE TABLE IF NOT EXISTS ebooks (
                                       ^
[2025-01-26T08:59:31.894+0000] {taskinstance.py:1225} INFO - Marking task as UP_FOR_RETRY. dag_id=fetch_and_store_ebooks, task_id=create_table, run_id=scheduled__2025-01-12T00:00:00+00:00, execution_date=20250112T000000, start_date=20250126T085929, end_date=20250126T085931
[2025-01-26T08:59:32.069+0000] {taskinstance.py:340} INFO - ::group::Post task execution logs
[2025-01-26T08:59:32.088+0000] {standard_task_runner.py:124} ERROR - Failed to execute job 927 for task create_table (permission denied for schema public
LINE 2:     CREATE TABLE IF NOT EXISTS ebooks (
                                       ^
; 3521)
Traceback (most recent call last):
  File "/home/airflow/.local/lib/python3.12/site-packages/airflow/task/task_runner/standard_task_runner.py", line 117, in _start_by_fork
    ret = args.func(args, dag=self.dag)
          ^^^^^^^^^^^^^^^^^^^^^^^^^^^^^
  File "/home/airflow/.local/lib/python3.12/site-packages/airflow/cli/cli_config.py", line 49, in command
    return func(*args, **kwargs)
           ^^^^^^^^^^^^^^^^^^^^^
  File "/home/airflow/.local/lib/python3.12/site-packages/airflow/utils/cli.py", line 116, in wrapper
    return f(*args, **kwargs)
           ^^^^^^^^^^^^^^^^^^
  File "/home/airflow/.local/lib/python3.12/site-packages/airflow/cli/commands/task_command.py", line 483, in task_run
    task_return_code = _run_task_by_selected_method(args, _dag, ti)
                       ^^^^^^^^^^^^^^^^^^^^^^^^^^^^^^^^^^^^^^^^^^^^
  File "/home/airflow/.local/lib/python3.12/site-packages/airflow/cli/commands/task_command.py", line 256, in _run_task_by_selected_method
    return _run_raw_task(args, ti)
           ^^^^^^^^^^^^^^^^^^^^^^^
  File "/home/airflow/.local/lib/python3.12/site-packages/airflow/cli/commands/task_command.py", line 341, in _run_raw_task
    return ti._run_raw_task(
           ^^^^^^^^^^^^^^^^^
  File "/home/airflow/.local/lib/python3.12/site-packages/airflow/utils/session.py", line 97, in wrapper
    return func(*args, session=session, **kwargs)
           ^^^^^^^^^^^^^^^^^^^^^^^^^^^^^^^^^^^^^^
  File "/home/airflow/.local/lib/python3.12/site-packages/airflow/models/taskinstance.py", line 3005, in _run_raw_task
    return _run_raw_task(
           ^^^^^^^^^^^^^^
  File "/home/airflow/.local/lib/python3.12/site-packages/airflow/models/taskinstance.py", line 273, in _run_raw_task
    TaskInstance._execute_task_with_callbacks(
  File "/home/airflow/.local/lib/python3.12/site-packages/airflow/models/taskinstance.py", line 3159, in _execute_task_with_callbacks
    result = self._execute_task(context, task_orig)
             ^^^^^^^^^^^^^^^^^^^^^^^^^^^^^^^^^^^^^^
  File "/home/airflow/.local/lib/python3.12/site-packages/airflow/models/taskinstance.py", line 3183, in _execute_task
    return _execute_task(self, context, task_orig)
           ^^^^^^^^^^^^^^^^^^^^^^^^^^^^^^^^^^^^^^^
  File "/home/airflow/.local/lib/python3.12/site-packages/airflow/models/taskinstance.py", line 767, in _execute_task
    result = _execute_callable(context=context, **execute_callable_kwargs)
             ^^^^^^^^^^^^^^^^^^^^^^^^^^^^^^^^^^^^^^^^^^^^^^^^^^^^^^^^^^^^^
  File "/home/airflow/.local/lib/python3.12/site-packages/airflow/models/taskinstance.py", line 733, in _execute_callable
    return ExecutionCallableRunner(
           ^^^^^^^^^^^^^^^^^^^^^^^^
  File "/home/airflow/.local/lib/python3.12/site-packages/airflow/utils/operator_helpers.py", line 252, in run
    return self.func(*args, **kwargs)
           ^^^^^^^^^^^^^^^^^^^^^^^^^^
  File "/home/airflow/.local/lib/python3.12/site-packages/airflow/models/baseoperator.py", line 422, in wrapper
    return func(self, *args, **kwargs)
           ^^^^^^^^^^^^^^^^^^^^^^^^^^^
  File "/home/airflow/.local/lib/python3.12/site-packages/airflow/providers/common/sql/operators/sql.py", line 284, in execute
    output = hook.run(
             ^^^^^^^^^
  File "/home/airflow/.local/lib/python3.12/site-packages/airflow/providers/common/sql/hooks/sql.py", line 498, in run
    self._run_command(cur, sql_statement, parameters)
  File "/home/airflow/.local/lib/python3.12/site-packages/airflow/providers/common/sql/hooks/sql.py", line 558, in _run_command
    cur.execute(sql_statement)
psycopg2.errors.InsufficientPrivilege: permission denied for schema public
LINE 2:     CREATE TABLE IF NOT EXISTS ebooks (
                                       ^

[2025-01-26T08:59:32.267+0000] {local_task_job_runner.py:266} INFO - Task exited with return code 1
[2025-01-26T08:59:32.543+0000] {taskinstance.py:3895} INFO - 0 downstream tasks scheduled from follow-on schedule check
[2025-01-26T08:59:32.561+0000] {local_task_job_runner.py:245} INFO - ::endgroup::
[2025-01-26T09:06:28.639+0000] {local_task_job_runner.py:123} INFO - ::group::Pre task execution logs
[2025-01-26T09:06:28.917+0000] {taskinstance.py:2613} INFO - Dependencies all met for dep_context=non-requeueable deps ti=<TaskInstance: fetch_and_store_ebooks.create_table scheduled__2025-01-12T00:00:00+00:00 [queued]>
[2025-01-26T09:06:29.015+0000] {taskinstance.py:2613} INFO - Dependencies all met for dep_context=requeueable deps ti=<TaskInstance: fetch_and_store_ebooks.create_table scheduled__2025-01-12T00:00:00+00:00 [queued]>
[2025-01-26T09:06:29.017+0000] {taskinstance.py:2866} INFO - Starting attempt 1 of 2
[2025-01-26T09:06:29.181+0000] {taskinstance.py:2889} INFO - Executing <Task(PostgresOperator): create_table> on 2025-01-12 00:00:00+00:00
[2025-01-26T09:06:29.217+0000] {warnings.py:112} WARNING - /home/***/.local/lib/python3.12/site-packages/***/task/task_runner/standard_task_runner.py:70: DeprecationWarning: This process (pid=3688) is multi-threaded, use of fork() may lead to deadlocks in the child.
  pid = os.fork()

[2025-01-26T09:06:29.235+0000] {standard_task_runner.py:72} INFO - Started process 3729 to run task
[2025-01-26T09:06:29.250+0000] {standard_task_runner.py:104} INFO - Running: ['***', 'tasks', 'run', 'fetch_and_store_ebooks', 'create_table', 'scheduled__2025-01-12T00:00:00+00:00', '--job-id', '963', '--raw', '--subdir', 'DAGS_FOLDER/app.py', '--cfg-path', '/tmp/tmpcbdzmlq1']
[2025-01-26T09:06:29.259+0000] {standard_task_runner.py:105} INFO - Job 963: Subtask create_table
[2025-01-26T09:06:29.628+0000] {task_command.py:467} INFO - Running <TaskInstance: fetch_and_store_ebooks.create_table scheduled__2025-01-12T00:00:00+00:00 [running]> on host 34edd304782d
[2025-01-26T09:06:30.251+0000] {taskinstance.py:3132} INFO - Exporting env vars: AIRFLOW_CTX_DAG_OWNER='***' AIRFLOW_CTX_DAG_ID='fetch_and_store_ebooks' AIRFLOW_CTX_TASK_ID='create_table' AIRFLOW_CTX_EXECUTION_DATE='2025-01-12T00:00:00+00:00' AIRFLOW_CTX_TRY_NUMBER='1' AIRFLOW_CTX_DAG_RUN_ID='scheduled__2025-01-12T00:00:00+00:00'
[2025-01-26T09:06:30.260+0000] {logging_mixin.py:190} INFO - Task instance is in running state
[2025-01-26T09:06:30.262+0000] {logging_mixin.py:190} INFO -  Previous state of the Task instance: queued
[2025-01-26T09:06:30.264+0000] {logging_mixin.py:190} INFO - Current task name:create_table state:running start_date:2025-01-26 09:06:28.924821+00:00
[2025-01-26T09:06:30.265+0000] {logging_mixin.py:190} INFO - Dag name:fetch_and_store_ebooks and current dag run status:running
[2025-01-26T09:06:30.271+0000] {taskinstance.py:731} INFO - ::endgroup::
[2025-01-26T09:06:30.273+0000] {sql.py:278} INFO - Executing: 
    CREATE TABLE IF NOT EXISTS ebooks (
        id SERIAL PRIMARY KEY,
        judul TEXT NOT NULL,
        penulis TEXT,
        link TEXT
    );
    
[2025-01-26T09:06:30.332+0000] {base.py:84} INFO - Retrieving connection 'ebooks_connection'
[2025-01-26T09:06:30.378+0000] {base.py:84} INFO - Retrieving connection 'ebooks_connection'
[2025-01-26T09:06:30.564+0000] {sql.py:553} INFO - Running statement: 
    CREATE TABLE IF NOT EXISTS ebooks (
        id SERIAL PRIMARY KEY,
        judul TEXT NOT NULL,
        penulis TEXT,
        link TEXT
    );
    , parameters: None
[2025-01-26T09:06:30.577+0000] {taskinstance.py:3311} ERROR - Task failed with exception
Traceback (most recent call last):
  File "/home/airflow/.local/lib/python3.12/site-packages/airflow/models/taskinstance.py", line 767, in _execute_task
    result = _execute_callable(context=context, **execute_callable_kwargs)
             ^^^^^^^^^^^^^^^^^^^^^^^^^^^^^^^^^^^^^^^^^^^^^^^^^^^^^^^^^^^^^
  File "/home/airflow/.local/lib/python3.12/site-packages/airflow/models/taskinstance.py", line 733, in _execute_callable
    return ExecutionCallableRunner(
           ^^^^^^^^^^^^^^^^^^^^^^^^
  File "/home/airflow/.local/lib/python3.12/site-packages/airflow/utils/operator_helpers.py", line 252, in run
    return self.func(*args, **kwargs)
           ^^^^^^^^^^^^^^^^^^^^^^^^^^
  File "/home/airflow/.local/lib/python3.12/site-packages/airflow/models/baseoperator.py", line 422, in wrapper
    return func(self, *args, **kwargs)
           ^^^^^^^^^^^^^^^^^^^^^^^^^^^
  File "/home/airflow/.local/lib/python3.12/site-packages/airflow/providers/common/sql/operators/sql.py", line 284, in execute
    output = hook.run(
             ^^^^^^^^^
  File "/home/airflow/.local/lib/python3.12/site-packages/airflow/providers/common/sql/hooks/sql.py", line 498, in run
    self._run_command(cur, sql_statement, parameters)
  File "/home/airflow/.local/lib/python3.12/site-packages/airflow/providers/common/sql/hooks/sql.py", line 558, in _run_command
    cur.execute(sql_statement)
psycopg2.errors.InsufficientPrivilege: permission denied for schema public
LINE 2:     CREATE TABLE IF NOT EXISTS ebooks (
                                       ^

[2025-01-26T09:06:30.660+0000] {logging_mixin.py:190} INFO - Task instance in failure state
[2025-01-26T09:06:30.663+0000] {logging_mixin.py:190} INFO - Task start:2025-01-26 09:06:28.924821+00:00 end:2025-01-26 09:06:30.657650+00:00 duration:1.732829
[2025-01-26T09:06:30.665+0000] {logging_mixin.py:190} INFO - Task:<Task(PostgresOperator): create_table> dag:<DAG: fetch_and_store_ebooks> dagrun:<DagRun fetch_and_store_ebooks @ 2025-01-12 00:00:00+00:00: scheduled__2025-01-12T00:00:00+00:00, state:running, queued_at: 2025-01-26 09:05:00.276058+00:00. externally triggered: False>
[2025-01-26T09:06:30.667+0000] {logging_mixin.py:190} INFO - Failure caused by permission denied for schema public
LINE 2:     CREATE TABLE IF NOT EXISTS ebooks (
                                       ^
[2025-01-26T09:06:30.669+0000] {taskinstance.py:1225} INFO - Marking task as UP_FOR_RETRY. dag_id=fetch_and_store_ebooks, task_id=create_table, run_id=scheduled__2025-01-12T00:00:00+00:00, execution_date=20250112T000000, start_date=20250126T090628, end_date=20250126T090630
[2025-01-26T09:06:30.751+0000] {taskinstance.py:340} INFO - ::group::Post task execution logs
[2025-01-26T09:06:30.756+0000] {standard_task_runner.py:124} ERROR - Failed to execute job 963 for task create_table (permission denied for schema public
LINE 2:     CREATE TABLE IF NOT EXISTS ebooks (
                                       ^
; 3729)
Traceback (most recent call last):
  File "/home/airflow/.local/lib/python3.12/site-packages/airflow/task/task_runner/standard_task_runner.py", line 117, in _start_by_fork
    ret = args.func(args, dag=self.dag)
          ^^^^^^^^^^^^^^^^^^^^^^^^^^^^^
  File "/home/airflow/.local/lib/python3.12/site-packages/airflow/cli/cli_config.py", line 49, in command
    return func(*args, **kwargs)
           ^^^^^^^^^^^^^^^^^^^^^
  File "/home/airflow/.local/lib/python3.12/site-packages/airflow/utils/cli.py", line 116, in wrapper
    return f(*args, **kwargs)
           ^^^^^^^^^^^^^^^^^^
  File "/home/airflow/.local/lib/python3.12/site-packages/airflow/cli/commands/task_command.py", line 483, in task_run
    task_return_code = _run_task_by_selected_method(args, _dag, ti)
                       ^^^^^^^^^^^^^^^^^^^^^^^^^^^^^^^^^^^^^^^^^^^^
  File "/home/airflow/.local/lib/python3.12/site-packages/airflow/cli/commands/task_command.py", line 256, in _run_task_by_selected_method
    return _run_raw_task(args, ti)
           ^^^^^^^^^^^^^^^^^^^^^^^
  File "/home/airflow/.local/lib/python3.12/site-packages/airflow/cli/commands/task_command.py", line 341, in _run_raw_task
    return ti._run_raw_task(
           ^^^^^^^^^^^^^^^^^
  File "/home/airflow/.local/lib/python3.12/site-packages/airflow/utils/session.py", line 97, in wrapper
    return func(*args, session=session, **kwargs)
           ^^^^^^^^^^^^^^^^^^^^^^^^^^^^^^^^^^^^^^
  File "/home/airflow/.local/lib/python3.12/site-packages/airflow/models/taskinstance.py", line 3005, in _run_raw_task
    return _run_raw_task(
           ^^^^^^^^^^^^^^
  File "/home/airflow/.local/lib/python3.12/site-packages/airflow/models/taskinstance.py", line 273, in _run_raw_task
    TaskInstance._execute_task_with_callbacks(
  File "/home/airflow/.local/lib/python3.12/site-packages/airflow/models/taskinstance.py", line 3159, in _execute_task_with_callbacks
    result = self._execute_task(context, task_orig)
             ^^^^^^^^^^^^^^^^^^^^^^^^^^^^^^^^^^^^^^
  File "/home/airflow/.local/lib/python3.12/site-packages/airflow/models/taskinstance.py", line 3183, in _execute_task
    return _execute_task(self, context, task_orig)
           ^^^^^^^^^^^^^^^^^^^^^^^^^^^^^^^^^^^^^^^
  File "/home/airflow/.local/lib/python3.12/site-packages/airflow/models/taskinstance.py", line 767, in _execute_task
    result = _execute_callable(context=context, **execute_callable_kwargs)
             ^^^^^^^^^^^^^^^^^^^^^^^^^^^^^^^^^^^^^^^^^^^^^^^^^^^^^^^^^^^^^
  File "/home/airflow/.local/lib/python3.12/site-packages/airflow/models/taskinstance.py", line 733, in _execute_callable
    return ExecutionCallableRunner(
           ^^^^^^^^^^^^^^^^^^^^^^^^
  File "/home/airflow/.local/lib/python3.12/site-packages/airflow/utils/operator_helpers.py", line 252, in run
    return self.func(*args, **kwargs)
           ^^^^^^^^^^^^^^^^^^^^^^^^^^
  File "/home/airflow/.local/lib/python3.12/site-packages/airflow/models/baseoperator.py", line 422, in wrapper
    return func(self, *args, **kwargs)
           ^^^^^^^^^^^^^^^^^^^^^^^^^^^
  File "/home/airflow/.local/lib/python3.12/site-packages/airflow/providers/common/sql/operators/sql.py", line 284, in execute
    output = hook.run(
             ^^^^^^^^^
  File "/home/airflow/.local/lib/python3.12/site-packages/airflow/providers/common/sql/hooks/sql.py", line 498, in run
    self._run_command(cur, sql_statement, parameters)
  File "/home/airflow/.local/lib/python3.12/site-packages/airflow/providers/common/sql/hooks/sql.py", line 558, in _run_command
    cur.execute(sql_statement)
psycopg2.errors.InsufficientPrivilege: permission denied for schema public
LINE 2:     CREATE TABLE IF NOT EXISTS ebooks (
                                       ^

[2025-01-26T09:06:30.837+0000] {local_task_job_runner.py:266} INFO - Task exited with return code 1
[2025-01-26T09:06:30.881+0000] {local_task_job_runner.py:245} INFO - ::endgroup::
[2025-01-26T09:28:14.878+0000] {local_task_job_runner.py:123} INFO - ::group::Pre task execution logs
[2025-01-26T09:28:15.384+0000] {taskinstance.py:2613} INFO - Dependencies all met for dep_context=non-requeueable deps ti=<TaskInstance: fetch_and_store_ebooks.create_table scheduled__2025-01-12T00:00:00+00:00 [queued]>
[2025-01-26T09:28:15.490+0000] {taskinstance.py:2613} INFO - Dependencies all met for dep_context=requeueable deps ti=<TaskInstance: fetch_and_store_ebooks.create_table scheduled__2025-01-12T00:00:00+00:00 [queued]>
[2025-01-26T09:28:15.493+0000] {taskinstance.py:2866} INFO - Starting attempt 1 of 2
[2025-01-26T09:28:15.868+0000] {taskinstance.py:2889} INFO - Executing <Task(PostgresOperator): create_table> on 2025-01-12 00:00:00+00:00
[2025-01-26T09:28:15.943+0000] {warnings.py:112} WARNING - /home/***/.local/lib/python3.12/site-packages/***/task/task_runner/standard_task_runner.py:70: DeprecationWarning: This process (pid=4410) is multi-threaded, use of fork() may lead to deadlocks in the child.
  pid = os.fork()

[2025-01-26T09:28:15.953+0000] {standard_task_runner.py:72} INFO - Started process 4469 to run task
[2025-01-26T09:28:16.060+0000] {standard_task_runner.py:104} INFO - Running: ['***', 'tasks', 'run', 'fetch_and_store_ebooks', 'create_table', 'scheduled__2025-01-12T00:00:00+00:00', '--job-id', '1081', '--raw', '--subdir', 'DAGS_FOLDER/app.py', '--cfg-path', '/tmp/tmpfljub7lt']
[2025-01-26T09:28:16.084+0000] {standard_task_runner.py:105} INFO - Job 1081: Subtask create_table
[2025-01-26T09:28:16.622+0000] {task_command.py:467} INFO - Running <TaskInstance: fetch_and_store_ebooks.create_table scheduled__2025-01-12T00:00:00+00:00 [running]> on host 34edd304782d
[2025-01-26T09:28:18.475+0000] {taskinstance.py:3132} INFO - Exporting env vars: AIRFLOW_CTX_DAG_OWNER='***' AIRFLOW_CTX_DAG_ID='fetch_and_store_ebooks' AIRFLOW_CTX_TASK_ID='create_table' AIRFLOW_CTX_EXECUTION_DATE='2025-01-12T00:00:00+00:00' AIRFLOW_CTX_TRY_NUMBER='1' AIRFLOW_CTX_DAG_RUN_ID='scheduled__2025-01-12T00:00:00+00:00'
[2025-01-26T09:28:18.482+0000] {logging_mixin.py:190} INFO - Task instance is in running state
[2025-01-26T09:28:18.484+0000] {logging_mixin.py:190} INFO -  Previous state of the Task instance: queued
[2025-01-26T09:28:18.487+0000] {logging_mixin.py:190} INFO - Current task name:create_table state:running start_date:2025-01-26 09:28:15.397294+00:00
[2025-01-26T09:28:18.499+0000] {logging_mixin.py:190} INFO - Dag name:fetch_and_store_ebooks and current dag run status:running
[2025-01-26T09:28:18.502+0000] {taskinstance.py:731} INFO - ::endgroup::
[2025-01-26T09:28:18.505+0000] {sql.py:278} INFO - Executing: 
    CREATE TABLE IF NOT EXISTS public.ebooks (
        id SERIAL PRIMARY KEY,
        judul TEXT NOT NULL,
        penulis TEXT,
        link TEXT
    );
    
[2025-01-26T09:28:18.609+0000] {base.py:84} INFO - Retrieving connection 'ebooks_connection'
[2025-01-26T09:28:18.685+0000] {base.py:84} INFO - Retrieving connection 'ebooks_connection'
[2025-01-26T09:28:19.007+0000] {sql.py:553} INFO - Running statement: 
    CREATE TABLE IF NOT EXISTS public.ebooks (
        id SERIAL PRIMARY KEY,
        judul TEXT NOT NULL,
        penulis TEXT,
        link TEXT
    );
    , parameters: None
[2025-01-26T09:28:19.265+0000] {taskinstance.py:340} INFO - ::group::Post task execution logs
[2025-01-26T09:28:19.290+0000] {taskinstance.py:352} INFO - Marking task as SUCCESS. dag_id=fetch_and_store_ebooks, task_id=create_table, run_id=scheduled__2025-01-12T00:00:00+00:00, execution_date=20250112T000000, start_date=20250126T092815, end_date=20250126T092819
[2025-01-26T09:28:19.439+0000] {logging_mixin.py:190} INFO - Task instance in success state
[2025-01-26T09:28:19.461+0000] {logging_mixin.py:190} INFO -  Previous state of the Task instance: running
[2025-01-26T09:28:19.470+0000] {logging_mixin.py:190} INFO - Dag name:fetch_and_store_ebooks queued_at:2025-01-26 09:26:23.678226+00:00
[2025-01-26T09:28:19.476+0000] {logging_mixin.py:190} INFO - Task hostname:34edd304782d operator:PostgresOperator
[2025-01-26T09:28:19.566+0000] {local_task_job_runner.py:266} INFO - Task exited with return code 0
[2025-01-26T09:28:19.945+0000] {taskinstance.py:3895} INFO - 1 downstream tasks scheduled from follow-on schedule check
[2025-01-26T09:28:19.997+0000] {local_task_job_runner.py:245} INFO - ::endgroup::
