[2025-01-25T17:11:03.649+0000] {local_task_job_runner.py:123} INFO - ::group::Pre task execution logs
[2025-01-25T17:11:03.754+0000] {taskinstance.py:2613} INFO - Dependencies all met for dep_context=non-requeueable deps ti=<TaskInstance: fetch_and_store_ebooks.create_table scheduled__2025-01-19T00:00:00+00:00 [queued]>
[2025-01-25T17:11:03.860+0000] {taskinstance.py:2613} INFO - Dependencies all met for dep_context=requeueable deps ti=<TaskInstance: fetch_and_store_ebooks.create_table scheduled__2025-01-19T00:00:00+00:00 [queued]>
[2025-01-25T17:11:03.864+0000] {taskinstance.py:2866} INFO - Starting attempt 1 of 2
[2025-01-25T17:11:04.076+0000] {taskinstance.py:2889} INFO - Executing <Task(PostgresOperator): create_table> on 2025-01-19 00:00:00+00:00
[2025-01-25T17:11:04.119+0000] {warnings.py:112} WARNING - /home/***/.local/lib/python3.12/site-packages/***/task/task_runner/standard_task_runner.py:70: DeprecationWarning: This process (pid=4004) is multi-threaded, use of fork() may lead to deadlocks in the child.
  pid = os.fork()

[2025-01-25T17:11:04.135+0000] {standard_task_runner.py:72} INFO - Started process 4018 to run task
[2025-01-25T17:11:04.148+0000] {standard_task_runner.py:104} INFO - Running: ['***', 'tasks', 'run', 'fetch_and_store_ebooks', 'create_table', 'scheduled__2025-01-19T00:00:00+00:00', '--job-id', '497', '--raw', '--subdir', 'DAGS_FOLDER/app.py', '--cfg-path', '/tmp/tmpjy64do__']
[2025-01-25T17:11:04.169+0000] {standard_task_runner.py:105} INFO - Job 497: Subtask create_table
[2025-01-25T17:11:04.669+0000] {task_command.py:467} INFO - Running <TaskInstance: fetch_and_store_ebooks.create_table scheduled__2025-01-19T00:00:00+00:00 [running]> on host 50ab235b552a
[2025-01-25T17:11:05.523+0000] {taskinstance.py:3132} INFO - Exporting env vars: AIRFLOW_CTX_DAG_OWNER='***' AIRFLOW_CTX_DAG_ID='fetch_and_store_ebooks' AIRFLOW_CTX_TASK_ID='create_table' AIRFLOW_CTX_EXECUTION_DATE='2025-01-19T00:00:00+00:00' AIRFLOW_CTX_TRY_NUMBER='1' AIRFLOW_CTX_DAG_RUN_ID='scheduled__2025-01-19T00:00:00+00:00'
[2025-01-25T17:11:05.550+0000] {logging_mixin.py:190} INFO - Task instance is in running state
[2025-01-25T17:11:05.570+0000] {logging_mixin.py:190} INFO -  Previous state of the Task instance: queued
[2025-01-25T17:11:05.577+0000] {logging_mixin.py:190} INFO - Current task name:create_table state:running start_date:2025-01-25 17:11:03.761200+00:00
[2025-01-25T17:11:05.580+0000] {logging_mixin.py:190} INFO - Dag name:fetch_and_store_ebooks and current dag run status:running
[2025-01-25T17:11:05.584+0000] {taskinstance.py:731} INFO - ::endgroup::
[2025-01-25T17:11:05.586+0000] {sql.py:278} INFO - Executing: 
    CREATE TABLE IF NOT EXISTS ebooks (
        id SERIAL PRIMARY KEY,
        judul TEXT NOT NULL,
        penulis TEXT,
        link TEXT
    );
    
[2025-01-25T17:11:05.648+0000] {base.py:84} INFO - Retrieving connection 'ebooks_connection'
[2025-01-25T17:11:05.719+0000] {base.py:84} INFO - Retrieving connection 'ebooks_connection'
[2025-01-25T17:11:05.738+0000] {taskinstance.py:3311} ERROR - Task failed with exception
Traceback (most recent call last):
  File "/home/airflow/.local/lib/python3.12/site-packages/airflow/models/taskinstance.py", line 767, in _execute_task
    result = _execute_callable(context=context, **execute_callable_kwargs)
             ^^^^^^^^^^^^^^^^^^^^^^^^^^^^^^^^^^^^^^^^^^^^^^^^^^^^^^^^^^^^^
  File "/home/airflow/.local/lib/python3.12/site-packages/airflow/models/taskinstance.py", line 733, in _execute_callable
    return ExecutionCallableRunner(
           ^^^^^^^^^^^^^^^^^^^^^^^^
  File "/home/airflow/.local/lib/python3.12/site-packages/airflow/utils/operator_helpers.py", line 252, in run
    return self.func(*args, **kwargs)
           ^^^^^^^^^^^^^^^^^^^^^^^^^^
  File "/home/airflow/.local/lib/python3.12/site-packages/airflow/models/baseoperator.py", line 422, in wrapper
    return func(self, *args, **kwargs)
           ^^^^^^^^^^^^^^^^^^^^^^^^^^^
  File "/home/airflow/.local/lib/python3.12/site-packages/airflow/providers/common/sql/operators/sql.py", line 284, in execute
    output = hook.run(
             ^^^^^^^^^
  File "/home/airflow/.local/lib/python3.12/site-packages/airflow/providers/common/sql/hooks/sql.py", line 494, in run
    with self._create_autocommit_connection(autocommit) as conn:
         ^^^^^^^^^^^^^^^^^^^^^^^^^^^^^^^^^^^^^^^^^^^^^^
  File "/usr/local/lib/python3.12/contextlib.py", line 137, in __enter__
    return next(self.gen)
           ^^^^^^^^^^^^^^
  File "/home/airflow/.local/lib/python3.12/site-packages/airflow/providers/common/sql/hooks/sql.py", line 618, in _create_autocommit_connection
    with closing(self.get_conn()) as conn:
                 ^^^^^^^^^^^^^^^
  File "/home/airflow/.local/lib/python3.12/site-packages/airflow/providers/postgres/hooks/postgres.py", line 189, in get_conn
    self.conn = psycopg2.connect(**conn_args)
                ^^^^^^^^^^^^^^^^^^^^^^^^^^^^^
  File "/home/airflow/.local/lib/python3.12/site-packages/psycopg2/__init__.py", line 122, in connect
    conn = _connect(dsn, connection_factory=connection_factory, **kwasync)
           ^^^^^^^^^^^^^^^^^^^^^^^^^^^^^^^^^^^^^^^^^^^^^^^^^^^^^^^^^^^^^^^
psycopg2.OperationalError: connection to server at "localhost" (::1), port 5432 failed: Connection refused
	Is the server running on that host and accepting TCP/IP connections?
connection to server at "localhost" (127.0.0.1), port 5432 failed: Connection refused
	Is the server running on that host and accepting TCP/IP connections?

[2025-01-25T17:11:05.879+0000] {logging_mixin.py:190} INFO - Task instance in failure state
[2025-01-25T17:11:05.909+0000] {logging_mixin.py:190} INFO - Task start:2025-01-25 17:11:03.761200+00:00 end:2025-01-25 17:11:05.876780+00:00 duration:2.11558
[2025-01-25T17:11:05.916+0000] {logging_mixin.py:190} INFO - Task:<Task(PostgresOperator): create_table> dag:<DAG: fetch_and_store_ebooks> dagrun:<DagRun fetch_and_store_ebooks @ 2025-01-19 00:00:00+00:00: scheduled__2025-01-19T00:00:00+00:00, state:running, queued_at: 2025-01-25 17:09:40.489199+00:00. externally triggered: False>
[2025-01-25T17:11:05.918+0000] {logging_mixin.py:190} INFO - Failure caused by connection to server at "localhost" (::1), port 5432 failed: Connection refused
	Is the server running on that host and accepting TCP/IP connections?
connection to server at "localhost" (127.0.0.1), port 5432 failed: Connection refused
	Is the server running on that host and accepting TCP/IP connections?
[2025-01-25T17:11:05.931+0000] {taskinstance.py:1225} INFO - Marking task as UP_FOR_RETRY. dag_id=fetch_and_store_ebooks, task_id=create_table, run_id=scheduled__2025-01-19T00:00:00+00:00, execution_date=20250119T000000, start_date=20250125T171103, end_date=20250125T171105
[2025-01-25T17:11:06.420+0000] {taskinstance.py:340} INFO - ::group::Post task execution logs
[2025-01-25T17:11:06.461+0000] {standard_task_runner.py:124} ERROR - Failed to execute job 497 for task create_table (connection to server at "localhost" (::1), port 5432 failed: Connection refused
	Is the server running on that host and accepting TCP/IP connections?
connection to server at "localhost" (127.0.0.1), port 5432 failed: Connection refused
	Is the server running on that host and accepting TCP/IP connections?
; 4018)
Traceback (most recent call last):
  File "/home/airflow/.local/lib/python3.12/site-packages/airflow/task/task_runner/standard_task_runner.py", line 117, in _start_by_fork
    ret = args.func(args, dag=self.dag)
          ^^^^^^^^^^^^^^^^^^^^^^^^^^^^^
  File "/home/airflow/.local/lib/python3.12/site-packages/airflow/cli/cli_config.py", line 49, in command
    return func(*args, **kwargs)
           ^^^^^^^^^^^^^^^^^^^^^
  File "/home/airflow/.local/lib/python3.12/site-packages/airflow/utils/cli.py", line 116, in wrapper
    return f(*args, **kwargs)
           ^^^^^^^^^^^^^^^^^^
  File "/home/airflow/.local/lib/python3.12/site-packages/airflow/cli/commands/task_command.py", line 483, in task_run
    task_return_code = _run_task_by_selected_method(args, _dag, ti)
                       ^^^^^^^^^^^^^^^^^^^^^^^^^^^^^^^^^^^^^^^^^^^^
  File "/home/airflow/.local/lib/python3.12/site-packages/airflow/cli/commands/task_command.py", line 256, in _run_task_by_selected_method
    return _run_raw_task(args, ti)
           ^^^^^^^^^^^^^^^^^^^^^^^
  File "/home/airflow/.local/lib/python3.12/site-packages/airflow/cli/commands/task_command.py", line 341, in _run_raw_task
    return ti._run_raw_task(
           ^^^^^^^^^^^^^^^^^
  File "/home/airflow/.local/lib/python3.12/site-packages/airflow/utils/session.py", line 97, in wrapper
    return func(*args, session=session, **kwargs)
           ^^^^^^^^^^^^^^^^^^^^^^^^^^^^^^^^^^^^^^
  File "/home/airflow/.local/lib/python3.12/site-packages/airflow/models/taskinstance.py", line 3005, in _run_raw_task
    return _run_raw_task(
           ^^^^^^^^^^^^^^
  File "/home/airflow/.local/lib/python3.12/site-packages/airflow/models/taskinstance.py", line 273, in _run_raw_task
    TaskInstance._execute_task_with_callbacks(
  File "/home/airflow/.local/lib/python3.12/site-packages/airflow/models/taskinstance.py", line 3159, in _execute_task_with_callbacks
    result = self._execute_task(context, task_orig)
             ^^^^^^^^^^^^^^^^^^^^^^^^^^^^^^^^^^^^^^
  File "/home/airflow/.local/lib/python3.12/site-packages/airflow/models/taskinstance.py", line 3183, in _execute_task
    return _execute_task(self, context, task_orig)
           ^^^^^^^^^^^^^^^^^^^^^^^^^^^^^^^^^^^^^^^
  File "/home/airflow/.local/lib/python3.12/site-packages/airflow/models/taskinstance.py", line 767, in _execute_task
    result = _execute_callable(context=context, **execute_callable_kwargs)
             ^^^^^^^^^^^^^^^^^^^^^^^^^^^^^^^^^^^^^^^^^^^^^^^^^^^^^^^^^^^^^
  File "/home/airflow/.local/lib/python3.12/site-packages/airflow/models/taskinstance.py", line 733, in _execute_callable
    return ExecutionCallableRunner(
           ^^^^^^^^^^^^^^^^^^^^^^^^
  File "/home/airflow/.local/lib/python3.12/site-packages/airflow/utils/operator_helpers.py", line 252, in run
    return self.func(*args, **kwargs)
           ^^^^^^^^^^^^^^^^^^^^^^^^^^
  File "/home/airflow/.local/lib/python3.12/site-packages/airflow/models/baseoperator.py", line 422, in wrapper
    return func(self, *args, **kwargs)
           ^^^^^^^^^^^^^^^^^^^^^^^^^^^
  File "/home/airflow/.local/lib/python3.12/site-packages/airflow/providers/common/sql/operators/sql.py", line 284, in execute
    output = hook.run(
             ^^^^^^^^^
  File "/home/airflow/.local/lib/python3.12/site-packages/airflow/providers/common/sql/hooks/sql.py", line 494, in run
    with self._create_autocommit_connection(autocommit) as conn:
         ^^^^^^^^^^^^^^^^^^^^^^^^^^^^^^^^^^^^^^^^^^^^^^
  File "/usr/local/lib/python3.12/contextlib.py", line 137, in __enter__
    return next(self.gen)
           ^^^^^^^^^^^^^^
  File "/home/airflow/.local/lib/python3.12/site-packages/airflow/providers/common/sql/hooks/sql.py", line 618, in _create_autocommit_connection
    with closing(self.get_conn()) as conn:
                 ^^^^^^^^^^^^^^^
  File "/home/airflow/.local/lib/python3.12/site-packages/airflow/providers/postgres/hooks/postgres.py", line 189, in get_conn
    self.conn = psycopg2.connect(**conn_args)
                ^^^^^^^^^^^^^^^^^^^^^^^^^^^^^
  File "/home/airflow/.local/lib/python3.12/site-packages/psycopg2/__init__.py", line 122, in connect
    conn = _connect(dsn, connection_factory=connection_factory, **kwasync)
           ^^^^^^^^^^^^^^^^^^^^^^^^^^^^^^^^^^^^^^^^^^^^^^^^^^^^^^^^^^^^^^^
psycopg2.OperationalError: connection to server at "localhost" (::1), port 5432 failed: Connection refused
	Is the server running on that host and accepting TCP/IP connections?
connection to server at "localhost" (127.0.0.1), port 5432 failed: Connection refused
	Is the server running on that host and accepting TCP/IP connections?

[2025-01-25T17:11:06.690+0000] {local_task_job_runner.py:266} INFO - Task exited with return code 1
[2025-01-25T17:11:07.117+0000] {taskinstance.py:3895} INFO - 0 downstream tasks scheduled from follow-on schedule check
[2025-01-25T17:11:07.132+0000] {local_task_job_runner.py:245} INFO - ::endgroup::
[2025-01-26T06:41:08.971+0000] {local_task_job_runner.py:123} INFO - ::group::Pre task execution logs
[2025-01-26T06:41:09.146+0000] {taskinstance.py:2613} INFO - Dependencies all met for dep_context=non-requeueable deps ti=<TaskInstance: fetch_and_store_ebooks.create_table scheduled__2025-01-19T00:00:00+00:00 [queued]>
[2025-01-26T06:41:09.234+0000] {taskinstance.py:2613} INFO - Dependencies all met for dep_context=requeueable deps ti=<TaskInstance: fetch_and_store_ebooks.create_table scheduled__2025-01-19T00:00:00+00:00 [queued]>
[2025-01-26T06:41:09.236+0000] {taskinstance.py:2866} INFO - Starting attempt 1 of 2
[2025-01-26T06:41:09.961+0000] {taskinstance.py:2889} INFO - Executing <Task(PostgresOperator): create_table> on 2025-01-19 00:00:00+00:00
[2025-01-26T06:41:10.002+0000] {warnings.py:112} WARNING - /home/***/.local/lib/python3.12/site-packages/***/task/task_runner/standard_task_runner.py:70: DeprecationWarning: This process (pid=679) is multi-threaded, use of fork() may lead to deadlocks in the child.
  pid = os.fork()

[2025-01-26T06:41:10.013+0000] {standard_task_runner.py:72} INFO - Started process 697 to run task
[2025-01-26T06:41:10.037+0000] {standard_task_runner.py:104} INFO - Running: ['***', 'tasks', 'run', 'fetch_and_store_ebooks', 'create_table', 'scheduled__2025-01-19T00:00:00+00:00', '--job-id', '593', '--raw', '--subdir', 'DAGS_FOLDER/app.py', '--cfg-path', '/tmp/tmp4tnn30ek']
[2025-01-26T06:41:10.059+0000] {standard_task_runner.py:105} INFO - Job 593: Subtask create_table
[2025-01-26T06:41:10.444+0000] {task_command.py:467} INFO - Running <TaskInstance: fetch_and_store_ebooks.create_table scheduled__2025-01-19T00:00:00+00:00 [running]> on host 34edd304782d
[2025-01-26T06:41:10.980+0000] {taskinstance.py:3132} INFO - Exporting env vars: AIRFLOW_CTX_DAG_OWNER='***' AIRFLOW_CTX_DAG_ID='fetch_and_store_ebooks' AIRFLOW_CTX_TASK_ID='create_table' AIRFLOW_CTX_EXECUTION_DATE='2025-01-19T00:00:00+00:00' AIRFLOW_CTX_TRY_NUMBER='1' AIRFLOW_CTX_DAG_RUN_ID='scheduled__2025-01-19T00:00:00+00:00'
[2025-01-26T06:41:10.986+0000] {logging_mixin.py:190} INFO - Task instance is in running state
[2025-01-26T06:41:10.988+0000] {logging_mixin.py:190} INFO -  Previous state of the Task instance: queued
[2025-01-26T06:41:10.990+0000] {logging_mixin.py:190} INFO - Current task name:create_table state:running start_date:2025-01-26 06:41:09.150492+00:00
[2025-01-26T06:41:10.992+0000] {logging_mixin.py:190} INFO - Dag name:fetch_and_store_ebooks and current dag run status:running
[2025-01-26T06:41:10.999+0000] {taskinstance.py:731} INFO - ::endgroup::
[2025-01-26T06:41:11.002+0000] {sql.py:278} INFO - Executing: 
    CREATE TABLE IF NOT EXISTS ebooks (
        id SERIAL PRIMARY KEY,
        judul TEXT NOT NULL,
        penulis TEXT,
        link TEXT
    );
    
[2025-01-26T06:41:11.044+0000] {base.py:84} INFO - Retrieving connection 'ebooks_connection'
[2025-01-26T06:41:11.075+0000] {base.py:84} INFO - Retrieving connection 'ebooks_connection'
[2025-01-26T06:41:11.277+0000] {sql.py:553} INFO - Running statement: 
    CREATE TABLE IF NOT EXISTS ebooks (
        id SERIAL PRIMARY KEY,
        judul TEXT NOT NULL,
        penulis TEXT,
        link TEXT
    );
    , parameters: None
[2025-01-26T06:41:11.291+0000] {taskinstance.py:3311} ERROR - Task failed with exception
Traceback (most recent call last):
  File "/home/airflow/.local/lib/python3.12/site-packages/airflow/models/taskinstance.py", line 767, in _execute_task
    result = _execute_callable(context=context, **execute_callable_kwargs)
             ^^^^^^^^^^^^^^^^^^^^^^^^^^^^^^^^^^^^^^^^^^^^^^^^^^^^^^^^^^^^^
  File "/home/airflow/.local/lib/python3.12/site-packages/airflow/models/taskinstance.py", line 733, in _execute_callable
    return ExecutionCallableRunner(
           ^^^^^^^^^^^^^^^^^^^^^^^^
  File "/home/airflow/.local/lib/python3.12/site-packages/airflow/utils/operator_helpers.py", line 252, in run
    return self.func(*args, **kwargs)
           ^^^^^^^^^^^^^^^^^^^^^^^^^^
  File "/home/airflow/.local/lib/python3.12/site-packages/airflow/models/baseoperator.py", line 422, in wrapper
    return func(self, *args, **kwargs)
           ^^^^^^^^^^^^^^^^^^^^^^^^^^^
  File "/home/airflow/.local/lib/python3.12/site-packages/airflow/providers/common/sql/operators/sql.py", line 284, in execute
    output = hook.run(
             ^^^^^^^^^
  File "/home/airflow/.local/lib/python3.12/site-packages/airflow/providers/common/sql/hooks/sql.py", line 498, in run
    self._run_command(cur, sql_statement, parameters)
  File "/home/airflow/.local/lib/python3.12/site-packages/airflow/providers/common/sql/hooks/sql.py", line 558, in _run_command
    cur.execute(sql_statement)
psycopg2.errors.InsufficientPrivilege: permission denied for schema public
LINE 2:     CREATE TABLE IF NOT EXISTS ebooks (
                                       ^

[2025-01-26T06:41:11.368+0000] {logging_mixin.py:190} INFO - Task instance in failure state
[2025-01-26T06:41:11.375+0000] {logging_mixin.py:190} INFO - Task start:2025-01-26 06:41:09.150492+00:00 end:2025-01-26 06:41:11.365664+00:00 duration:2.215172
[2025-01-26T06:41:11.378+0000] {logging_mixin.py:190} INFO - Task:<Task(PostgresOperator): create_table> dag:<DAG: fetch_and_store_ebooks> dagrun:<DagRun fetch_and_store_ebooks @ 2025-01-19 00:00:00+00:00: scheduled__2025-01-19T00:00:00+00:00, state:running, queued_at: 2025-01-26 06:40:11.243394+00:00. externally triggered: False>
[2025-01-26T06:41:11.381+0000] {logging_mixin.py:190} INFO - Failure caused by permission denied for schema public
LINE 2:     CREATE TABLE IF NOT EXISTS ebooks (
                                       ^
[2025-01-26T06:41:11.384+0000] {taskinstance.py:1225} INFO - Marking task as UP_FOR_RETRY. dag_id=fetch_and_store_ebooks, task_id=create_table, run_id=scheduled__2025-01-19T00:00:00+00:00, execution_date=20250119T000000, start_date=20250126T064109, end_date=20250126T064111
[2025-01-26T06:41:11.488+0000] {taskinstance.py:340} INFO - ::group::Post task execution logs
[2025-01-26T06:41:11.491+0000] {standard_task_runner.py:124} ERROR - Failed to execute job 593 for task create_table (permission denied for schema public
LINE 2:     CREATE TABLE IF NOT EXISTS ebooks (
                                       ^
; 697)
Traceback (most recent call last):
  File "/home/airflow/.local/lib/python3.12/site-packages/airflow/task/task_runner/standard_task_runner.py", line 117, in _start_by_fork
    ret = args.func(args, dag=self.dag)
          ^^^^^^^^^^^^^^^^^^^^^^^^^^^^^
  File "/home/airflow/.local/lib/python3.12/site-packages/airflow/cli/cli_config.py", line 49, in command
    return func(*args, **kwargs)
           ^^^^^^^^^^^^^^^^^^^^^
  File "/home/airflow/.local/lib/python3.12/site-packages/airflow/utils/cli.py", line 116, in wrapper
    return f(*args, **kwargs)
           ^^^^^^^^^^^^^^^^^^
  File "/home/airflow/.local/lib/python3.12/site-packages/airflow/cli/commands/task_command.py", line 483, in task_run
    task_return_code = _run_task_by_selected_method(args, _dag, ti)
                       ^^^^^^^^^^^^^^^^^^^^^^^^^^^^^^^^^^^^^^^^^^^^
  File "/home/airflow/.local/lib/python3.12/site-packages/airflow/cli/commands/task_command.py", line 256, in _run_task_by_selected_method
    return _run_raw_task(args, ti)
           ^^^^^^^^^^^^^^^^^^^^^^^
  File "/home/airflow/.local/lib/python3.12/site-packages/airflow/cli/commands/task_command.py", line 341, in _run_raw_task
    return ti._run_raw_task(
           ^^^^^^^^^^^^^^^^^
  File "/home/airflow/.local/lib/python3.12/site-packages/airflow/utils/session.py", line 97, in wrapper
    return func(*args, session=session, **kwargs)
           ^^^^^^^^^^^^^^^^^^^^^^^^^^^^^^^^^^^^^^
  File "/home/airflow/.local/lib/python3.12/site-packages/airflow/models/taskinstance.py", line 3005, in _run_raw_task
    return _run_raw_task(
           ^^^^^^^^^^^^^^
  File "/home/airflow/.local/lib/python3.12/site-packages/airflow/models/taskinstance.py", line 273, in _run_raw_task
    TaskInstance._execute_task_with_callbacks(
  File "/home/airflow/.local/lib/python3.12/site-packages/airflow/models/taskinstance.py", line 3159, in _execute_task_with_callbacks
    result = self._execute_task(context, task_orig)
             ^^^^^^^^^^^^^^^^^^^^^^^^^^^^^^^^^^^^^^
  File "/home/airflow/.local/lib/python3.12/site-packages/airflow/models/taskinstance.py", line 3183, in _execute_task
    return _execute_task(self, context, task_orig)
           ^^^^^^^^^^^^^^^^^^^^^^^^^^^^^^^^^^^^^^^
  File "/home/airflow/.local/lib/python3.12/site-packages/airflow/models/taskinstance.py", line 767, in _execute_task
    result = _execute_callable(context=context, **execute_callable_kwargs)
             ^^^^^^^^^^^^^^^^^^^^^^^^^^^^^^^^^^^^^^^^^^^^^^^^^^^^^^^^^^^^^
  File "/home/airflow/.local/lib/python3.12/site-packages/airflow/models/taskinstance.py", line 733, in _execute_callable
    return ExecutionCallableRunner(
           ^^^^^^^^^^^^^^^^^^^^^^^^
  File "/home/airflow/.local/lib/python3.12/site-packages/airflow/utils/operator_helpers.py", line 252, in run
    return self.func(*args, **kwargs)
           ^^^^^^^^^^^^^^^^^^^^^^^^^^
  File "/home/airflow/.local/lib/python3.12/site-packages/airflow/models/baseoperator.py", line 422, in wrapper
    return func(self, *args, **kwargs)
           ^^^^^^^^^^^^^^^^^^^^^^^^^^^
  File "/home/airflow/.local/lib/python3.12/site-packages/airflow/providers/common/sql/operators/sql.py", line 284, in execute
    output = hook.run(
             ^^^^^^^^^
  File "/home/airflow/.local/lib/python3.12/site-packages/airflow/providers/common/sql/hooks/sql.py", line 498, in run
    self._run_command(cur, sql_statement, parameters)
  File "/home/airflow/.local/lib/python3.12/site-packages/airflow/providers/common/sql/hooks/sql.py", line 558, in _run_command
    cur.execute(sql_statement)
psycopg2.errors.InsufficientPrivilege: permission denied for schema public
LINE 2:     CREATE TABLE IF NOT EXISTS ebooks (
                                       ^

[2025-01-26T06:41:11.573+0000] {local_task_job_runner.py:266} INFO - Task exited with return code 1
[2025-01-26T06:41:11.679+0000] {taskinstance.py:3895} INFO - 0 downstream tasks scheduled from follow-on schedule check
[2025-01-26T06:41:11.686+0000] {local_task_job_runner.py:245} INFO - ::endgroup::
[2025-01-26T07:29:57.140+0000] {local_task_job_runner.py:123} INFO - ::group::Pre task execution logs
[2025-01-26T07:29:57.314+0000] {taskinstance.py:2613} INFO - Dependencies all met for dep_context=non-requeueable deps ti=<TaskInstance: fetch_and_store_ebooks.create_table scheduled__2025-01-19T00:00:00+00:00 [queued]>
[2025-01-26T07:29:57.438+0000] {taskinstance.py:2613} INFO - Dependencies all met for dep_context=requeueable deps ti=<TaskInstance: fetch_and_store_ebooks.create_table scheduled__2025-01-19T00:00:00+00:00 [queued]>
[2025-01-26T07:29:57.444+0000] {taskinstance.py:2866} INFO - Starting attempt 1 of 2
[2025-01-26T07:29:57.596+0000] {taskinstance.py:2889} INFO - Executing <Task(PostgresOperator): create_table> on 2025-01-19 00:00:00+00:00
[2025-01-26T07:29:57.627+0000] {warnings.py:112} WARNING - /home/***/.local/lib/python3.12/site-packages/***/task/task_runner/standard_task_runner.py:70: DeprecationWarning: This process (pid=1535) is multi-threaded, use of fork() may lead to deadlocks in the child.
  pid = os.fork()

[2025-01-26T07:29:57.637+0000] {standard_task_runner.py:104} INFO - Running: ['***', 'tasks', 'run', 'fetch_and_store_ebooks', 'create_table', 'scheduled__2025-01-19T00:00:00+00:00', '--job-id', '682', '--raw', '--subdir', 'DAGS_FOLDER/app.py', '--cfg-path', '/tmp/tmpqe6hnbcb']
[2025-01-26T07:29:57.639+0000] {standard_task_runner.py:72} INFO - Started process 1559 to run task
[2025-01-26T07:29:57.642+0000] {standard_task_runner.py:105} INFO - Job 682: Subtask create_table
[2025-01-26T07:29:58.875+0000] {task_command.py:467} INFO - Running <TaskInstance: fetch_and_store_ebooks.create_table scheduled__2025-01-19T00:00:00+00:00 [running]> on host 34edd304782d
[2025-01-26T07:29:59.335+0000] {taskinstance.py:3132} INFO - Exporting env vars: AIRFLOW_CTX_DAG_OWNER='***' AIRFLOW_CTX_DAG_ID='fetch_and_store_ebooks' AIRFLOW_CTX_TASK_ID='create_table' AIRFLOW_CTX_EXECUTION_DATE='2025-01-19T00:00:00+00:00' AIRFLOW_CTX_TRY_NUMBER='1' AIRFLOW_CTX_DAG_RUN_ID='scheduled__2025-01-19T00:00:00+00:00'
[2025-01-26T07:29:59.339+0000] {logging_mixin.py:190} INFO - Task instance is in running state
[2025-01-26T07:29:59.343+0000] {logging_mixin.py:190} INFO -  Previous state of the Task instance: queued
[2025-01-26T07:29:59.346+0000] {logging_mixin.py:190} INFO - Current task name:create_table state:running start_date:2025-01-26 07:29:57.316944+00:00
[2025-01-26T07:29:59.348+0000] {logging_mixin.py:190} INFO - Dag name:fetch_and_store_ebooks and current dag run status:running
[2025-01-26T07:29:59.350+0000] {taskinstance.py:731} INFO - ::endgroup::
[2025-01-26T07:29:59.352+0000] {sql.py:278} INFO - Executing: 
    CREATE TABLE IF NOT EXISTS ebooks (
        id SERIAL PRIMARY KEY,
        judul TEXT NOT NULL,
        penulis TEXT,
        link TEXT
    );
    
[2025-01-26T07:29:59.390+0000] {base.py:84} INFO - Retrieving connection 'ebooks_connection'
[2025-01-26T07:29:59.421+0000] {base.py:84} INFO - Retrieving connection 'ebooks_connection'
[2025-01-26T07:29:59.781+0000] {sql.py:553} INFO - Running statement: 
    CREATE TABLE IF NOT EXISTS ebooks (
        id SERIAL PRIMARY KEY,
        judul TEXT NOT NULL,
        penulis TEXT,
        link TEXT
    );
    , parameters: None
[2025-01-26T07:29:59.796+0000] {taskinstance.py:3311} ERROR - Task failed with exception
Traceback (most recent call last):
  File "/home/airflow/.local/lib/python3.12/site-packages/airflow/models/taskinstance.py", line 767, in _execute_task
    result = _execute_callable(context=context, **execute_callable_kwargs)
             ^^^^^^^^^^^^^^^^^^^^^^^^^^^^^^^^^^^^^^^^^^^^^^^^^^^^^^^^^^^^^
  File "/home/airflow/.local/lib/python3.12/site-packages/airflow/models/taskinstance.py", line 733, in _execute_callable
    return ExecutionCallableRunner(
           ^^^^^^^^^^^^^^^^^^^^^^^^
  File "/home/airflow/.local/lib/python3.12/site-packages/airflow/utils/operator_helpers.py", line 252, in run
    return self.func(*args, **kwargs)
           ^^^^^^^^^^^^^^^^^^^^^^^^^^
  File "/home/airflow/.local/lib/python3.12/site-packages/airflow/models/baseoperator.py", line 422, in wrapper
    return func(self, *args, **kwargs)
           ^^^^^^^^^^^^^^^^^^^^^^^^^^^
  File "/home/airflow/.local/lib/python3.12/site-packages/airflow/providers/common/sql/operators/sql.py", line 284, in execute
    output = hook.run(
             ^^^^^^^^^
  File "/home/airflow/.local/lib/python3.12/site-packages/airflow/providers/common/sql/hooks/sql.py", line 498, in run
    self._run_command(cur, sql_statement, parameters)
  File "/home/airflow/.local/lib/python3.12/site-packages/airflow/providers/common/sql/hooks/sql.py", line 558, in _run_command
    cur.execute(sql_statement)
psycopg2.errors.InsufficientPrivilege: permission denied for schema public
LINE 2:     CREATE TABLE IF NOT EXISTS ebooks (
                                       ^

[2025-01-26T07:29:59.924+0000] {logging_mixin.py:190} INFO - Task instance in failure state
[2025-01-26T07:29:59.926+0000] {logging_mixin.py:190} INFO - Task start:2025-01-26 07:29:57.316944+00:00 end:2025-01-26 07:29:59.919902+00:00 duration:2.602958
[2025-01-26T07:29:59.932+0000] {logging_mixin.py:190} INFO - Task:<Task(PostgresOperator): create_table> dag:<DAG: fetch_and_store_ebooks> dagrun:<DagRun fetch_and_store_ebooks @ 2025-01-19 00:00:00+00:00: scheduled__2025-01-19T00:00:00+00:00, state:running, queued_at: 2025-01-26 07:28:35.095117+00:00. externally triggered: False>
[2025-01-26T07:29:59.935+0000] {logging_mixin.py:190} INFO - Failure caused by permission denied for schema public
LINE 2:     CREATE TABLE IF NOT EXISTS ebooks (
                                       ^
[2025-01-26T07:29:59.939+0000] {taskinstance.py:1225} INFO - Marking task as UP_FOR_RETRY. dag_id=fetch_and_store_ebooks, task_id=create_table, run_id=scheduled__2025-01-19T00:00:00+00:00, execution_date=20250119T000000, start_date=20250126T072957, end_date=20250126T072959
[2025-01-26T07:30:00.063+0000] {taskinstance.py:340} INFO - ::group::Post task execution logs
[2025-01-26T07:30:00.067+0000] {standard_task_runner.py:124} ERROR - Failed to execute job 682 for task create_table (permission denied for schema public
LINE 2:     CREATE TABLE IF NOT EXISTS ebooks (
                                       ^
; 1559)
Traceback (most recent call last):
  File "/home/airflow/.local/lib/python3.12/site-packages/airflow/task/task_runner/standard_task_runner.py", line 117, in _start_by_fork
    ret = args.func(args, dag=self.dag)
          ^^^^^^^^^^^^^^^^^^^^^^^^^^^^^
  File "/home/airflow/.local/lib/python3.12/site-packages/airflow/cli/cli_config.py", line 49, in command
    return func(*args, **kwargs)
           ^^^^^^^^^^^^^^^^^^^^^
  File "/home/airflow/.local/lib/python3.12/site-packages/airflow/utils/cli.py", line 116, in wrapper
    return f(*args, **kwargs)
           ^^^^^^^^^^^^^^^^^^
  File "/home/airflow/.local/lib/python3.12/site-packages/airflow/cli/commands/task_command.py", line 483, in task_run
    task_return_code = _run_task_by_selected_method(args, _dag, ti)
                       ^^^^^^^^^^^^^^^^^^^^^^^^^^^^^^^^^^^^^^^^^^^^
  File "/home/airflow/.local/lib/python3.12/site-packages/airflow/cli/commands/task_command.py", line 256, in _run_task_by_selected_method
    return _run_raw_task(args, ti)
           ^^^^^^^^^^^^^^^^^^^^^^^
  File "/home/airflow/.local/lib/python3.12/site-packages/airflow/cli/commands/task_command.py", line 341, in _run_raw_task
    return ti._run_raw_task(
           ^^^^^^^^^^^^^^^^^
  File "/home/airflow/.local/lib/python3.12/site-packages/airflow/utils/session.py", line 97, in wrapper
    return func(*args, session=session, **kwargs)
           ^^^^^^^^^^^^^^^^^^^^^^^^^^^^^^^^^^^^^^
  File "/home/airflow/.local/lib/python3.12/site-packages/airflow/models/taskinstance.py", line 3005, in _run_raw_task
    return _run_raw_task(
           ^^^^^^^^^^^^^^
  File "/home/airflow/.local/lib/python3.12/site-packages/airflow/models/taskinstance.py", line 273, in _run_raw_task
    TaskInstance._execute_task_with_callbacks(
  File "/home/airflow/.local/lib/python3.12/site-packages/airflow/models/taskinstance.py", line 3159, in _execute_task_with_callbacks
    result = self._execute_task(context, task_orig)
             ^^^^^^^^^^^^^^^^^^^^^^^^^^^^^^^^^^^^^^
  File "/home/airflow/.local/lib/python3.12/site-packages/airflow/models/taskinstance.py", line 3183, in _execute_task
    return _execute_task(self, context, task_orig)
           ^^^^^^^^^^^^^^^^^^^^^^^^^^^^^^^^^^^^^^^
  File "/home/airflow/.local/lib/python3.12/site-packages/airflow/models/taskinstance.py", line 767, in _execute_task
    result = _execute_callable(context=context, **execute_callable_kwargs)
             ^^^^^^^^^^^^^^^^^^^^^^^^^^^^^^^^^^^^^^^^^^^^^^^^^^^^^^^^^^^^^
  File "/home/airflow/.local/lib/python3.12/site-packages/airflow/models/taskinstance.py", line 733, in _execute_callable
    return ExecutionCallableRunner(
           ^^^^^^^^^^^^^^^^^^^^^^^^
  File "/home/airflow/.local/lib/python3.12/site-packages/airflow/utils/operator_helpers.py", line 252, in run
    return self.func(*args, **kwargs)
           ^^^^^^^^^^^^^^^^^^^^^^^^^^
  File "/home/airflow/.local/lib/python3.12/site-packages/airflow/models/baseoperator.py", line 422, in wrapper
    return func(self, *args, **kwargs)
           ^^^^^^^^^^^^^^^^^^^^^^^^^^^
  File "/home/airflow/.local/lib/python3.12/site-packages/airflow/providers/common/sql/operators/sql.py", line 284, in execute
    output = hook.run(
             ^^^^^^^^^
  File "/home/airflow/.local/lib/python3.12/site-packages/airflow/providers/common/sql/hooks/sql.py", line 498, in run
    self._run_command(cur, sql_statement, parameters)
  File "/home/airflow/.local/lib/python3.12/site-packages/airflow/providers/common/sql/hooks/sql.py", line 558, in _run_command
    cur.execute(sql_statement)
psycopg2.errors.InsufficientPrivilege: permission denied for schema public
LINE 2:     CREATE TABLE IF NOT EXISTS ebooks (
                                       ^

[2025-01-26T07:30:00.175+0000] {local_task_job_runner.py:266} INFO - Task exited with return code 1
[2025-01-26T07:30:00.234+0000] {local_task_job_runner.py:245} INFO - ::endgroup::
[2025-01-26T07:54:45.163+0000] {local_task_job_runner.py:123} INFO - ::group::Pre task execution logs
[2025-01-26T07:54:45.266+0000] {taskinstance.py:2613} INFO - Dependencies all met for dep_context=non-requeueable deps ti=<TaskInstance: fetch_and_store_ebooks.create_table scheduled__2025-01-19T00:00:00+00:00 [queued]>
[2025-01-26T07:54:45.353+0000] {taskinstance.py:2613} INFO - Dependencies all met for dep_context=requeueable deps ti=<TaskInstance: fetch_and_store_ebooks.create_table scheduled__2025-01-19T00:00:00+00:00 [queued]>
[2025-01-26T07:54:45.356+0000] {taskinstance.py:2866} INFO - Starting attempt 1 of 2
[2025-01-26T07:54:45.524+0000] {taskinstance.py:2889} INFO - Executing <Task(PostgresOperator): create_table> on 2025-01-19 00:00:00+00:00
[2025-01-26T07:54:45.551+0000] {warnings.py:112} WARNING - /home/***/.local/lib/python3.12/site-packages/***/task/task_runner/standard_task_runner.py:70: DeprecationWarning: This process (pid=2200) is multi-threaded, use of fork() may lead to deadlocks in the child.
  pid = os.fork()

[2025-01-26T07:54:45.557+0000] {standard_task_runner.py:72} INFO - Started process 2228 to run task
[2025-01-26T07:54:45.570+0000] {standard_task_runner.py:104} INFO - Running: ['***', 'tasks', 'run', 'fetch_and_store_ebooks', 'create_table', 'scheduled__2025-01-19T00:00:00+00:00', '--job-id', '777', '--raw', '--subdir', 'DAGS_FOLDER/app.py', '--cfg-path', '/tmp/tmplbj8_oji']
[2025-01-26T07:54:45.585+0000] {standard_task_runner.py:105} INFO - Job 777: Subtask create_table
[2025-01-26T07:54:46.082+0000] {task_command.py:467} INFO - Running <TaskInstance: fetch_and_store_ebooks.create_table scheduled__2025-01-19T00:00:00+00:00 [running]> on host 34edd304782d
[2025-01-26T07:54:46.696+0000] {taskinstance.py:3132} INFO - Exporting env vars: AIRFLOW_CTX_DAG_OWNER='***' AIRFLOW_CTX_DAG_ID='fetch_and_store_ebooks' AIRFLOW_CTX_TASK_ID='create_table' AIRFLOW_CTX_EXECUTION_DATE='2025-01-19T00:00:00+00:00' AIRFLOW_CTX_TRY_NUMBER='1' AIRFLOW_CTX_DAG_RUN_ID='scheduled__2025-01-19T00:00:00+00:00'
[2025-01-26T07:54:46.720+0000] {logging_mixin.py:190} INFO - Task instance is in running state
[2025-01-26T07:54:46.727+0000] {logging_mixin.py:190} INFO -  Previous state of the Task instance: queued
[2025-01-26T07:54:46.730+0000] {logging_mixin.py:190} INFO - Current task name:create_table state:running start_date:2025-01-26 07:54:45.292608+00:00
[2025-01-26T07:54:46.738+0000] {logging_mixin.py:190} INFO - Dag name:fetch_and_store_ebooks and current dag run status:running
[2025-01-26T07:54:46.743+0000] {taskinstance.py:731} INFO - ::endgroup::
[2025-01-26T07:54:46.763+0000] {sql.py:278} INFO - Executing: 
    CREATE TABLE IF NOT EXISTS ebooks (
        id SERIAL PRIMARY KEY,
        judul TEXT NOT NULL,
        penulis TEXT,
        link TEXT
    );
    
[2025-01-26T07:54:46.870+0000] {base.py:84} INFO - Retrieving connection 'ebooks_connection'
[2025-01-26T07:54:46.961+0000] {base.py:84} INFO - Retrieving connection 'ebooks_connection'
[2025-01-26T07:54:47.292+0000] {sql.py:553} INFO - Running statement: 
    CREATE TABLE IF NOT EXISTS ebooks (
        id SERIAL PRIMARY KEY,
        judul TEXT NOT NULL,
        penulis TEXT,
        link TEXT
    );
    , parameters: None
[2025-01-26T07:54:47.306+0000] {taskinstance.py:3311} ERROR - Task failed with exception
Traceback (most recent call last):
  File "/home/airflow/.local/lib/python3.12/site-packages/airflow/models/taskinstance.py", line 767, in _execute_task
    result = _execute_callable(context=context, **execute_callable_kwargs)
             ^^^^^^^^^^^^^^^^^^^^^^^^^^^^^^^^^^^^^^^^^^^^^^^^^^^^^^^^^^^^^
  File "/home/airflow/.local/lib/python3.12/site-packages/airflow/models/taskinstance.py", line 733, in _execute_callable
    return ExecutionCallableRunner(
           ^^^^^^^^^^^^^^^^^^^^^^^^
  File "/home/airflow/.local/lib/python3.12/site-packages/airflow/utils/operator_helpers.py", line 252, in run
    return self.func(*args, **kwargs)
           ^^^^^^^^^^^^^^^^^^^^^^^^^^
  File "/home/airflow/.local/lib/python3.12/site-packages/airflow/models/baseoperator.py", line 422, in wrapper
    return func(self, *args, **kwargs)
           ^^^^^^^^^^^^^^^^^^^^^^^^^^^
  File "/home/airflow/.local/lib/python3.12/site-packages/airflow/providers/common/sql/operators/sql.py", line 284, in execute
    output = hook.run(
             ^^^^^^^^^
  File "/home/airflow/.local/lib/python3.12/site-packages/airflow/providers/common/sql/hooks/sql.py", line 498, in run
    self._run_command(cur, sql_statement, parameters)
  File "/home/airflow/.local/lib/python3.12/site-packages/airflow/providers/common/sql/hooks/sql.py", line 558, in _run_command
    cur.execute(sql_statement)
psycopg2.errors.InsufficientPrivilege: permission denied for schema public
LINE 2:     CREATE TABLE IF NOT EXISTS ebooks (
                                       ^

[2025-01-26T07:54:47.428+0000] {logging_mixin.py:190} INFO - Task instance in failure state
[2025-01-26T07:54:47.445+0000] {logging_mixin.py:190} INFO - Task start:2025-01-26 07:54:45.292608+00:00 end:2025-01-26 07:54:47.425740+00:00 duration:2.133132
[2025-01-26T07:54:47.450+0000] {logging_mixin.py:190} INFO - Task:<Task(PostgresOperator): create_table> dag:<DAG: fetch_and_store_ebooks> dagrun:<DagRun fetch_and_store_ebooks @ 2025-01-19 00:00:00+00:00: scheduled__2025-01-19T00:00:00+00:00, state:running, queued_at: 2025-01-26 07:54:04.772121+00:00. externally triggered: False>
[2025-01-26T07:54:47.452+0000] {logging_mixin.py:190} INFO - Failure caused by permission denied for schema public
LINE 2:     CREATE TABLE IF NOT EXISTS ebooks (
                                       ^
[2025-01-26T07:54:47.468+0000] {taskinstance.py:1225} INFO - Marking task as UP_FOR_RETRY. dag_id=fetch_and_store_ebooks, task_id=create_table, run_id=scheduled__2025-01-19T00:00:00+00:00, execution_date=20250119T000000, start_date=20250126T075445, end_date=20250126T075447
[2025-01-26T07:54:47.600+0000] {taskinstance.py:340} INFO - ::group::Post task execution logs
[2025-01-26T07:54:47.624+0000] {standard_task_runner.py:124} ERROR - Failed to execute job 777 for task create_table (permission denied for schema public
LINE 2:     CREATE TABLE IF NOT EXISTS ebooks (
                                       ^
; 2228)
Traceback (most recent call last):
  File "/home/airflow/.local/lib/python3.12/site-packages/airflow/task/task_runner/standard_task_runner.py", line 117, in _start_by_fork
    ret = args.func(args, dag=self.dag)
          ^^^^^^^^^^^^^^^^^^^^^^^^^^^^^
  File "/home/airflow/.local/lib/python3.12/site-packages/airflow/cli/cli_config.py", line 49, in command
    return func(*args, **kwargs)
           ^^^^^^^^^^^^^^^^^^^^^
  File "/home/airflow/.local/lib/python3.12/site-packages/airflow/utils/cli.py", line 116, in wrapper
    return f(*args, **kwargs)
           ^^^^^^^^^^^^^^^^^^
  File "/home/airflow/.local/lib/python3.12/site-packages/airflow/cli/commands/task_command.py", line 483, in task_run
    task_return_code = _run_task_by_selected_method(args, _dag, ti)
                       ^^^^^^^^^^^^^^^^^^^^^^^^^^^^^^^^^^^^^^^^^^^^
  File "/home/airflow/.local/lib/python3.12/site-packages/airflow/cli/commands/task_command.py", line 256, in _run_task_by_selected_method
    return _run_raw_task(args, ti)
           ^^^^^^^^^^^^^^^^^^^^^^^
  File "/home/airflow/.local/lib/python3.12/site-packages/airflow/cli/commands/task_command.py", line 341, in _run_raw_task
    return ti._run_raw_task(
           ^^^^^^^^^^^^^^^^^
  File "/home/airflow/.local/lib/python3.12/site-packages/airflow/utils/session.py", line 97, in wrapper
    return func(*args, session=session, **kwargs)
           ^^^^^^^^^^^^^^^^^^^^^^^^^^^^^^^^^^^^^^
  File "/home/airflow/.local/lib/python3.12/site-packages/airflow/models/taskinstance.py", line 3005, in _run_raw_task
    return _run_raw_task(
           ^^^^^^^^^^^^^^
  File "/home/airflow/.local/lib/python3.12/site-packages/airflow/models/taskinstance.py", line 273, in _run_raw_task
    TaskInstance._execute_task_with_callbacks(
  File "/home/airflow/.local/lib/python3.12/site-packages/airflow/models/taskinstance.py", line 3159, in _execute_task_with_callbacks
    result = self._execute_task(context, task_orig)
             ^^^^^^^^^^^^^^^^^^^^^^^^^^^^^^^^^^^^^^
  File "/home/airflow/.local/lib/python3.12/site-packages/airflow/models/taskinstance.py", line 3183, in _execute_task
    return _execute_task(self, context, task_orig)
           ^^^^^^^^^^^^^^^^^^^^^^^^^^^^^^^^^^^^^^^
  File "/home/airflow/.local/lib/python3.12/site-packages/airflow/models/taskinstance.py", line 767, in _execute_task
    result = _execute_callable(context=context, **execute_callable_kwargs)
             ^^^^^^^^^^^^^^^^^^^^^^^^^^^^^^^^^^^^^^^^^^^^^^^^^^^^^^^^^^^^^
  File "/home/airflow/.local/lib/python3.12/site-packages/airflow/models/taskinstance.py", line 733, in _execute_callable
    return ExecutionCallableRunner(
           ^^^^^^^^^^^^^^^^^^^^^^^^
  File "/home/airflow/.local/lib/python3.12/site-packages/airflow/utils/operator_helpers.py", line 252, in run
    return self.func(*args, **kwargs)
           ^^^^^^^^^^^^^^^^^^^^^^^^^^
  File "/home/airflow/.local/lib/python3.12/site-packages/airflow/models/baseoperator.py", line 422, in wrapper
    return func(self, *args, **kwargs)
           ^^^^^^^^^^^^^^^^^^^^^^^^^^^
  File "/home/airflow/.local/lib/python3.12/site-packages/airflow/providers/common/sql/operators/sql.py", line 284, in execute
    output = hook.run(
             ^^^^^^^^^
  File "/home/airflow/.local/lib/python3.12/site-packages/airflow/providers/common/sql/hooks/sql.py", line 498, in run
    self._run_command(cur, sql_statement, parameters)
  File "/home/airflow/.local/lib/python3.12/site-packages/airflow/providers/common/sql/hooks/sql.py", line 558, in _run_command
    cur.execute(sql_statement)
psycopg2.errors.InsufficientPrivilege: permission denied for schema public
LINE 2:     CREATE TABLE IF NOT EXISTS ebooks (
                                       ^

[2025-01-26T07:54:47.730+0000] {local_task_job_runner.py:266} INFO - Task exited with return code 1
[2025-01-26T07:54:47.805+0000] {local_task_job_runner.py:245} INFO - ::endgroup::
[2025-01-26T09:13:07.402+0000] {local_task_job_runner.py:123} INFO - ::group::Pre task execution logs
[2025-01-26T09:13:07.612+0000] {taskinstance.py:2613} INFO - Dependencies all met for dep_context=non-requeueable deps ti=<TaskInstance: fetch_and_store_ebooks.create_table scheduled__2025-01-19T00:00:00+00:00 [queued]>
[2025-01-26T09:13:07.687+0000] {taskinstance.py:2613} INFO - Dependencies all met for dep_context=requeueable deps ti=<TaskInstance: fetch_and_store_ebooks.create_table scheduled__2025-01-19T00:00:00+00:00 [queued]>
[2025-01-26T09:13:07.695+0000] {taskinstance.py:2866} INFO - Starting attempt 1 of 2
[2025-01-26T09:13:07.872+0000] {taskinstance.py:2889} INFO - Executing <Task(PostgresOperator): create_table> on 2025-01-19 00:00:00+00:00
[2025-01-26T09:13:07.918+0000] {warnings.py:112} WARNING - /home/***/.local/lib/python3.12/site-packages/***/task/task_runner/standard_task_runner.py:70: DeprecationWarning: This process (pid=3902) is multi-threaded, use of fork() may lead to deadlocks in the child.
  pid = os.fork()

[2025-01-26T09:13:07.959+0000] {standard_task_runner.py:72} INFO - Started process 3929 to run task
[2025-01-26T09:13:07.938+0000] {standard_task_runner.py:104} INFO - Running: ['***', 'tasks', 'run', 'fetch_and_store_ebooks', 'create_table', 'scheduled__2025-01-19T00:00:00+00:00', '--job-id', '993', '--raw', '--subdir', 'DAGS_FOLDER/app.py', '--cfg-path', '/tmp/tmpxie097a9']
[2025-01-26T09:13:07.979+0000] {standard_task_runner.py:105} INFO - Job 993: Subtask create_table
[2025-01-26T09:13:08.529+0000] {task_command.py:467} INFO - Running <TaskInstance: fetch_and_store_ebooks.create_table scheduled__2025-01-19T00:00:00+00:00 [running]> on host 34edd304782d
[2025-01-26T09:13:09.305+0000] {taskinstance.py:3132} INFO - Exporting env vars: AIRFLOW_CTX_DAG_OWNER='***' AIRFLOW_CTX_DAG_ID='fetch_and_store_ebooks' AIRFLOW_CTX_TASK_ID='create_table' AIRFLOW_CTX_EXECUTION_DATE='2025-01-19T00:00:00+00:00' AIRFLOW_CTX_TRY_NUMBER='1' AIRFLOW_CTX_DAG_RUN_ID='scheduled__2025-01-19T00:00:00+00:00'
[2025-01-26T09:13:09.316+0000] {logging_mixin.py:190} INFO - Task instance is in running state
[2025-01-26T09:13:09.325+0000] {logging_mixin.py:190} INFO -  Previous state of the Task instance: queued
[2025-01-26T09:13:09.330+0000] {logging_mixin.py:190} INFO - Current task name:create_table state:running start_date:2025-01-26 09:13:07.618153+00:00
[2025-01-26T09:13:09.331+0000] {logging_mixin.py:190} INFO - Dag name:fetch_and_store_ebooks and current dag run status:running
[2025-01-26T09:13:09.336+0000] {taskinstance.py:731} INFO - ::endgroup::
[2025-01-26T09:13:09.338+0000] {sql.py:278} INFO - Executing: 
    CREATE TABLE IF NOT EXISTS ebooks (
        id SERIAL PRIMARY KEY,
        judul TEXT NOT NULL,
        penulis TEXT,
        link TEXT
    );
    
[2025-01-26T09:13:09.402+0000] {base.py:84} INFO - Retrieving connection 'ebooks_connection'
[2025-01-26T09:13:09.475+0000] {base.py:84} INFO - Retrieving connection 'ebooks_connection'
[2025-01-26T09:13:09.716+0000] {sql.py:553} INFO - Running statement: 
    CREATE TABLE IF NOT EXISTS ebooks (
        id SERIAL PRIMARY KEY,
        judul TEXT NOT NULL,
        penulis TEXT,
        link TEXT
    );
    , parameters: None
[2025-01-26T09:13:09.740+0000] {taskinstance.py:3311} ERROR - Task failed with exception
Traceback (most recent call last):
  File "/home/airflow/.local/lib/python3.12/site-packages/airflow/models/taskinstance.py", line 767, in _execute_task
    result = _execute_callable(context=context, **execute_callable_kwargs)
             ^^^^^^^^^^^^^^^^^^^^^^^^^^^^^^^^^^^^^^^^^^^^^^^^^^^^^^^^^^^^^
  File "/home/airflow/.local/lib/python3.12/site-packages/airflow/models/taskinstance.py", line 733, in _execute_callable
    return ExecutionCallableRunner(
           ^^^^^^^^^^^^^^^^^^^^^^^^
  File "/home/airflow/.local/lib/python3.12/site-packages/airflow/utils/operator_helpers.py", line 252, in run
    return self.func(*args, **kwargs)
           ^^^^^^^^^^^^^^^^^^^^^^^^^^
  File "/home/airflow/.local/lib/python3.12/site-packages/airflow/models/baseoperator.py", line 422, in wrapper
    return func(self, *args, **kwargs)
           ^^^^^^^^^^^^^^^^^^^^^^^^^^^
  File "/home/airflow/.local/lib/python3.12/site-packages/airflow/providers/common/sql/operators/sql.py", line 284, in execute
    output = hook.run(
             ^^^^^^^^^
  File "/home/airflow/.local/lib/python3.12/site-packages/airflow/providers/common/sql/hooks/sql.py", line 498, in run
    self._run_command(cur, sql_statement, parameters)
  File "/home/airflow/.local/lib/python3.12/site-packages/airflow/providers/common/sql/hooks/sql.py", line 558, in _run_command
    cur.execute(sql_statement)
psycopg2.errors.InsufficientPrivilege: permission denied for schema public
LINE 2:     CREATE TABLE IF NOT EXISTS ebooks (
                                       ^

[2025-01-26T09:13:09.875+0000] {logging_mixin.py:190} INFO - Task instance in failure state
[2025-01-26T09:13:09.878+0000] {logging_mixin.py:190} INFO - Task start:2025-01-26 09:13:07.618153+00:00 end:2025-01-26 09:13:09.873375+00:00 duration:2.255222
[2025-01-26T09:13:09.885+0000] {logging_mixin.py:190} INFO - Task:<Task(PostgresOperator): create_table> dag:<DAG: fetch_and_store_ebooks> dagrun:<DagRun fetch_and_store_ebooks @ 2025-01-19 00:00:00+00:00: scheduled__2025-01-19T00:00:00+00:00, state:running, queued_at: 2025-01-26 09:12:09.645212+00:00. externally triggered: False>
[2025-01-26T09:13:09.889+0000] {logging_mixin.py:190} INFO - Failure caused by permission denied for schema public
LINE 2:     CREATE TABLE IF NOT EXISTS ebooks (
                                       ^
[2025-01-26T09:13:09.893+0000] {taskinstance.py:1225} INFO - Marking task as UP_FOR_RETRY. dag_id=fetch_and_store_ebooks, task_id=create_table, run_id=scheduled__2025-01-19T00:00:00+00:00, execution_date=20250119T000000, start_date=20250126T091307, end_date=20250126T091309
[2025-01-26T09:13:10.087+0000] {taskinstance.py:340} INFO - ::group::Post task execution logs
[2025-01-26T09:13:10.097+0000] {standard_task_runner.py:124} ERROR - Failed to execute job 993 for task create_table (permission denied for schema public
LINE 2:     CREATE TABLE IF NOT EXISTS ebooks (
                                       ^
; 3929)
Traceback (most recent call last):
  File "/home/airflow/.local/lib/python3.12/site-packages/airflow/task/task_runner/standard_task_runner.py", line 117, in _start_by_fork
    ret = args.func(args, dag=self.dag)
          ^^^^^^^^^^^^^^^^^^^^^^^^^^^^^
  File "/home/airflow/.local/lib/python3.12/site-packages/airflow/cli/cli_config.py", line 49, in command
    return func(*args, **kwargs)
           ^^^^^^^^^^^^^^^^^^^^^
  File "/home/airflow/.local/lib/python3.12/site-packages/airflow/utils/cli.py", line 116, in wrapper
    return f(*args, **kwargs)
           ^^^^^^^^^^^^^^^^^^
  File "/home/airflow/.local/lib/python3.12/site-packages/airflow/cli/commands/task_command.py", line 483, in task_run
    task_return_code = _run_task_by_selected_method(args, _dag, ti)
                       ^^^^^^^^^^^^^^^^^^^^^^^^^^^^^^^^^^^^^^^^^^^^
  File "/home/airflow/.local/lib/python3.12/site-packages/airflow/cli/commands/task_command.py", line 256, in _run_task_by_selected_method
    return _run_raw_task(args, ti)
           ^^^^^^^^^^^^^^^^^^^^^^^
  File "/home/airflow/.local/lib/python3.12/site-packages/airflow/cli/commands/task_command.py", line 341, in _run_raw_task
    return ti._run_raw_task(
           ^^^^^^^^^^^^^^^^^
  File "/home/airflow/.local/lib/python3.12/site-packages/airflow/utils/session.py", line 97, in wrapper
    return func(*args, session=session, **kwargs)
           ^^^^^^^^^^^^^^^^^^^^^^^^^^^^^^^^^^^^^^
  File "/home/airflow/.local/lib/python3.12/site-packages/airflow/models/taskinstance.py", line 3005, in _run_raw_task
    return _run_raw_task(
           ^^^^^^^^^^^^^^
  File "/home/airflow/.local/lib/python3.12/site-packages/airflow/models/taskinstance.py", line 273, in _run_raw_task
    TaskInstance._execute_task_with_callbacks(
  File "/home/airflow/.local/lib/python3.12/site-packages/airflow/models/taskinstance.py", line 3159, in _execute_task_with_callbacks
    result = self._execute_task(context, task_orig)
             ^^^^^^^^^^^^^^^^^^^^^^^^^^^^^^^^^^^^^^
  File "/home/airflow/.local/lib/python3.12/site-packages/airflow/models/taskinstance.py", line 3183, in _execute_task
    return _execute_task(self, context, task_orig)
           ^^^^^^^^^^^^^^^^^^^^^^^^^^^^^^^^^^^^^^^
  File "/home/airflow/.local/lib/python3.12/site-packages/airflow/models/taskinstance.py", line 767, in _execute_task
    result = _execute_callable(context=context, **execute_callable_kwargs)
             ^^^^^^^^^^^^^^^^^^^^^^^^^^^^^^^^^^^^^^^^^^^^^^^^^^^^^^^^^^^^^
  File "/home/airflow/.local/lib/python3.12/site-packages/airflow/models/taskinstance.py", line 733, in _execute_callable
    return ExecutionCallableRunner(
           ^^^^^^^^^^^^^^^^^^^^^^^^
  File "/home/airflow/.local/lib/python3.12/site-packages/airflow/utils/operator_helpers.py", line 252, in run
    return self.func(*args, **kwargs)
           ^^^^^^^^^^^^^^^^^^^^^^^^^^
  File "/home/airflow/.local/lib/python3.12/site-packages/airflow/models/baseoperator.py", line 422, in wrapper
    return func(self, *args, **kwargs)
           ^^^^^^^^^^^^^^^^^^^^^^^^^^^
  File "/home/airflow/.local/lib/python3.12/site-packages/airflow/providers/common/sql/operators/sql.py", line 284, in execute
    output = hook.run(
             ^^^^^^^^^
  File "/home/airflow/.local/lib/python3.12/site-packages/airflow/providers/common/sql/hooks/sql.py", line 498, in run
    self._run_command(cur, sql_statement, parameters)
  File "/home/airflow/.local/lib/python3.12/site-packages/airflow/providers/common/sql/hooks/sql.py", line 558, in _run_command
    cur.execute(sql_statement)
psycopg2.errors.InsufficientPrivilege: permission denied for schema public
LINE 2:     CREATE TABLE IF NOT EXISTS ebooks (
                                       ^

[2025-01-26T09:13:10.268+0000] {local_task_job_runner.py:266} INFO - Task exited with return code 1
[2025-01-26T09:13:10.553+0000] {taskinstance.py:3895} INFO - 0 downstream tasks scheduled from follow-on schedule check
[2025-01-26T09:13:10.625+0000] {local_task_job_runner.py:245} INFO - ::endgroup::
[2025-01-26T09:31:15.337+0000] {local_task_job_runner.py:123} INFO - ::group::Pre task execution logs
[2025-01-26T09:31:15.586+0000] {taskinstance.py:2613} INFO - Dependencies all met for dep_context=non-requeueable deps ti=<TaskInstance: fetch_and_store_ebooks.create_table scheduled__2025-01-19T00:00:00+00:00 [queued]>
[2025-01-26T09:31:15.665+0000] {taskinstance.py:2613} INFO - Dependencies all met for dep_context=requeueable deps ti=<TaskInstance: fetch_and_store_ebooks.create_table scheduled__2025-01-19T00:00:00+00:00 [queued]>
[2025-01-26T09:31:15.682+0000] {taskinstance.py:2866} INFO - Starting attempt 1 of 2
[2025-01-26T09:31:15.821+0000] {taskinstance.py:2889} INFO - Executing <Task(PostgresOperator): create_table> on 2025-01-19 00:00:00+00:00
[2025-01-26T09:31:15.919+0000] {warnings.py:112} WARNING - /home/***/.local/lib/python3.12/site-packages/***/task/task_runner/standard_task_runner.py:70: DeprecationWarning: This process (pid=4603) is multi-threaded, use of fork() may lead to deadlocks in the child.
  pid = os.fork()

[2025-01-26T09:31:15.931+0000] {standard_task_runner.py:72} INFO - Started process 4630 to run task
[2025-01-26T09:31:15.943+0000] {standard_task_runner.py:104} INFO - Running: ['***', 'tasks', 'run', 'fetch_and_store_ebooks', 'create_table', 'scheduled__2025-01-19T00:00:00+00:00', '--job-id', '1117', '--raw', '--subdir', 'DAGS_FOLDER/app.py', '--cfg-path', '/tmp/tmpswqe8b61']
[2025-01-26T09:31:15.968+0000] {standard_task_runner.py:105} INFO - Job 1117: Subtask create_table
[2025-01-26T09:31:16.459+0000] {task_command.py:467} INFO - Running <TaskInstance: fetch_and_store_ebooks.create_table scheduled__2025-01-19T00:00:00+00:00 [running]> on host 34edd304782d
[2025-01-26T09:31:17.744+0000] {taskinstance.py:3132} INFO - Exporting env vars: AIRFLOW_CTX_DAG_OWNER='***' AIRFLOW_CTX_DAG_ID='fetch_and_store_ebooks' AIRFLOW_CTX_TASK_ID='create_table' AIRFLOW_CTX_EXECUTION_DATE='2025-01-19T00:00:00+00:00' AIRFLOW_CTX_TRY_NUMBER='1' AIRFLOW_CTX_DAG_RUN_ID='scheduled__2025-01-19T00:00:00+00:00'
[2025-01-26T09:31:17.751+0000] {logging_mixin.py:190} INFO - Task instance is in running state
[2025-01-26T09:31:17.753+0000] {logging_mixin.py:190} INFO -  Previous state of the Task instance: queued
[2025-01-26T09:31:17.756+0000] {logging_mixin.py:190} INFO - Current task name:create_table state:running start_date:2025-01-26 09:31:15.588886+00:00
[2025-01-26T09:31:17.766+0000] {logging_mixin.py:190} INFO - Dag name:fetch_and_store_ebooks and current dag run status:running
[2025-01-26T09:31:17.780+0000] {taskinstance.py:731} INFO - ::endgroup::
[2025-01-26T09:31:17.793+0000] {sql.py:278} INFO - Executing: 
    CREATE TABLE IF NOT EXISTS public.ebooks (
        id SERIAL PRIMARY KEY,
        judul TEXT NOT NULL,
        penulis TEXT,
        link TEXT
    );
    
[2025-01-26T09:31:17.857+0000] {base.py:84} INFO - Retrieving connection 'ebooks_connection'
[2025-01-26T09:31:17.913+0000] {base.py:84} INFO - Retrieving connection 'ebooks_connection'
[2025-01-26T09:31:18.630+0000] {sql.py:553} INFO - Running statement: 
    CREATE TABLE IF NOT EXISTS public.ebooks (
        id SERIAL PRIMARY KEY,
        judul TEXT NOT NULL,
        penulis TEXT,
        link TEXT
    );
    , parameters: None
[2025-01-26T09:31:18.790+0000] {taskinstance.py:340} INFO - ::group::Post task execution logs
[2025-01-26T09:31:18.793+0000] {taskinstance.py:352} INFO - Marking task as SUCCESS. dag_id=fetch_and_store_ebooks, task_id=create_table, run_id=scheduled__2025-01-19T00:00:00+00:00, execution_date=20250119T000000, start_date=20250126T093115, end_date=20250126T093118
[2025-01-26T09:31:18.995+0000] {logging_mixin.py:190} INFO - Task instance in success state
[2025-01-26T09:31:19.014+0000] {logging_mixin.py:190} INFO -  Previous state of the Task instance: running
[2025-01-26T09:31:19.073+0000] {logging_mixin.py:190} INFO - Dag name:fetch_and_store_ebooks queued_at:2025-01-26 09:30:12.853882+00:00
[2025-01-26T09:31:19.095+0000] {logging_mixin.py:190} INFO - Task hostname:34edd304782d operator:PostgresOperator
[2025-01-26T09:31:19.354+0000] {local_task_job_runner.py:266} INFO - Task exited with return code 0
[2025-01-26T09:31:19.579+0000] {taskinstance.py:3895} INFO - 1 downstream tasks scheduled from follow-on schedule check
[2025-01-26T09:31:19.613+0000] {local_task_job_runner.py:245} INFO - ::endgroup::
