[2025-01-25T17:15:46.375+0000] {local_task_job_runner.py:123} INFO - ::group::Pre task execution logs
[2025-01-25T17:15:46.464+0000] {taskinstance.py:2613} INFO - Dependencies all met for dep_context=non-requeueable deps ti=<TaskInstance: fetch_and_store_ebooks.create_table scheduled__2025-01-17T00:00:00+00:00 [queued]>
[2025-01-25T17:15:46.506+0000] {taskinstance.py:2613} INFO - Dependencies all met for dep_context=requeueable deps ti=<TaskInstance: fetch_and_store_ebooks.create_table scheduled__2025-01-17T00:00:00+00:00 [queued]>
[2025-01-25T17:15:46.509+0000] {taskinstance.py:2866} INFO - Starting attempt 2 of 2
[2025-01-25T17:15:46.565+0000] {taskinstance.py:2889} INFO - Executing <Task(PostgresOperator): create_table> on 2025-01-17 00:00:00+00:00
[2025-01-25T17:15:46.582+0000] {warnings.py:112} WARNING - /home/***/.local/lib/python3.12/site-packages/***/task/task_runner/standard_task_runner.py:70: DeprecationWarning: This process (pid=4091) is multi-threaded, use of fork() may lead to deadlocks in the child.
  pid = os.fork()

[2025-01-25T17:15:46.587+0000] {standard_task_runner.py:72} INFO - Started process 4093 to run task
[2025-01-25T17:15:46.591+0000] {standard_task_runner.py:104} INFO - Running: ['***', 'tasks', 'run', 'fetch_and_store_ebooks', 'create_table', 'scheduled__2025-01-17T00:00:00+00:00', '--job-id', '506', '--raw', '--subdir', 'DAGS_FOLDER/app.py', '--cfg-path', '/tmp/tmp2xqj9mu2']
[2025-01-25T17:15:46.596+0000] {standard_task_runner.py:105} INFO - Job 506: Subtask create_table
[2025-01-25T17:15:47.586+0000] {task_command.py:467} INFO - Running <TaskInstance: fetch_and_store_ebooks.create_table scheduled__2025-01-17T00:00:00+00:00 [running]> on host 50ab235b552a
[2025-01-25T17:15:48.028+0000] {taskinstance.py:3132} INFO - Exporting env vars: AIRFLOW_CTX_DAG_OWNER='***' AIRFLOW_CTX_DAG_ID='fetch_and_store_ebooks' AIRFLOW_CTX_TASK_ID='create_table' AIRFLOW_CTX_EXECUTION_DATE='2025-01-17T00:00:00+00:00' AIRFLOW_CTX_TRY_NUMBER='2' AIRFLOW_CTX_DAG_RUN_ID='scheduled__2025-01-17T00:00:00+00:00'
[2025-01-25T17:15:48.033+0000] {logging_mixin.py:190} INFO - Task instance is in running state
[2025-01-25T17:15:48.036+0000] {logging_mixin.py:190} INFO -  Previous state of the Task instance: queued
[2025-01-25T17:15:48.038+0000] {logging_mixin.py:190} INFO - Current task name:create_table state:running start_date:2025-01-25 17:15:46.466872+00:00
[2025-01-25T17:15:48.040+0000] {logging_mixin.py:190} INFO - Dag name:fetch_and_store_ebooks and current dag run status:running
[2025-01-25T17:15:48.043+0000] {taskinstance.py:731} INFO - ::endgroup::
[2025-01-25T17:15:48.045+0000] {sql.py:278} INFO - Executing: 
    CREATE TABLE IF NOT EXISTS ebooks (
        id SERIAL PRIMARY KEY,
        judul TEXT NOT NULL,
        penulis TEXT,
        link TEXT
    );
    
[2025-01-25T17:15:48.087+0000] {base.py:84} INFO - Retrieving connection 'ebooks_connection'
[2025-01-25T17:15:48.121+0000] {base.py:84} INFO - Retrieving connection 'ebooks_connection'
[2025-01-25T17:15:48.126+0000] {taskinstance.py:3311} ERROR - Task failed with exception
Traceback (most recent call last):
  File "/home/airflow/.local/lib/python3.12/site-packages/airflow/models/taskinstance.py", line 767, in _execute_task
    result = _execute_callable(context=context, **execute_callable_kwargs)
             ^^^^^^^^^^^^^^^^^^^^^^^^^^^^^^^^^^^^^^^^^^^^^^^^^^^^^^^^^^^^^
  File "/home/airflow/.local/lib/python3.12/site-packages/airflow/models/taskinstance.py", line 733, in _execute_callable
    return ExecutionCallableRunner(
           ^^^^^^^^^^^^^^^^^^^^^^^^
  File "/home/airflow/.local/lib/python3.12/site-packages/airflow/utils/operator_helpers.py", line 252, in run
    return self.func(*args, **kwargs)
           ^^^^^^^^^^^^^^^^^^^^^^^^^^
  File "/home/airflow/.local/lib/python3.12/site-packages/airflow/models/baseoperator.py", line 422, in wrapper
    return func(self, *args, **kwargs)
           ^^^^^^^^^^^^^^^^^^^^^^^^^^^
  File "/home/airflow/.local/lib/python3.12/site-packages/airflow/providers/common/sql/operators/sql.py", line 284, in execute
    output = hook.run(
             ^^^^^^^^^
  File "/home/airflow/.local/lib/python3.12/site-packages/airflow/providers/common/sql/hooks/sql.py", line 494, in run
    with self._create_autocommit_connection(autocommit) as conn:
         ^^^^^^^^^^^^^^^^^^^^^^^^^^^^^^^^^^^^^^^^^^^^^^
  File "/usr/local/lib/python3.12/contextlib.py", line 137, in __enter__
    return next(self.gen)
           ^^^^^^^^^^^^^^
  File "/home/airflow/.local/lib/python3.12/site-packages/airflow/providers/common/sql/hooks/sql.py", line 618, in _create_autocommit_connection
    with closing(self.get_conn()) as conn:
                 ^^^^^^^^^^^^^^^
  File "/home/airflow/.local/lib/python3.12/site-packages/airflow/providers/postgres/hooks/postgres.py", line 189, in get_conn
    self.conn = psycopg2.connect(**conn_args)
                ^^^^^^^^^^^^^^^^^^^^^^^^^^^^^
  File "/home/airflow/.local/lib/python3.12/site-packages/psycopg2/__init__.py", line 122, in connect
    conn = _connect(dsn, connection_factory=connection_factory, **kwasync)
           ^^^^^^^^^^^^^^^^^^^^^^^^^^^^^^^^^^^^^^^^^^^^^^^^^^^^^^^^^^^^^^^
psycopg2.OperationalError: connection to server at "localhost" (::1), port 5432 failed: Connection refused
	Is the server running on that host and accepting TCP/IP connections?
connection to server at "localhost" (127.0.0.1), port 5432 failed: Connection refused
	Is the server running on that host and accepting TCP/IP connections?

[2025-01-25T17:15:48.173+0000] {logging_mixin.py:190} INFO - Task instance in failure state
[2025-01-25T17:15:48.176+0000] {logging_mixin.py:190} INFO - Task start:2025-01-25 17:15:46.466872+00:00 end:2025-01-25 17:15:48.172039+00:00 duration:1.705167
[2025-01-25T17:15:48.178+0000] {logging_mixin.py:190} INFO - Task:<Task(PostgresOperator): create_table> dag:<DAG: fetch_and_store_ebooks> dagrun:<DagRun fetch_and_store_ebooks @ 2025-01-17 00:00:00+00:00: scheduled__2025-01-17T00:00:00+00:00, state:running, queued_at: 2025-01-25 17:09:17.858192+00:00. externally triggered: False>
[2025-01-25T17:15:48.181+0000] {logging_mixin.py:190} INFO - Failure caused by connection to server at "localhost" (::1), port 5432 failed: Connection refused
	Is the server running on that host and accepting TCP/IP connections?
connection to server at "localhost" (127.0.0.1), port 5432 failed: Connection refused
	Is the server running on that host and accepting TCP/IP connections?
[2025-01-25T17:15:48.183+0000] {taskinstance.py:1225} INFO - Marking task as FAILED. dag_id=fetch_and_store_ebooks, task_id=create_table, run_id=scheduled__2025-01-17T00:00:00+00:00, execution_date=20250117T000000, start_date=20250125T171546, end_date=20250125T171548
[2025-01-25T17:15:48.234+0000] {taskinstance.py:340} INFO - ::group::Post task execution logs
[2025-01-25T17:15:48.236+0000] {standard_task_runner.py:124} ERROR - Failed to execute job 506 for task create_table (connection to server at "localhost" (::1), port 5432 failed: Connection refused
	Is the server running on that host and accepting TCP/IP connections?
connection to server at "localhost" (127.0.0.1), port 5432 failed: Connection refused
	Is the server running on that host and accepting TCP/IP connections?
; 4093)
Traceback (most recent call last):
  File "/home/airflow/.local/lib/python3.12/site-packages/airflow/task/task_runner/standard_task_runner.py", line 117, in _start_by_fork
    ret = args.func(args, dag=self.dag)
          ^^^^^^^^^^^^^^^^^^^^^^^^^^^^^
  File "/home/airflow/.local/lib/python3.12/site-packages/airflow/cli/cli_config.py", line 49, in command
    return func(*args, **kwargs)
           ^^^^^^^^^^^^^^^^^^^^^
  File "/home/airflow/.local/lib/python3.12/site-packages/airflow/utils/cli.py", line 116, in wrapper
    return f(*args, **kwargs)
           ^^^^^^^^^^^^^^^^^^
  File "/home/airflow/.local/lib/python3.12/site-packages/airflow/cli/commands/task_command.py", line 483, in task_run
    task_return_code = _run_task_by_selected_method(args, _dag, ti)
                       ^^^^^^^^^^^^^^^^^^^^^^^^^^^^^^^^^^^^^^^^^^^^
  File "/home/airflow/.local/lib/python3.12/site-packages/airflow/cli/commands/task_command.py", line 256, in _run_task_by_selected_method
    return _run_raw_task(args, ti)
           ^^^^^^^^^^^^^^^^^^^^^^^
  File "/home/airflow/.local/lib/python3.12/site-packages/airflow/cli/commands/task_command.py", line 341, in _run_raw_task
    return ti._run_raw_task(
           ^^^^^^^^^^^^^^^^^
  File "/home/airflow/.local/lib/python3.12/site-packages/airflow/utils/session.py", line 97, in wrapper
    return func(*args, session=session, **kwargs)
           ^^^^^^^^^^^^^^^^^^^^^^^^^^^^^^^^^^^^^^
  File "/home/airflow/.local/lib/python3.12/site-packages/airflow/models/taskinstance.py", line 3005, in _run_raw_task
    return _run_raw_task(
           ^^^^^^^^^^^^^^
  File "/home/airflow/.local/lib/python3.12/site-packages/airflow/models/taskinstance.py", line 273, in _run_raw_task
    TaskInstance._execute_task_with_callbacks(
  File "/home/airflow/.local/lib/python3.12/site-packages/airflow/models/taskinstance.py", line 3159, in _execute_task_with_callbacks
    result = self._execute_task(context, task_orig)
             ^^^^^^^^^^^^^^^^^^^^^^^^^^^^^^^^^^^^^^
  File "/home/airflow/.local/lib/python3.12/site-packages/airflow/models/taskinstance.py", line 3183, in _execute_task
    return _execute_task(self, context, task_orig)
           ^^^^^^^^^^^^^^^^^^^^^^^^^^^^^^^^^^^^^^^
  File "/home/airflow/.local/lib/python3.12/site-packages/airflow/models/taskinstance.py", line 767, in _execute_task
    result = _execute_callable(context=context, **execute_callable_kwargs)
             ^^^^^^^^^^^^^^^^^^^^^^^^^^^^^^^^^^^^^^^^^^^^^^^^^^^^^^^^^^^^^
  File "/home/airflow/.local/lib/python3.12/site-packages/airflow/models/taskinstance.py", line 733, in _execute_callable
    return ExecutionCallableRunner(
           ^^^^^^^^^^^^^^^^^^^^^^^^
  File "/home/airflow/.local/lib/python3.12/site-packages/airflow/utils/operator_helpers.py", line 252, in run
    return self.func(*args, **kwargs)
           ^^^^^^^^^^^^^^^^^^^^^^^^^^
  File "/home/airflow/.local/lib/python3.12/site-packages/airflow/models/baseoperator.py", line 422, in wrapper
    return func(self, *args, **kwargs)
           ^^^^^^^^^^^^^^^^^^^^^^^^^^^
  File "/home/airflow/.local/lib/python3.12/site-packages/airflow/providers/common/sql/operators/sql.py", line 284, in execute
    output = hook.run(
             ^^^^^^^^^
  File "/home/airflow/.local/lib/python3.12/site-packages/airflow/providers/common/sql/hooks/sql.py", line 494, in run
    with self._create_autocommit_connection(autocommit) as conn:
         ^^^^^^^^^^^^^^^^^^^^^^^^^^^^^^^^^^^^^^^^^^^^^^
  File "/usr/local/lib/python3.12/contextlib.py", line 137, in __enter__
    return next(self.gen)
           ^^^^^^^^^^^^^^
  File "/home/airflow/.local/lib/python3.12/site-packages/airflow/providers/common/sql/hooks/sql.py", line 618, in _create_autocommit_connection
    with closing(self.get_conn()) as conn:
                 ^^^^^^^^^^^^^^^
  File "/home/airflow/.local/lib/python3.12/site-packages/airflow/providers/postgres/hooks/postgres.py", line 189, in get_conn
    self.conn = psycopg2.connect(**conn_args)
                ^^^^^^^^^^^^^^^^^^^^^^^^^^^^^
  File "/home/airflow/.local/lib/python3.12/site-packages/psycopg2/__init__.py", line 122, in connect
    conn = _connect(dsn, connection_factory=connection_factory, **kwasync)
           ^^^^^^^^^^^^^^^^^^^^^^^^^^^^^^^^^^^^^^^^^^^^^^^^^^^^^^^^^^^^^^^
psycopg2.OperationalError: connection to server at "localhost" (::1), port 5432 failed: Connection refused
	Is the server running on that host and accepting TCP/IP connections?
connection to server at "localhost" (127.0.0.1), port 5432 failed: Connection refused
	Is the server running on that host and accepting TCP/IP connections?

[2025-01-25T17:15:48.321+0000] {local_task_job_runner.py:266} INFO - Task exited with return code 1
[2025-01-25T17:15:49.030+0000] {taskinstance.py:3895} INFO - 0 downstream tasks scheduled from follow-on schedule check
[2025-01-25T17:15:49.046+0000] {local_task_job_runner.py:245} INFO - ::endgroup::
[2025-01-26T06:46:21.671+0000] {local_task_job_runner.py:123} INFO - ::group::Pre task execution logs
[2025-01-26T06:46:21.798+0000] {taskinstance.py:2613} INFO - Dependencies all met for dep_context=non-requeueable deps ti=<TaskInstance: fetch_and_store_ebooks.create_table scheduled__2025-01-17T00:00:00+00:00 [queued]>
[2025-01-26T06:46:21.840+0000] {taskinstance.py:2613} INFO - Dependencies all met for dep_context=requeueable deps ti=<TaskInstance: fetch_and_store_ebooks.create_table scheduled__2025-01-17T00:00:00+00:00 [queued]>
[2025-01-26T06:46:21.842+0000] {taskinstance.py:2866} INFO - Starting attempt 2 of 2
[2025-01-26T06:46:22.360+0000] {taskinstance.py:2889} INFO - Executing <Task(PostgresOperator): create_table> on 2025-01-17 00:00:00+00:00
[2025-01-26T06:46:22.451+0000] {warnings.py:112} WARNING - /home/***/.local/lib/python3.12/site-packages/***/task/task_runner/standard_task_runner.py:70: DeprecationWarning: This process (pid=776) is multi-threaded, use of fork() may lead to deadlocks in the child.
  pid = os.fork()

[2025-01-26T06:46:22.457+0000] {standard_task_runner.py:104} INFO - Running: ['***', 'tasks', 'run', 'fetch_and_store_ebooks', 'create_table', 'scheduled__2025-01-17T00:00:00+00:00', '--job-id', '602', '--raw', '--subdir', 'DAGS_FOLDER/app.py', '--cfg-path', '/tmp/tmphwz8r17g']
[2025-01-26T06:46:22.491+0000] {standard_task_runner.py:72} INFO - Started process 790 to run task
[2025-01-26T06:46:22.493+0000] {standard_task_runner.py:105} INFO - Job 602: Subtask create_table
[2025-01-26T06:46:22.890+0000] {task_command.py:467} INFO - Running <TaskInstance: fetch_and_store_ebooks.create_table scheduled__2025-01-17T00:00:00+00:00 [running]> on host 34edd304782d
[2025-01-26T06:46:23.446+0000] {taskinstance.py:3132} INFO - Exporting env vars: AIRFLOW_CTX_DAG_OWNER='***' AIRFLOW_CTX_DAG_ID='fetch_and_store_ebooks' AIRFLOW_CTX_TASK_ID='create_table' AIRFLOW_CTX_EXECUTION_DATE='2025-01-17T00:00:00+00:00' AIRFLOW_CTX_TRY_NUMBER='2' AIRFLOW_CTX_DAG_RUN_ID='scheduled__2025-01-17T00:00:00+00:00'
[2025-01-26T06:46:23.481+0000] {logging_mixin.py:190} INFO - Task instance is in running state
[2025-01-26T06:46:23.487+0000] {logging_mixin.py:190} INFO -  Previous state of the Task instance: queued
[2025-01-26T06:46:23.507+0000] {logging_mixin.py:190} INFO - Current task name:create_table state:running start_date:2025-01-26 06:46:21.802866+00:00
[2025-01-26T06:46:23.509+0000] {logging_mixin.py:190} INFO - Dag name:fetch_and_store_ebooks and current dag run status:running
[2025-01-26T06:46:23.511+0000] {taskinstance.py:731} INFO - ::endgroup::
[2025-01-26T06:46:23.513+0000] {sql.py:278} INFO - Executing: 
    CREATE TABLE IF NOT EXISTS ebooks (
        id SERIAL PRIMARY KEY,
        judul TEXT NOT NULL,
        penulis TEXT,
        link TEXT
    );
    
[2025-01-26T06:46:23.582+0000] {base.py:84} INFO - Retrieving connection 'ebooks_connection'
[2025-01-26T06:46:23.658+0000] {base.py:84} INFO - Retrieving connection 'ebooks_connection'
[2025-01-26T06:46:23.893+0000] {sql.py:553} INFO - Running statement: 
    CREATE TABLE IF NOT EXISTS ebooks (
        id SERIAL PRIMARY KEY,
        judul TEXT NOT NULL,
        penulis TEXT,
        link TEXT
    );
    , parameters: None
[2025-01-26T06:46:23.905+0000] {taskinstance.py:3311} ERROR - Task failed with exception
Traceback (most recent call last):
  File "/home/airflow/.local/lib/python3.12/site-packages/airflow/models/taskinstance.py", line 767, in _execute_task
    result = _execute_callable(context=context, **execute_callable_kwargs)
             ^^^^^^^^^^^^^^^^^^^^^^^^^^^^^^^^^^^^^^^^^^^^^^^^^^^^^^^^^^^^^
  File "/home/airflow/.local/lib/python3.12/site-packages/airflow/models/taskinstance.py", line 733, in _execute_callable
    return ExecutionCallableRunner(
           ^^^^^^^^^^^^^^^^^^^^^^^^
  File "/home/airflow/.local/lib/python3.12/site-packages/airflow/utils/operator_helpers.py", line 252, in run
    return self.func(*args, **kwargs)
           ^^^^^^^^^^^^^^^^^^^^^^^^^^
  File "/home/airflow/.local/lib/python3.12/site-packages/airflow/models/baseoperator.py", line 422, in wrapper
    return func(self, *args, **kwargs)
           ^^^^^^^^^^^^^^^^^^^^^^^^^^^
  File "/home/airflow/.local/lib/python3.12/site-packages/airflow/providers/common/sql/operators/sql.py", line 284, in execute
    output = hook.run(
             ^^^^^^^^^
  File "/home/airflow/.local/lib/python3.12/site-packages/airflow/providers/common/sql/hooks/sql.py", line 498, in run
    self._run_command(cur, sql_statement, parameters)
  File "/home/airflow/.local/lib/python3.12/site-packages/airflow/providers/common/sql/hooks/sql.py", line 558, in _run_command
    cur.execute(sql_statement)
psycopg2.errors.InsufficientPrivilege: permission denied for schema public
LINE 2:     CREATE TABLE IF NOT EXISTS ebooks (
                                       ^

[2025-01-26T06:46:24.023+0000] {logging_mixin.py:190} INFO - Task instance in failure state
[2025-01-26T06:46:24.025+0000] {logging_mixin.py:190} INFO - Task start:2025-01-26 06:46:21.802866+00:00 end:2025-01-26 06:46:24.021370+00:00 duration:2.218504
[2025-01-26T06:46:24.027+0000] {logging_mixin.py:190} INFO - Task:<Task(PostgresOperator): create_table> dag:<DAG: fetch_and_store_ebooks> dagrun:<DagRun fetch_and_store_ebooks @ 2025-01-17 00:00:00+00:00: scheduled__2025-01-17T00:00:00+00:00, state:running, queued_at: 2025-01-26 06:40:09.487530+00:00. externally triggered: False>
[2025-01-26T06:46:24.049+0000] {logging_mixin.py:190} INFO - Failure caused by permission denied for schema public
LINE 2:     CREATE TABLE IF NOT EXISTS ebooks (
                                       ^
[2025-01-26T06:46:24.062+0000] {taskinstance.py:1225} INFO - Marking task as FAILED. dag_id=fetch_and_store_ebooks, task_id=create_table, run_id=scheduled__2025-01-17T00:00:00+00:00, execution_date=20250117T000000, start_date=20250126T064621, end_date=20250126T064624
[2025-01-26T06:46:24.541+0000] {taskinstance.py:340} INFO - ::group::Post task execution logs
[2025-01-26T06:46:24.545+0000] {standard_task_runner.py:124} ERROR - Failed to execute job 602 for task create_table (permission denied for schema public
LINE 2:     CREATE TABLE IF NOT EXISTS ebooks (
                                       ^
; 790)
Traceback (most recent call last):
  File "/home/airflow/.local/lib/python3.12/site-packages/airflow/task/task_runner/standard_task_runner.py", line 117, in _start_by_fork
    ret = args.func(args, dag=self.dag)
          ^^^^^^^^^^^^^^^^^^^^^^^^^^^^^
  File "/home/airflow/.local/lib/python3.12/site-packages/airflow/cli/cli_config.py", line 49, in command
    return func(*args, **kwargs)
           ^^^^^^^^^^^^^^^^^^^^^
  File "/home/airflow/.local/lib/python3.12/site-packages/airflow/utils/cli.py", line 116, in wrapper
    return f(*args, **kwargs)
           ^^^^^^^^^^^^^^^^^^
  File "/home/airflow/.local/lib/python3.12/site-packages/airflow/cli/commands/task_command.py", line 483, in task_run
    task_return_code = _run_task_by_selected_method(args, _dag, ti)
                       ^^^^^^^^^^^^^^^^^^^^^^^^^^^^^^^^^^^^^^^^^^^^
  File "/home/airflow/.local/lib/python3.12/site-packages/airflow/cli/commands/task_command.py", line 256, in _run_task_by_selected_method
    return _run_raw_task(args, ti)
           ^^^^^^^^^^^^^^^^^^^^^^^
  File "/home/airflow/.local/lib/python3.12/site-packages/airflow/cli/commands/task_command.py", line 341, in _run_raw_task
    return ti._run_raw_task(
           ^^^^^^^^^^^^^^^^^
  File "/home/airflow/.local/lib/python3.12/site-packages/airflow/utils/session.py", line 97, in wrapper
    return func(*args, session=session, **kwargs)
           ^^^^^^^^^^^^^^^^^^^^^^^^^^^^^^^^^^^^^^
  File "/home/airflow/.local/lib/python3.12/site-packages/airflow/models/taskinstance.py", line 3005, in _run_raw_task
    return _run_raw_task(
           ^^^^^^^^^^^^^^
  File "/home/airflow/.local/lib/python3.12/site-packages/airflow/models/taskinstance.py", line 273, in _run_raw_task
    TaskInstance._execute_task_with_callbacks(
  File "/home/airflow/.local/lib/python3.12/site-packages/airflow/models/taskinstance.py", line 3159, in _execute_task_with_callbacks
    result = self._execute_task(context, task_orig)
             ^^^^^^^^^^^^^^^^^^^^^^^^^^^^^^^^^^^^^^
  File "/home/airflow/.local/lib/python3.12/site-packages/airflow/models/taskinstance.py", line 3183, in _execute_task
    return _execute_task(self, context, task_orig)
           ^^^^^^^^^^^^^^^^^^^^^^^^^^^^^^^^^^^^^^^
  File "/home/airflow/.local/lib/python3.12/site-packages/airflow/models/taskinstance.py", line 767, in _execute_task
    result = _execute_callable(context=context, **execute_callable_kwargs)
             ^^^^^^^^^^^^^^^^^^^^^^^^^^^^^^^^^^^^^^^^^^^^^^^^^^^^^^^^^^^^^
  File "/home/airflow/.local/lib/python3.12/site-packages/airflow/models/taskinstance.py", line 733, in _execute_callable
    return ExecutionCallableRunner(
           ^^^^^^^^^^^^^^^^^^^^^^^^
  File "/home/airflow/.local/lib/python3.12/site-packages/airflow/utils/operator_helpers.py", line 252, in run
    return self.func(*args, **kwargs)
           ^^^^^^^^^^^^^^^^^^^^^^^^^^
  File "/home/airflow/.local/lib/python3.12/site-packages/airflow/models/baseoperator.py", line 422, in wrapper
    return func(self, *args, **kwargs)
           ^^^^^^^^^^^^^^^^^^^^^^^^^^^
  File "/home/airflow/.local/lib/python3.12/site-packages/airflow/providers/common/sql/operators/sql.py", line 284, in execute
    output = hook.run(
             ^^^^^^^^^
  File "/home/airflow/.local/lib/python3.12/site-packages/airflow/providers/common/sql/hooks/sql.py", line 498, in run
    self._run_command(cur, sql_statement, parameters)
  File "/home/airflow/.local/lib/python3.12/site-packages/airflow/providers/common/sql/hooks/sql.py", line 558, in _run_command
    cur.execute(sql_statement)
psycopg2.errors.InsufficientPrivilege: permission denied for schema public
LINE 2:     CREATE TABLE IF NOT EXISTS ebooks (
                                       ^

[2025-01-26T06:46:24.698+0000] {local_task_job_runner.py:266} INFO - Task exited with return code 1
[2025-01-26T06:46:24.832+0000] {taskinstance.py:3895} INFO - 0 downstream tasks scheduled from follow-on schedule check
[2025-01-26T06:46:24.869+0000] {local_task_job_runner.py:245} INFO - ::endgroup::
[2025-01-26T07:35:21.298+0000] {local_task_job_runner.py:123} INFO - ::group::Pre task execution logs
[2025-01-26T07:35:21.483+0000] {taskinstance.py:2613} INFO - Dependencies all met for dep_context=non-requeueable deps ti=<TaskInstance: fetch_and_store_ebooks.create_table scheduled__2025-01-17T00:00:00+00:00 [queued]>
[2025-01-26T07:35:21.555+0000] {taskinstance.py:2613} INFO - Dependencies all met for dep_context=requeueable deps ti=<TaskInstance: fetch_and_store_ebooks.create_table scheduled__2025-01-17T00:00:00+00:00 [queued]>
[2025-01-26T07:35:21.559+0000] {taskinstance.py:2866} INFO - Starting attempt 2 of 2
[2025-01-26T07:35:22.130+0000] {taskinstance.py:2889} INFO - Executing <Task(PostgresOperator): create_table> on 2025-01-17 00:00:00+00:00
[2025-01-26T07:35:22.183+0000] {warnings.py:112} WARNING - /home/***/.local/lib/python3.12/site-packages/***/task/task_runner/standard_task_runner.py:70: DeprecationWarning: This process (pid=1626) is multi-threaded, use of fork() may lead to deadlocks in the child.
  pid = os.fork()

[2025-01-26T07:35:22.198+0000] {standard_task_runner.py:72} INFO - Started process 1655 to run task
[2025-01-26T07:35:22.199+0000] {standard_task_runner.py:104} INFO - Running: ['***', 'tasks', 'run', 'fetch_and_store_ebooks', 'create_table', 'scheduled__2025-01-17T00:00:00+00:00', '--job-id', '691', '--raw', '--subdir', 'DAGS_FOLDER/app.py', '--cfg-path', '/tmp/tmpworfnnen']
[2025-01-26T07:35:22.213+0000] {standard_task_runner.py:105} INFO - Job 691: Subtask create_table
[2025-01-26T07:35:22.564+0000] {task_command.py:467} INFO - Running <TaskInstance: fetch_and_store_ebooks.create_table scheduled__2025-01-17T00:00:00+00:00 [running]> on host 34edd304782d
[2025-01-26T07:35:23.117+0000] {taskinstance.py:3132} INFO - Exporting env vars: AIRFLOW_CTX_DAG_OWNER='***' AIRFLOW_CTX_DAG_ID='fetch_and_store_ebooks' AIRFLOW_CTX_TASK_ID='create_table' AIRFLOW_CTX_EXECUTION_DATE='2025-01-17T00:00:00+00:00' AIRFLOW_CTX_TRY_NUMBER='2' AIRFLOW_CTX_DAG_RUN_ID='scheduled__2025-01-17T00:00:00+00:00'
[2025-01-26T07:35:23.125+0000] {logging_mixin.py:190} INFO - Task instance is in running state
[2025-01-26T07:35:23.139+0000] {logging_mixin.py:190} INFO -  Previous state of the Task instance: queued
[2025-01-26T07:35:23.153+0000] {logging_mixin.py:190} INFO - Current task name:create_table state:running start_date:2025-01-26 07:35:21.488382+00:00
[2025-01-26T07:35:23.157+0000] {logging_mixin.py:190} INFO - Dag name:fetch_and_store_ebooks and current dag run status:running
[2025-01-26T07:35:23.165+0000] {taskinstance.py:731} INFO - ::endgroup::
[2025-01-26T07:35:23.176+0000] {sql.py:278} INFO - Executing: 
    CREATE TABLE IF NOT EXISTS ebooks (
        id SERIAL PRIMARY KEY,
        judul TEXT NOT NULL,
        penulis TEXT,
        link TEXT
    );
    
[2025-01-26T07:35:23.225+0000] {base.py:84} INFO - Retrieving connection 'ebooks_connection'
[2025-01-26T07:35:23.258+0000] {base.py:84} INFO - Retrieving connection 'ebooks_connection'
[2025-01-26T07:35:23.441+0000] {sql.py:553} INFO - Running statement: 
    CREATE TABLE IF NOT EXISTS ebooks (
        id SERIAL PRIMARY KEY,
        judul TEXT NOT NULL,
        penulis TEXT,
        link TEXT
    );
    , parameters: None
[2025-01-26T07:35:23.453+0000] {taskinstance.py:3311} ERROR - Task failed with exception
Traceback (most recent call last):
  File "/home/airflow/.local/lib/python3.12/site-packages/airflow/models/taskinstance.py", line 767, in _execute_task
    result = _execute_callable(context=context, **execute_callable_kwargs)
             ^^^^^^^^^^^^^^^^^^^^^^^^^^^^^^^^^^^^^^^^^^^^^^^^^^^^^^^^^^^^^
  File "/home/airflow/.local/lib/python3.12/site-packages/airflow/models/taskinstance.py", line 733, in _execute_callable
    return ExecutionCallableRunner(
           ^^^^^^^^^^^^^^^^^^^^^^^^
  File "/home/airflow/.local/lib/python3.12/site-packages/airflow/utils/operator_helpers.py", line 252, in run
    return self.func(*args, **kwargs)
           ^^^^^^^^^^^^^^^^^^^^^^^^^^
  File "/home/airflow/.local/lib/python3.12/site-packages/airflow/models/baseoperator.py", line 422, in wrapper
    return func(self, *args, **kwargs)
           ^^^^^^^^^^^^^^^^^^^^^^^^^^^
  File "/home/airflow/.local/lib/python3.12/site-packages/airflow/providers/common/sql/operators/sql.py", line 284, in execute
    output = hook.run(
             ^^^^^^^^^
  File "/home/airflow/.local/lib/python3.12/site-packages/airflow/providers/common/sql/hooks/sql.py", line 498, in run
    self._run_command(cur, sql_statement, parameters)
  File "/home/airflow/.local/lib/python3.12/site-packages/airflow/providers/common/sql/hooks/sql.py", line 558, in _run_command
    cur.execute(sql_statement)
psycopg2.errors.InsufficientPrivilege: permission denied for schema public
LINE 2:     CREATE TABLE IF NOT EXISTS ebooks (
                                       ^

[2025-01-26T07:35:23.491+0000] {logging_mixin.py:190} INFO - Task instance in failure state
[2025-01-26T07:35:23.495+0000] {logging_mixin.py:190} INFO - Task start:2025-01-26 07:35:21.488382+00:00 end:2025-01-26 07:35:23.489480+00:00 duration:2.001098
[2025-01-26T07:35:23.498+0000] {logging_mixin.py:190} INFO - Task:<Task(PostgresOperator): create_table> dag:<DAG: fetch_and_store_ebooks> dagrun:<DagRun fetch_and_store_ebooks @ 2025-01-17 00:00:00+00:00: scheduled__2025-01-17T00:00:00+00:00, state:running, queued_at: 2025-01-26 07:28:34.562110+00:00. externally triggered: False>
[2025-01-26T07:35:23.500+0000] {logging_mixin.py:190} INFO - Failure caused by permission denied for schema public
LINE 2:     CREATE TABLE IF NOT EXISTS ebooks (
                                       ^
[2025-01-26T07:35:23.502+0000] {taskinstance.py:1225} INFO - Marking task as FAILED. dag_id=fetch_and_store_ebooks, task_id=create_table, run_id=scheduled__2025-01-17T00:00:00+00:00, execution_date=20250117T000000, start_date=20250126T073521, end_date=20250126T073523
[2025-01-26T07:35:23.576+0000] {taskinstance.py:340} INFO - ::group::Post task execution logs
[2025-01-26T07:35:23.578+0000] {standard_task_runner.py:124} ERROR - Failed to execute job 691 for task create_table (permission denied for schema public
LINE 2:     CREATE TABLE IF NOT EXISTS ebooks (
                                       ^
; 1655)
Traceback (most recent call last):
  File "/home/airflow/.local/lib/python3.12/site-packages/airflow/task/task_runner/standard_task_runner.py", line 117, in _start_by_fork
    ret = args.func(args, dag=self.dag)
          ^^^^^^^^^^^^^^^^^^^^^^^^^^^^^
  File "/home/airflow/.local/lib/python3.12/site-packages/airflow/cli/cli_config.py", line 49, in command
    return func(*args, **kwargs)
           ^^^^^^^^^^^^^^^^^^^^^
  File "/home/airflow/.local/lib/python3.12/site-packages/airflow/utils/cli.py", line 116, in wrapper
    return f(*args, **kwargs)
           ^^^^^^^^^^^^^^^^^^
  File "/home/airflow/.local/lib/python3.12/site-packages/airflow/cli/commands/task_command.py", line 483, in task_run
    task_return_code = _run_task_by_selected_method(args, _dag, ti)
                       ^^^^^^^^^^^^^^^^^^^^^^^^^^^^^^^^^^^^^^^^^^^^
  File "/home/airflow/.local/lib/python3.12/site-packages/airflow/cli/commands/task_command.py", line 256, in _run_task_by_selected_method
    return _run_raw_task(args, ti)
           ^^^^^^^^^^^^^^^^^^^^^^^
  File "/home/airflow/.local/lib/python3.12/site-packages/airflow/cli/commands/task_command.py", line 341, in _run_raw_task
    return ti._run_raw_task(
           ^^^^^^^^^^^^^^^^^
  File "/home/airflow/.local/lib/python3.12/site-packages/airflow/utils/session.py", line 97, in wrapper
    return func(*args, session=session, **kwargs)
           ^^^^^^^^^^^^^^^^^^^^^^^^^^^^^^^^^^^^^^
  File "/home/airflow/.local/lib/python3.12/site-packages/airflow/models/taskinstance.py", line 3005, in _run_raw_task
    return _run_raw_task(
           ^^^^^^^^^^^^^^
  File "/home/airflow/.local/lib/python3.12/site-packages/airflow/models/taskinstance.py", line 273, in _run_raw_task
    TaskInstance._execute_task_with_callbacks(
  File "/home/airflow/.local/lib/python3.12/site-packages/airflow/models/taskinstance.py", line 3159, in _execute_task_with_callbacks
    result = self._execute_task(context, task_orig)
             ^^^^^^^^^^^^^^^^^^^^^^^^^^^^^^^^^^^^^^
  File "/home/airflow/.local/lib/python3.12/site-packages/airflow/models/taskinstance.py", line 3183, in _execute_task
    return _execute_task(self, context, task_orig)
           ^^^^^^^^^^^^^^^^^^^^^^^^^^^^^^^^^^^^^^^
  File "/home/airflow/.local/lib/python3.12/site-packages/airflow/models/taskinstance.py", line 767, in _execute_task
    result = _execute_callable(context=context, **execute_callable_kwargs)
             ^^^^^^^^^^^^^^^^^^^^^^^^^^^^^^^^^^^^^^^^^^^^^^^^^^^^^^^^^^^^^
  File "/home/airflow/.local/lib/python3.12/site-packages/airflow/models/taskinstance.py", line 733, in _execute_callable
    return ExecutionCallableRunner(
           ^^^^^^^^^^^^^^^^^^^^^^^^
  File "/home/airflow/.local/lib/python3.12/site-packages/airflow/utils/operator_helpers.py", line 252, in run
    return self.func(*args, **kwargs)
           ^^^^^^^^^^^^^^^^^^^^^^^^^^
  File "/home/airflow/.local/lib/python3.12/site-packages/airflow/models/baseoperator.py", line 422, in wrapper
    return func(self, *args, **kwargs)
           ^^^^^^^^^^^^^^^^^^^^^^^^^^^
  File "/home/airflow/.local/lib/python3.12/site-packages/airflow/providers/common/sql/operators/sql.py", line 284, in execute
    output = hook.run(
             ^^^^^^^^^
  File "/home/airflow/.local/lib/python3.12/site-packages/airflow/providers/common/sql/hooks/sql.py", line 498, in run
    self._run_command(cur, sql_statement, parameters)
  File "/home/airflow/.local/lib/python3.12/site-packages/airflow/providers/common/sql/hooks/sql.py", line 558, in _run_command
    cur.execute(sql_statement)
psycopg2.errors.InsufficientPrivilege: permission denied for schema public
LINE 2:     CREATE TABLE IF NOT EXISTS ebooks (
                                       ^

[2025-01-26T07:35:23.639+0000] {local_task_job_runner.py:266} INFO - Task exited with return code 1
[2025-01-26T07:35:23.735+0000] {taskinstance.py:3895} INFO - 0 downstream tasks scheduled from follow-on schedule check
[2025-01-26T07:35:23.792+0000] {local_task_job_runner.py:245} INFO - ::endgroup::
[2025-01-26T07:59:25.901+0000] {local_task_job_runner.py:123} INFO - ::group::Pre task execution logs
[2025-01-26T07:59:25.968+0000] {taskinstance.py:2613} INFO - Dependencies all met for dep_context=non-requeueable deps ti=<TaskInstance: fetch_and_store_ebooks.create_table scheduled__2025-01-17T00:00:00+00:00 [queued]>
[2025-01-26T07:59:25.996+0000] {taskinstance.py:2613} INFO - Dependencies all met for dep_context=requeueable deps ti=<TaskInstance: fetch_and_store_ebooks.create_table scheduled__2025-01-17T00:00:00+00:00 [queued]>
[2025-01-26T07:59:25.997+0000] {taskinstance.py:2866} INFO - Starting attempt 2 of 2
[2025-01-26T07:59:26.087+0000] {taskinstance.py:2889} INFO - Executing <Task(PostgresOperator): create_table> on 2025-01-17 00:00:00+00:00
[2025-01-26T07:59:26.106+0000] {warnings.py:112} WARNING - /home/***/.local/lib/python3.12/site-packages/***/task/task_runner/standard_task_runner.py:70: DeprecationWarning: This process (pid=2286) is multi-threaded, use of fork() may lead to deadlocks in the child.
  pid = os.fork()

[2025-01-26T07:59:26.114+0000] {standard_task_runner.py:72} INFO - Started process 2292 to run task
[2025-01-26T07:59:26.122+0000] {standard_task_runner.py:104} INFO - Running: ['***', 'tasks', 'run', 'fetch_and_store_ebooks', 'create_table', 'scheduled__2025-01-17T00:00:00+00:00', '--job-id', '780', '--raw', '--subdir', 'DAGS_FOLDER/app.py', '--cfg-path', '/tmp/tmptbqnv8dc']
[2025-01-26T07:59:26.127+0000] {standard_task_runner.py:105} INFO - Job 780: Subtask create_table
[2025-01-26T07:59:26.298+0000] {task_command.py:467} INFO - Running <TaskInstance: fetch_and_store_ebooks.create_table scheduled__2025-01-17T00:00:00+00:00 [running]> on host 34edd304782d
[2025-01-26T07:59:26.674+0000] {taskinstance.py:3132} INFO - Exporting env vars: AIRFLOW_CTX_DAG_OWNER='***' AIRFLOW_CTX_DAG_ID='fetch_and_store_ebooks' AIRFLOW_CTX_TASK_ID='create_table' AIRFLOW_CTX_EXECUTION_DATE='2025-01-17T00:00:00+00:00' AIRFLOW_CTX_TRY_NUMBER='2' AIRFLOW_CTX_DAG_RUN_ID='scheduled__2025-01-17T00:00:00+00:00'
[2025-01-26T07:59:26.678+0000] {logging_mixin.py:190} INFO - Task instance is in running state
[2025-01-26T07:59:26.680+0000] {logging_mixin.py:190} INFO -  Previous state of the Task instance: queued
[2025-01-26T07:59:26.681+0000] {logging_mixin.py:190} INFO - Current task name:create_table state:running start_date:2025-01-26 07:59:25.969974+00:00
[2025-01-26T07:59:26.682+0000] {logging_mixin.py:190} INFO - Dag name:fetch_and_store_ebooks and current dag run status:running
[2025-01-26T07:59:26.683+0000] {taskinstance.py:731} INFO - ::endgroup::
[2025-01-26T07:59:26.685+0000] {sql.py:278} INFO - Executing: 
    CREATE TABLE IF NOT EXISTS ebooks (
        id SERIAL PRIMARY KEY,
        judul TEXT NOT NULL,
        penulis TEXT,
        link TEXT
    );
    
[2025-01-26T07:59:26.710+0000] {base.py:84} INFO - Retrieving connection 'ebooks_connection'
[2025-01-26T07:59:26.732+0000] {base.py:84} INFO - Retrieving connection 'ebooks_connection'
[2025-01-26T07:59:26.883+0000] {sql.py:553} INFO - Running statement: 
    CREATE TABLE IF NOT EXISTS ebooks (
        id SERIAL PRIMARY KEY,
        judul TEXT NOT NULL,
        penulis TEXT,
        link TEXT
    );
    , parameters: None
[2025-01-26T07:59:26.892+0000] {taskinstance.py:3311} ERROR - Task failed with exception
Traceback (most recent call last):
  File "/home/airflow/.local/lib/python3.12/site-packages/airflow/models/taskinstance.py", line 767, in _execute_task
    result = _execute_callable(context=context, **execute_callable_kwargs)
             ^^^^^^^^^^^^^^^^^^^^^^^^^^^^^^^^^^^^^^^^^^^^^^^^^^^^^^^^^^^^^
  File "/home/airflow/.local/lib/python3.12/site-packages/airflow/models/taskinstance.py", line 733, in _execute_callable
    return ExecutionCallableRunner(
           ^^^^^^^^^^^^^^^^^^^^^^^^
  File "/home/airflow/.local/lib/python3.12/site-packages/airflow/utils/operator_helpers.py", line 252, in run
    return self.func(*args, **kwargs)
           ^^^^^^^^^^^^^^^^^^^^^^^^^^
  File "/home/airflow/.local/lib/python3.12/site-packages/airflow/models/baseoperator.py", line 422, in wrapper
    return func(self, *args, **kwargs)
           ^^^^^^^^^^^^^^^^^^^^^^^^^^^
  File "/home/airflow/.local/lib/python3.12/site-packages/airflow/providers/common/sql/operators/sql.py", line 284, in execute
    output = hook.run(
             ^^^^^^^^^
  File "/home/airflow/.local/lib/python3.12/site-packages/airflow/providers/common/sql/hooks/sql.py", line 498, in run
    self._run_command(cur, sql_statement, parameters)
  File "/home/airflow/.local/lib/python3.12/site-packages/airflow/providers/common/sql/hooks/sql.py", line 558, in _run_command
    cur.execute(sql_statement)
psycopg2.errors.InsufficientPrivilege: permission denied for schema public
LINE 2:     CREATE TABLE IF NOT EXISTS ebooks (
                                       ^

[2025-01-26T07:59:26.921+0000] {logging_mixin.py:190} INFO - Task instance in failure state
[2025-01-26T07:59:26.923+0000] {logging_mixin.py:190} INFO - Task start:2025-01-26 07:59:25.969974+00:00 end:2025-01-26 07:59:26.920339+00:00 duration:0.950365
[2025-01-26T07:59:26.925+0000] {logging_mixin.py:190} INFO - Task:<Task(PostgresOperator): create_table> dag:<DAG: fetch_and_store_ebooks> dagrun:<DagRun fetch_and_store_ebooks @ 2025-01-17 00:00:00+00:00: scheduled__2025-01-17T00:00:00+00:00, state:running, queued_at: 2025-01-26 07:53:32.381132+00:00. externally triggered: False>
[2025-01-26T07:59:26.926+0000] {logging_mixin.py:190} INFO - Failure caused by permission denied for schema public
LINE 2:     CREATE TABLE IF NOT EXISTS ebooks (
                                       ^
[2025-01-26T07:59:26.928+0000] {taskinstance.py:1225} INFO - Marking task as FAILED. dag_id=fetch_and_store_ebooks, task_id=create_table, run_id=scheduled__2025-01-17T00:00:00+00:00, execution_date=20250117T000000, start_date=20250126T075925, end_date=20250126T075926
[2025-01-26T07:59:26.972+0000] {taskinstance.py:340} INFO - ::group::Post task execution logs
[2025-01-26T07:59:26.974+0000] {standard_task_runner.py:124} ERROR - Failed to execute job 780 for task create_table (permission denied for schema public
LINE 2:     CREATE TABLE IF NOT EXISTS ebooks (
                                       ^
; 2292)
Traceback (most recent call last):
  File "/home/airflow/.local/lib/python3.12/site-packages/airflow/task/task_runner/standard_task_runner.py", line 117, in _start_by_fork
    ret = args.func(args, dag=self.dag)
          ^^^^^^^^^^^^^^^^^^^^^^^^^^^^^
  File "/home/airflow/.local/lib/python3.12/site-packages/airflow/cli/cli_config.py", line 49, in command
    return func(*args, **kwargs)
           ^^^^^^^^^^^^^^^^^^^^^
  File "/home/airflow/.local/lib/python3.12/site-packages/airflow/utils/cli.py", line 116, in wrapper
    return f(*args, **kwargs)
           ^^^^^^^^^^^^^^^^^^
  File "/home/airflow/.local/lib/python3.12/site-packages/airflow/cli/commands/task_command.py", line 483, in task_run
    task_return_code = _run_task_by_selected_method(args, _dag, ti)
                       ^^^^^^^^^^^^^^^^^^^^^^^^^^^^^^^^^^^^^^^^^^^^
  File "/home/airflow/.local/lib/python3.12/site-packages/airflow/cli/commands/task_command.py", line 256, in _run_task_by_selected_method
    return _run_raw_task(args, ti)
           ^^^^^^^^^^^^^^^^^^^^^^^
  File "/home/airflow/.local/lib/python3.12/site-packages/airflow/cli/commands/task_command.py", line 341, in _run_raw_task
    return ti._run_raw_task(
           ^^^^^^^^^^^^^^^^^
  File "/home/airflow/.local/lib/python3.12/site-packages/airflow/utils/session.py", line 97, in wrapper
    return func(*args, session=session, **kwargs)
           ^^^^^^^^^^^^^^^^^^^^^^^^^^^^^^^^^^^^^^
  File "/home/airflow/.local/lib/python3.12/site-packages/airflow/models/taskinstance.py", line 3005, in _run_raw_task
    return _run_raw_task(
           ^^^^^^^^^^^^^^
  File "/home/airflow/.local/lib/python3.12/site-packages/airflow/models/taskinstance.py", line 273, in _run_raw_task
    TaskInstance._execute_task_with_callbacks(
  File "/home/airflow/.local/lib/python3.12/site-packages/airflow/models/taskinstance.py", line 3159, in _execute_task_with_callbacks
    result = self._execute_task(context, task_orig)
             ^^^^^^^^^^^^^^^^^^^^^^^^^^^^^^^^^^^^^^
  File "/home/airflow/.local/lib/python3.12/site-packages/airflow/models/taskinstance.py", line 3183, in _execute_task
    return _execute_task(self, context, task_orig)
           ^^^^^^^^^^^^^^^^^^^^^^^^^^^^^^^^^^^^^^^
  File "/home/airflow/.local/lib/python3.12/site-packages/airflow/models/taskinstance.py", line 767, in _execute_task
    result = _execute_callable(context=context, **execute_callable_kwargs)
             ^^^^^^^^^^^^^^^^^^^^^^^^^^^^^^^^^^^^^^^^^^^^^^^^^^^^^^^^^^^^^
  File "/home/airflow/.local/lib/python3.12/site-packages/airflow/models/taskinstance.py", line 733, in _execute_callable
    return ExecutionCallableRunner(
           ^^^^^^^^^^^^^^^^^^^^^^^^
  File "/home/airflow/.local/lib/python3.12/site-packages/airflow/utils/operator_helpers.py", line 252, in run
    return self.func(*args, **kwargs)
           ^^^^^^^^^^^^^^^^^^^^^^^^^^
  File "/home/airflow/.local/lib/python3.12/site-packages/airflow/models/baseoperator.py", line 422, in wrapper
    return func(self, *args, **kwargs)
           ^^^^^^^^^^^^^^^^^^^^^^^^^^^
  File "/home/airflow/.local/lib/python3.12/site-packages/airflow/providers/common/sql/operators/sql.py", line 284, in execute
    output = hook.run(
             ^^^^^^^^^
  File "/home/airflow/.local/lib/python3.12/site-packages/airflow/providers/common/sql/hooks/sql.py", line 498, in run
    self._run_command(cur, sql_statement, parameters)
  File "/home/airflow/.local/lib/python3.12/site-packages/airflow/providers/common/sql/hooks/sql.py", line 558, in _run_command
    cur.execute(sql_statement)
psycopg2.errors.InsufficientPrivilege: permission denied for schema public
LINE 2:     CREATE TABLE IF NOT EXISTS ebooks (
                                       ^

[2025-01-26T07:59:27.031+0000] {local_task_job_runner.py:266} INFO - Task exited with return code 1
[2025-01-26T07:59:27.092+0000] {taskinstance.py:3895} INFO - 0 downstream tasks scheduled from follow-on schedule check
[2025-01-26T07:59:27.139+0000] {local_task_job_runner.py:245} INFO - ::endgroup::
