[2025-01-25T17:04:21.692+0000] {local_task_job_runner.py:123} INFO - ::group::Pre task execution logs
[2025-01-25T17:04:21.861+0000] {taskinstance.py:2613} INFO - Dependencies all met for dep_context=non-requeueable deps ti=<TaskInstance: fetch_and_store_ebooks.create_table scheduled__2025-01-02T00:00:00+00:00 [queued]>
[2025-01-25T17:04:21.952+0000] {taskinstance.py:2613} INFO - Dependencies all met for dep_context=requeueable deps ti=<TaskInstance: fetch_and_store_ebooks.create_table scheduled__2025-01-02T00:00:00+00:00 [queued]>
[2025-01-25T17:04:21.965+0000] {taskinstance.py:2866} INFO - Starting attempt 1 of 2
[2025-01-25T17:04:22.086+0000] {taskinstance.py:2889} INFO - Executing <Task(PostgresOperator): create_table> on 2025-01-02 00:00:00+00:00
[2025-01-25T17:04:22.120+0000] {warnings.py:112} WARNING - /home/***/.local/lib/python3.12/site-packages/***/task/task_runner/standard_task_runner.py:70: DeprecationWarning: This process (pid=3778) is multi-threaded, use of fork() may lead to deadlocks in the child.
  pid = os.fork()

[2025-01-25T17:04:22.126+0000] {standard_task_runner.py:72} INFO - Started process 3834 to run task
[2025-01-25T17:04:22.127+0000] {standard_task_runner.py:104} INFO - Running: ['***', 'tasks', 'run', 'fetch_and_store_ebooks', 'create_table', 'scheduled__2025-01-02T00:00:00+00:00', '--job-id', '471', '--raw', '--subdir', 'DAGS_FOLDER/app.py', '--cfg-path', '/tmp/tmp6rk_9hm0']
[2025-01-25T17:04:22.136+0000] {standard_task_runner.py:105} INFO - Job 471: Subtask create_table
[2025-01-25T17:04:23.229+0000] {task_command.py:467} INFO - Running <TaskInstance: fetch_and_store_ebooks.create_table scheduled__2025-01-02T00:00:00+00:00 [running]> on host 50ab235b552a
[2025-01-25T17:04:23.787+0000] {taskinstance.py:3132} INFO - Exporting env vars: AIRFLOW_CTX_DAG_OWNER='***' AIRFLOW_CTX_DAG_ID='fetch_and_store_ebooks' AIRFLOW_CTX_TASK_ID='create_table' AIRFLOW_CTX_EXECUTION_DATE='2025-01-02T00:00:00+00:00' AIRFLOW_CTX_TRY_NUMBER='1' AIRFLOW_CTX_DAG_RUN_ID='scheduled__2025-01-02T00:00:00+00:00'
[2025-01-25T17:04:23.791+0000] {logging_mixin.py:190} INFO - Task instance is in running state
[2025-01-25T17:04:23.793+0000] {logging_mixin.py:190} INFO -  Previous state of the Task instance: queued
[2025-01-25T17:04:23.795+0000] {logging_mixin.py:190} INFO - Current task name:create_table state:running start_date:2025-01-25 17:04:21.872901+00:00
[2025-01-25T17:04:23.799+0000] {logging_mixin.py:190} INFO - Dag name:fetch_and_store_ebooks and current dag run status:running
[2025-01-25T17:04:23.802+0000] {taskinstance.py:731} INFO - ::endgroup::
[2025-01-25T17:04:23.805+0000] {sql.py:278} INFO - Executing: 
    CREATE TABLE IF NOT EXISTS ebooks (
        id SERIAL PRIMARY KEY,
        judul TEXT NOT NULL,
        penulis TEXT,
        link TEXT
    );
    
[2025-01-25T17:04:23.841+0000] {base.py:84} INFO - Retrieving connection 'ebooks_connection'
[2025-01-25T17:04:23.902+0000] {base.py:84} INFO - Retrieving connection 'ebooks_connection'
[2025-01-25T17:04:23.908+0000] {taskinstance.py:3311} ERROR - Task failed with exception
Traceback (most recent call last):
  File "/home/airflow/.local/lib/python3.12/site-packages/airflow/models/taskinstance.py", line 767, in _execute_task
    result = _execute_callable(context=context, **execute_callable_kwargs)
             ^^^^^^^^^^^^^^^^^^^^^^^^^^^^^^^^^^^^^^^^^^^^^^^^^^^^^^^^^^^^^
  File "/home/airflow/.local/lib/python3.12/site-packages/airflow/models/taskinstance.py", line 733, in _execute_callable
    return ExecutionCallableRunner(
           ^^^^^^^^^^^^^^^^^^^^^^^^
  File "/home/airflow/.local/lib/python3.12/site-packages/airflow/utils/operator_helpers.py", line 252, in run
    return self.func(*args, **kwargs)
           ^^^^^^^^^^^^^^^^^^^^^^^^^^
  File "/home/airflow/.local/lib/python3.12/site-packages/airflow/models/baseoperator.py", line 422, in wrapper
    return func(self, *args, **kwargs)
           ^^^^^^^^^^^^^^^^^^^^^^^^^^^
  File "/home/airflow/.local/lib/python3.12/site-packages/airflow/providers/common/sql/operators/sql.py", line 284, in execute
    output = hook.run(
             ^^^^^^^^^
  File "/home/airflow/.local/lib/python3.12/site-packages/airflow/providers/common/sql/hooks/sql.py", line 494, in run
    with self._create_autocommit_connection(autocommit) as conn:
         ^^^^^^^^^^^^^^^^^^^^^^^^^^^^^^^^^^^^^^^^^^^^^^
  File "/usr/local/lib/python3.12/contextlib.py", line 137, in __enter__
    return next(self.gen)
           ^^^^^^^^^^^^^^
  File "/home/airflow/.local/lib/python3.12/site-packages/airflow/providers/common/sql/hooks/sql.py", line 618, in _create_autocommit_connection
    with closing(self.get_conn()) as conn:
                 ^^^^^^^^^^^^^^^
  File "/home/airflow/.local/lib/python3.12/site-packages/airflow/providers/postgres/hooks/postgres.py", line 189, in get_conn
    self.conn = psycopg2.connect(**conn_args)
                ^^^^^^^^^^^^^^^^^^^^^^^^^^^^^
  File "/home/airflow/.local/lib/python3.12/site-packages/psycopg2/__init__.py", line 122, in connect
    conn = _connect(dsn, connection_factory=connection_factory, **kwasync)
           ^^^^^^^^^^^^^^^^^^^^^^^^^^^^^^^^^^^^^^^^^^^^^^^^^^^^^^^^^^^^^^^
psycopg2.OperationalError: connection to server at "localhost" (::1), port 5432 failed: Connection refused
	Is the server running on that host and accepting TCP/IP connections?
connection to server at "localhost" (127.0.0.1), port 5432 failed: Connection refused
	Is the server running on that host and accepting TCP/IP connections?

[2025-01-25T17:04:23.976+0000] {logging_mixin.py:190} INFO - Task instance in failure state
[2025-01-25T17:04:23.979+0000] {logging_mixin.py:190} INFO - Task start:2025-01-25 17:04:21.872901+00:00 end:2025-01-25 17:04:23.973403+00:00 duration:2.100502
[2025-01-25T17:04:23.981+0000] {logging_mixin.py:190} INFO - Task:<Task(PostgresOperator): create_table> dag:<DAG: fetch_and_store_ebooks> dagrun:<DagRun fetch_and_store_ebooks @ 2025-01-02 00:00:00+00:00: scheduled__2025-01-02T00:00:00+00:00, state:running, queued_at: 2025-01-25 17:02:00.125869+00:00. externally triggered: False>
[2025-01-25T17:04:23.984+0000] {logging_mixin.py:190} INFO - Failure caused by connection to server at "localhost" (::1), port 5432 failed: Connection refused
	Is the server running on that host and accepting TCP/IP connections?
connection to server at "localhost" (127.0.0.1), port 5432 failed: Connection refused
	Is the server running on that host and accepting TCP/IP connections?
[2025-01-25T17:04:23.987+0000] {taskinstance.py:1225} INFO - Marking task as UP_FOR_RETRY. dag_id=fetch_and_store_ebooks, task_id=create_table, run_id=scheduled__2025-01-02T00:00:00+00:00, execution_date=20250102T000000, start_date=20250125T170421, end_date=20250125T170423
[2025-01-25T17:04:24.101+0000] {taskinstance.py:340} INFO - ::group::Post task execution logs
[2025-01-25T17:04:24.111+0000] {standard_task_runner.py:124} ERROR - Failed to execute job 471 for task create_table (connection to server at "localhost" (::1), port 5432 failed: Connection refused
	Is the server running on that host and accepting TCP/IP connections?
connection to server at "localhost" (127.0.0.1), port 5432 failed: Connection refused
	Is the server running on that host and accepting TCP/IP connections?
; 3834)
Traceback (most recent call last):
  File "/home/airflow/.local/lib/python3.12/site-packages/airflow/task/task_runner/standard_task_runner.py", line 117, in _start_by_fork
    ret = args.func(args, dag=self.dag)
          ^^^^^^^^^^^^^^^^^^^^^^^^^^^^^
  File "/home/airflow/.local/lib/python3.12/site-packages/airflow/cli/cli_config.py", line 49, in command
    return func(*args, **kwargs)
           ^^^^^^^^^^^^^^^^^^^^^
  File "/home/airflow/.local/lib/python3.12/site-packages/airflow/utils/cli.py", line 116, in wrapper
    return f(*args, **kwargs)
           ^^^^^^^^^^^^^^^^^^
  File "/home/airflow/.local/lib/python3.12/site-packages/airflow/cli/commands/task_command.py", line 483, in task_run
    task_return_code = _run_task_by_selected_method(args, _dag, ti)
                       ^^^^^^^^^^^^^^^^^^^^^^^^^^^^^^^^^^^^^^^^^^^^
  File "/home/airflow/.local/lib/python3.12/site-packages/airflow/cli/commands/task_command.py", line 256, in _run_task_by_selected_method
    return _run_raw_task(args, ti)
           ^^^^^^^^^^^^^^^^^^^^^^^
  File "/home/airflow/.local/lib/python3.12/site-packages/airflow/cli/commands/task_command.py", line 341, in _run_raw_task
    return ti._run_raw_task(
           ^^^^^^^^^^^^^^^^^
  File "/home/airflow/.local/lib/python3.12/site-packages/airflow/utils/session.py", line 97, in wrapper
    return func(*args, session=session, **kwargs)
           ^^^^^^^^^^^^^^^^^^^^^^^^^^^^^^^^^^^^^^
  File "/home/airflow/.local/lib/python3.12/site-packages/airflow/models/taskinstance.py", line 3005, in _run_raw_task
    return _run_raw_task(
           ^^^^^^^^^^^^^^
  File "/home/airflow/.local/lib/python3.12/site-packages/airflow/models/taskinstance.py", line 273, in _run_raw_task
    TaskInstance._execute_task_with_callbacks(
  File "/home/airflow/.local/lib/python3.12/site-packages/airflow/models/taskinstance.py", line 3159, in _execute_task_with_callbacks
    result = self._execute_task(context, task_orig)
             ^^^^^^^^^^^^^^^^^^^^^^^^^^^^^^^^^^^^^^
  File "/home/airflow/.local/lib/python3.12/site-packages/airflow/models/taskinstance.py", line 3183, in _execute_task
    return _execute_task(self, context, task_orig)
           ^^^^^^^^^^^^^^^^^^^^^^^^^^^^^^^^^^^^^^^
  File "/home/airflow/.local/lib/python3.12/site-packages/airflow/models/taskinstance.py", line 767, in _execute_task
    result = _execute_callable(context=context, **execute_callable_kwargs)
             ^^^^^^^^^^^^^^^^^^^^^^^^^^^^^^^^^^^^^^^^^^^^^^^^^^^^^^^^^^^^^
  File "/home/airflow/.local/lib/python3.12/site-packages/airflow/models/taskinstance.py", line 733, in _execute_callable
    return ExecutionCallableRunner(
           ^^^^^^^^^^^^^^^^^^^^^^^^
  File "/home/airflow/.local/lib/python3.12/site-packages/airflow/utils/operator_helpers.py", line 252, in run
    return self.func(*args, **kwargs)
           ^^^^^^^^^^^^^^^^^^^^^^^^^^
  File "/home/airflow/.local/lib/python3.12/site-packages/airflow/models/baseoperator.py", line 422, in wrapper
    return func(self, *args, **kwargs)
           ^^^^^^^^^^^^^^^^^^^^^^^^^^^
  File "/home/airflow/.local/lib/python3.12/site-packages/airflow/providers/common/sql/operators/sql.py", line 284, in execute
    output = hook.run(
             ^^^^^^^^^
  File "/home/airflow/.local/lib/python3.12/site-packages/airflow/providers/common/sql/hooks/sql.py", line 494, in run
    with self._create_autocommit_connection(autocommit) as conn:
         ^^^^^^^^^^^^^^^^^^^^^^^^^^^^^^^^^^^^^^^^^^^^^^
  File "/usr/local/lib/python3.12/contextlib.py", line 137, in __enter__
    return next(self.gen)
           ^^^^^^^^^^^^^^
  File "/home/airflow/.local/lib/python3.12/site-packages/airflow/providers/common/sql/hooks/sql.py", line 618, in _create_autocommit_connection
    with closing(self.get_conn()) as conn:
                 ^^^^^^^^^^^^^^^
  File "/home/airflow/.local/lib/python3.12/site-packages/airflow/providers/postgres/hooks/postgres.py", line 189, in get_conn
    self.conn = psycopg2.connect(**conn_args)
                ^^^^^^^^^^^^^^^^^^^^^^^^^^^^^
  File "/home/airflow/.local/lib/python3.12/site-packages/psycopg2/__init__.py", line 122, in connect
    conn = _connect(dsn, connection_factory=connection_factory, **kwasync)
           ^^^^^^^^^^^^^^^^^^^^^^^^^^^^^^^^^^^^^^^^^^^^^^^^^^^^^^^^^^^^^^^
psycopg2.OperationalError: connection to server at "localhost" (::1), port 5432 failed: Connection refused
	Is the server running on that host and accepting TCP/IP connections?
connection to server at "localhost" (127.0.0.1), port 5432 failed: Connection refused
	Is the server running on that host and accepting TCP/IP connections?

[2025-01-25T17:04:24.253+0000] {local_task_job_runner.py:266} INFO - Task exited with return code 1
[2025-01-25T17:04:24.315+0000] {local_task_job_runner.py:245} INFO - ::endgroup::
[2025-01-26T06:34:33.663+0000] {local_task_job_runner.py:123} INFO - ::group::Pre task execution logs
[2025-01-26T06:34:33.790+0000] {taskinstance.py:2613} INFO - Dependencies all met for dep_context=non-requeueable deps ti=<TaskInstance: fetch_and_store_ebooks.create_table scheduled__2025-01-02T00:00:00+00:00 [queued]>
[2025-01-26T06:34:33.852+0000] {taskinstance.py:2613} INFO - Dependencies all met for dep_context=requeueable deps ti=<TaskInstance: fetch_and_store_ebooks.create_table scheduled__2025-01-02T00:00:00+00:00 [queued]>
[2025-01-26T06:34:33.854+0000] {taskinstance.py:2866} INFO - Starting attempt 1 of 2
[2025-01-26T06:34:35.388+0000] {taskinstance.py:2889} INFO - Executing <Task(PostgresOperator): create_table> on 2025-01-02 00:00:00+00:00
[2025-01-26T06:34:35.477+0000] {warnings.py:112} WARNING - /home/***/.local/lib/python3.12/site-packages/***/task/task_runner/standard_task_runner.py:70: DeprecationWarning: This process (pid=427) is multi-threaded, use of fork() may lead to deadlocks in the child.
  pid = os.fork()

[2025-01-26T06:34:35.505+0000] {standard_task_runner.py:72} INFO - Started process 466 to run task
[2025-01-26T06:34:35.502+0000] {standard_task_runner.py:104} INFO - Running: ['***', 'tasks', 'run', 'fetch_and_store_ebooks', 'create_table', 'scheduled__2025-01-02T00:00:00+00:00', '--job-id', '549', '--raw', '--subdir', 'DAGS_FOLDER/app.py', '--cfg-path', '/tmp/tmpho27u2wr']
[2025-01-26T06:34:35.555+0000] {standard_task_runner.py:105} INFO - Job 549: Subtask create_table
[2025-01-26T06:34:35.898+0000] {task_command.py:467} INFO - Running <TaskInstance: fetch_and_store_ebooks.create_table scheduled__2025-01-02T00:00:00+00:00 [running]> on host 34edd304782d
[2025-01-26T06:34:36.483+0000] {taskinstance.py:3132} INFO - Exporting env vars: AIRFLOW_CTX_DAG_OWNER='***' AIRFLOW_CTX_DAG_ID='fetch_and_store_ebooks' AIRFLOW_CTX_TASK_ID='create_table' AIRFLOW_CTX_EXECUTION_DATE='2025-01-02T00:00:00+00:00' AIRFLOW_CTX_TRY_NUMBER='1' AIRFLOW_CTX_DAG_RUN_ID='scheduled__2025-01-02T00:00:00+00:00'
[2025-01-26T06:34:36.502+0000] {logging_mixin.py:190} INFO - Task instance is in running state
[2025-01-26T06:34:36.504+0000] {logging_mixin.py:190} INFO -  Previous state of the Task instance: queued
[2025-01-26T06:34:36.506+0000] {logging_mixin.py:190} INFO - Current task name:create_table state:running start_date:2025-01-26 06:34:33.794116+00:00
[2025-01-26T06:34:36.508+0000] {logging_mixin.py:190} INFO - Dag name:fetch_and_store_ebooks and current dag run status:running
[2025-01-26T06:34:36.510+0000] {taskinstance.py:731} INFO - ::endgroup::
[2025-01-26T06:34:36.512+0000] {sql.py:278} INFO - Executing: 
    CREATE TABLE IF NOT EXISTS ebooks (
        id SERIAL PRIMARY KEY,
        judul TEXT NOT NULL,
        penulis TEXT,
        link TEXT
    );
    
[2025-01-26T06:34:36.589+0000] {base.py:84} INFO - Retrieving connection 'ebooks_connection'
[2025-01-26T06:34:36.654+0000] {base.py:84} INFO - Retrieving connection 'ebooks_connection'
[2025-01-26T06:34:37.039+0000] {sql.py:553} INFO - Running statement: 
    CREATE TABLE IF NOT EXISTS ebooks (
        id SERIAL PRIMARY KEY,
        judul TEXT NOT NULL,
        penulis TEXT,
        link TEXT
    );
    , parameters: None
[2025-01-26T06:34:37.099+0000] {taskinstance.py:3311} ERROR - Task failed with exception
Traceback (most recent call last):
  File "/home/airflow/.local/lib/python3.12/site-packages/airflow/models/taskinstance.py", line 767, in _execute_task
    result = _execute_callable(context=context, **execute_callable_kwargs)
             ^^^^^^^^^^^^^^^^^^^^^^^^^^^^^^^^^^^^^^^^^^^^^^^^^^^^^^^^^^^^^
  File "/home/airflow/.local/lib/python3.12/site-packages/airflow/models/taskinstance.py", line 733, in _execute_callable
    return ExecutionCallableRunner(
           ^^^^^^^^^^^^^^^^^^^^^^^^
  File "/home/airflow/.local/lib/python3.12/site-packages/airflow/utils/operator_helpers.py", line 252, in run
    return self.func(*args, **kwargs)
           ^^^^^^^^^^^^^^^^^^^^^^^^^^
  File "/home/airflow/.local/lib/python3.12/site-packages/airflow/models/baseoperator.py", line 422, in wrapper
    return func(self, *args, **kwargs)
           ^^^^^^^^^^^^^^^^^^^^^^^^^^^
  File "/home/airflow/.local/lib/python3.12/site-packages/airflow/providers/common/sql/operators/sql.py", line 284, in execute
    output = hook.run(
             ^^^^^^^^^
  File "/home/airflow/.local/lib/python3.12/site-packages/airflow/providers/common/sql/hooks/sql.py", line 498, in run
    self._run_command(cur, sql_statement, parameters)
  File "/home/airflow/.local/lib/python3.12/site-packages/airflow/providers/common/sql/hooks/sql.py", line 558, in _run_command
    cur.execute(sql_statement)
psycopg2.errors.InsufficientPrivilege: permission denied for schema public
LINE 2:     CREATE TABLE IF NOT EXISTS ebooks (
                                       ^

[2025-01-26T06:34:37.350+0000] {logging_mixin.py:190} INFO - Task instance in failure state
[2025-01-26T06:34:37.354+0000] {logging_mixin.py:190} INFO - Task start:2025-01-26 06:34:33.794116+00:00 end:2025-01-26 06:34:37.346255+00:00 duration:3.552139
[2025-01-26T06:34:37.357+0000] {logging_mixin.py:190} INFO - Task:<Task(PostgresOperator): create_table> dag:<DAG: fetch_and_store_ebooks> dagrun:<DagRun fetch_and_store_ebooks @ 2025-01-02 00:00:00+00:00: scheduled__2025-01-02T00:00:00+00:00, state:running, queued_at: 2025-01-26 06:33:28.991870+00:00. externally triggered: False>
[2025-01-26T06:34:37.360+0000] {logging_mixin.py:190} INFO - Failure caused by permission denied for schema public
LINE 2:     CREATE TABLE IF NOT EXISTS ebooks (
                                       ^
[2025-01-26T06:34:37.362+0000] {taskinstance.py:1225} INFO - Marking task as UP_FOR_RETRY. dag_id=fetch_and_store_ebooks, task_id=create_table, run_id=scheduled__2025-01-02T00:00:00+00:00, execution_date=20250102T000000, start_date=20250126T063433, end_date=20250126T063437
[2025-01-26T06:34:37.460+0000] {taskinstance.py:340} INFO - ::group::Post task execution logs
[2025-01-26T06:34:37.468+0000] {standard_task_runner.py:124} ERROR - Failed to execute job 549 for task create_table (permission denied for schema public
LINE 2:     CREATE TABLE IF NOT EXISTS ebooks (
                                       ^
; 466)
Traceback (most recent call last):
  File "/home/airflow/.local/lib/python3.12/site-packages/airflow/task/task_runner/standard_task_runner.py", line 117, in _start_by_fork
    ret = args.func(args, dag=self.dag)
          ^^^^^^^^^^^^^^^^^^^^^^^^^^^^^
  File "/home/airflow/.local/lib/python3.12/site-packages/airflow/cli/cli_config.py", line 49, in command
    return func(*args, **kwargs)
           ^^^^^^^^^^^^^^^^^^^^^
  File "/home/airflow/.local/lib/python3.12/site-packages/airflow/utils/cli.py", line 116, in wrapper
    return f(*args, **kwargs)
           ^^^^^^^^^^^^^^^^^^
  File "/home/airflow/.local/lib/python3.12/site-packages/airflow/cli/commands/task_command.py", line 483, in task_run
    task_return_code = _run_task_by_selected_method(args, _dag, ti)
                       ^^^^^^^^^^^^^^^^^^^^^^^^^^^^^^^^^^^^^^^^^^^^
  File "/home/airflow/.local/lib/python3.12/site-packages/airflow/cli/commands/task_command.py", line 256, in _run_task_by_selected_method
    return _run_raw_task(args, ti)
           ^^^^^^^^^^^^^^^^^^^^^^^
  File "/home/airflow/.local/lib/python3.12/site-packages/airflow/cli/commands/task_command.py", line 341, in _run_raw_task
    return ti._run_raw_task(
           ^^^^^^^^^^^^^^^^^
  File "/home/airflow/.local/lib/python3.12/site-packages/airflow/utils/session.py", line 97, in wrapper
    return func(*args, session=session, **kwargs)
           ^^^^^^^^^^^^^^^^^^^^^^^^^^^^^^^^^^^^^^
  File "/home/airflow/.local/lib/python3.12/site-packages/airflow/models/taskinstance.py", line 3005, in _run_raw_task
    return _run_raw_task(
           ^^^^^^^^^^^^^^
  File "/home/airflow/.local/lib/python3.12/site-packages/airflow/models/taskinstance.py", line 273, in _run_raw_task
    TaskInstance._execute_task_with_callbacks(
  File "/home/airflow/.local/lib/python3.12/site-packages/airflow/models/taskinstance.py", line 3159, in _execute_task_with_callbacks
    result = self._execute_task(context, task_orig)
             ^^^^^^^^^^^^^^^^^^^^^^^^^^^^^^^^^^^^^^
  File "/home/airflow/.local/lib/python3.12/site-packages/airflow/models/taskinstance.py", line 3183, in _execute_task
    return _execute_task(self, context, task_orig)
           ^^^^^^^^^^^^^^^^^^^^^^^^^^^^^^^^^^^^^^^
  File "/home/airflow/.local/lib/python3.12/site-packages/airflow/models/taskinstance.py", line 767, in _execute_task
    result = _execute_callable(context=context, **execute_callable_kwargs)
             ^^^^^^^^^^^^^^^^^^^^^^^^^^^^^^^^^^^^^^^^^^^^^^^^^^^^^^^^^^^^^
  File "/home/airflow/.local/lib/python3.12/site-packages/airflow/models/taskinstance.py", line 733, in _execute_callable
    return ExecutionCallableRunner(
           ^^^^^^^^^^^^^^^^^^^^^^^^
  File "/home/airflow/.local/lib/python3.12/site-packages/airflow/utils/operator_helpers.py", line 252, in run
    return self.func(*args, **kwargs)
           ^^^^^^^^^^^^^^^^^^^^^^^^^^
  File "/home/airflow/.local/lib/python3.12/site-packages/airflow/models/baseoperator.py", line 422, in wrapper
    return func(self, *args, **kwargs)
           ^^^^^^^^^^^^^^^^^^^^^^^^^^^
  File "/home/airflow/.local/lib/python3.12/site-packages/airflow/providers/common/sql/operators/sql.py", line 284, in execute
    output = hook.run(
             ^^^^^^^^^
  File "/home/airflow/.local/lib/python3.12/site-packages/airflow/providers/common/sql/hooks/sql.py", line 498, in run
    self._run_command(cur, sql_statement, parameters)
  File "/home/airflow/.local/lib/python3.12/site-packages/airflow/providers/common/sql/hooks/sql.py", line 558, in _run_command
    cur.execute(sql_statement)
psycopg2.errors.InsufficientPrivilege: permission denied for schema public
LINE 2:     CREATE TABLE IF NOT EXISTS ebooks (
                                       ^

[2025-01-26T06:34:37.715+0000] {local_task_job_runner.py:266} INFO - Task exited with return code 1
[2025-01-26T06:34:37.902+0000] {taskinstance.py:3895} INFO - 0 downstream tasks scheduled from follow-on schedule check
[2025-01-26T06:34:37.911+0000] {local_task_job_runner.py:245} INFO - ::endgroup::
[2025-01-26T07:22:35.869+0000] {local_task_job_runner.py:123} INFO - ::group::Pre task execution logs
[2025-01-26T07:22:36.089+0000] {taskinstance.py:2613} INFO - Dependencies all met for dep_context=non-requeueable deps ti=<TaskInstance: fetch_and_store_ebooks.create_table scheduled__2025-01-02T00:00:00+00:00 [queued]>
[2025-01-26T07:22:36.217+0000] {taskinstance.py:2613} INFO - Dependencies all met for dep_context=requeueable deps ti=<TaskInstance: fetch_and_store_ebooks.create_table scheduled__2025-01-02T00:00:00+00:00 [queued]>
[2025-01-26T07:22:36.236+0000] {taskinstance.py:2866} INFO - Starting attempt 1 of 2
[2025-01-26T07:22:38.317+0000] {taskinstance.py:2889} INFO - Executing <Task(PostgresOperator): create_table> on 2025-01-02 00:00:00+00:00
[2025-01-26T07:22:38.440+0000] {warnings.py:112} WARNING - /home/***/.local/lib/python3.12/site-packages/***/task/task_runner/standard_task_runner.py:70: DeprecationWarning: This process (pid=1259) is multi-threaded, use of fork() may lead to deadlocks in the child.
  pid = os.fork()

[2025-01-26T07:22:38.459+0000] {standard_task_runner.py:72} INFO - Started process 1316 to run task
[2025-01-26T07:22:38.460+0000] {standard_task_runner.py:104} INFO - Running: ['***', 'tasks', 'run', 'fetch_and_store_ebooks', 'create_table', 'scheduled__2025-01-02T00:00:00+00:00', '--job-id', '634', '--raw', '--subdir', 'DAGS_FOLDER/app.py', '--cfg-path', '/tmp/tmp3p4nc7p0']
[2025-01-26T07:22:38.501+0000] {standard_task_runner.py:105} INFO - Job 634: Subtask create_table
[2025-01-26T07:22:39.242+0000] {task_command.py:467} INFO - Running <TaskInstance: fetch_and_store_ebooks.create_table scheduled__2025-01-02T00:00:00+00:00 [running]> on host 34edd304782d
[2025-01-26T07:22:40.723+0000] {taskinstance.py:3132} INFO - Exporting env vars: AIRFLOW_CTX_DAG_OWNER='***' AIRFLOW_CTX_DAG_ID='fetch_and_store_ebooks' AIRFLOW_CTX_TASK_ID='create_table' AIRFLOW_CTX_EXECUTION_DATE='2025-01-02T00:00:00+00:00' AIRFLOW_CTX_TRY_NUMBER='1' AIRFLOW_CTX_DAG_RUN_ID='scheduled__2025-01-02T00:00:00+00:00'
[2025-01-26T07:22:40.755+0000] {logging_mixin.py:190} INFO - Task instance is in running state
[2025-01-26T07:22:40.757+0000] {logging_mixin.py:190} INFO -  Previous state of the Task instance: queued
[2025-01-26T07:22:40.762+0000] {logging_mixin.py:190} INFO - Current task name:create_table state:running start_date:2025-01-26 07:22:36.094014+00:00
[2025-01-26T07:22:40.774+0000] {logging_mixin.py:190} INFO - Dag name:fetch_and_store_ebooks and current dag run status:running
[2025-01-26T07:22:40.776+0000] {taskinstance.py:731} INFO - ::endgroup::
[2025-01-26T07:22:40.789+0000] {sql.py:278} INFO - Executing: 
    CREATE TABLE IF NOT EXISTS ebooks (
        id SERIAL PRIMARY KEY,
        judul TEXT NOT NULL,
        penulis TEXT,
        link TEXT
    );
    
[2025-01-26T07:22:40.907+0000] {base.py:84} INFO - Retrieving connection 'ebooks_connection'
[2025-01-26T07:22:40.958+0000] {base.py:84} INFO - Retrieving connection 'ebooks_connection'
[2025-01-26T07:22:41.214+0000] {sql.py:553} INFO - Running statement: 
    CREATE TABLE IF NOT EXISTS ebooks (
        id SERIAL PRIMARY KEY,
        judul TEXT NOT NULL,
        penulis TEXT,
        link TEXT
    );
    , parameters: None
[2025-01-26T07:22:41.235+0000] {taskinstance.py:3311} ERROR - Task failed with exception
Traceback (most recent call last):
  File "/home/airflow/.local/lib/python3.12/site-packages/airflow/models/taskinstance.py", line 767, in _execute_task
    result = _execute_callable(context=context, **execute_callable_kwargs)
             ^^^^^^^^^^^^^^^^^^^^^^^^^^^^^^^^^^^^^^^^^^^^^^^^^^^^^^^^^^^^^
  File "/home/airflow/.local/lib/python3.12/site-packages/airflow/models/taskinstance.py", line 733, in _execute_callable
    return ExecutionCallableRunner(
           ^^^^^^^^^^^^^^^^^^^^^^^^
  File "/home/airflow/.local/lib/python3.12/site-packages/airflow/utils/operator_helpers.py", line 252, in run
    return self.func(*args, **kwargs)
           ^^^^^^^^^^^^^^^^^^^^^^^^^^
  File "/home/airflow/.local/lib/python3.12/site-packages/airflow/models/baseoperator.py", line 422, in wrapper
    return func(self, *args, **kwargs)
           ^^^^^^^^^^^^^^^^^^^^^^^^^^^
  File "/home/airflow/.local/lib/python3.12/site-packages/airflow/providers/common/sql/operators/sql.py", line 284, in execute
    output = hook.run(
             ^^^^^^^^^
  File "/home/airflow/.local/lib/python3.12/site-packages/airflow/providers/common/sql/hooks/sql.py", line 498, in run
    self._run_command(cur, sql_statement, parameters)
  File "/home/airflow/.local/lib/python3.12/site-packages/airflow/providers/common/sql/hooks/sql.py", line 558, in _run_command
    cur.execute(sql_statement)
psycopg2.errors.InsufficientPrivilege: permission denied for schema public
LINE 2:     CREATE TABLE IF NOT EXISTS ebooks (
                                       ^

[2025-01-26T07:22:41.359+0000] {logging_mixin.py:190} INFO - Task instance in failure state
[2025-01-26T07:22:41.369+0000] {logging_mixin.py:190} INFO - Task start:2025-01-26 07:22:36.094014+00:00 end:2025-01-26 07:22:41.356859+00:00 duration:5.262845
[2025-01-26T07:22:41.374+0000] {logging_mixin.py:190} INFO - Task:<Task(PostgresOperator): create_table> dag:<DAG: fetch_and_store_ebooks> dagrun:<DagRun fetch_and_store_ebooks @ 2025-01-02 00:00:00+00:00: scheduled__2025-01-02T00:00:00+00:00, state:running, queued_at: 2025-01-26 07:21:27.584240+00:00. externally triggered: False>
[2025-01-26T07:22:41.376+0000] {logging_mixin.py:190} INFO - Failure caused by permission denied for schema public
LINE 2:     CREATE TABLE IF NOT EXISTS ebooks (
                                       ^
[2025-01-26T07:22:41.382+0000] {taskinstance.py:1225} INFO - Marking task as UP_FOR_RETRY. dag_id=fetch_and_store_ebooks, task_id=create_table, run_id=scheduled__2025-01-02T00:00:00+00:00, execution_date=20250102T000000, start_date=20250126T072236, end_date=20250126T072241
[2025-01-26T07:22:41.638+0000] {taskinstance.py:340} INFO - ::group::Post task execution logs
[2025-01-26T07:22:41.643+0000] {standard_task_runner.py:124} ERROR - Failed to execute job 634 for task create_table (permission denied for schema public
LINE 2:     CREATE TABLE IF NOT EXISTS ebooks (
                                       ^
; 1316)
Traceback (most recent call last):
  File "/home/airflow/.local/lib/python3.12/site-packages/airflow/task/task_runner/standard_task_runner.py", line 117, in _start_by_fork
    ret = args.func(args, dag=self.dag)
          ^^^^^^^^^^^^^^^^^^^^^^^^^^^^^
  File "/home/airflow/.local/lib/python3.12/site-packages/airflow/cli/cli_config.py", line 49, in command
    return func(*args, **kwargs)
           ^^^^^^^^^^^^^^^^^^^^^
  File "/home/airflow/.local/lib/python3.12/site-packages/airflow/utils/cli.py", line 116, in wrapper
    return f(*args, **kwargs)
           ^^^^^^^^^^^^^^^^^^
  File "/home/airflow/.local/lib/python3.12/site-packages/airflow/cli/commands/task_command.py", line 483, in task_run
    task_return_code = _run_task_by_selected_method(args, _dag, ti)
                       ^^^^^^^^^^^^^^^^^^^^^^^^^^^^^^^^^^^^^^^^^^^^
  File "/home/airflow/.local/lib/python3.12/site-packages/airflow/cli/commands/task_command.py", line 256, in _run_task_by_selected_method
    return _run_raw_task(args, ti)
           ^^^^^^^^^^^^^^^^^^^^^^^
  File "/home/airflow/.local/lib/python3.12/site-packages/airflow/cli/commands/task_command.py", line 341, in _run_raw_task
    return ti._run_raw_task(
           ^^^^^^^^^^^^^^^^^
  File "/home/airflow/.local/lib/python3.12/site-packages/airflow/utils/session.py", line 97, in wrapper
    return func(*args, session=session, **kwargs)
           ^^^^^^^^^^^^^^^^^^^^^^^^^^^^^^^^^^^^^^
  File "/home/airflow/.local/lib/python3.12/site-packages/airflow/models/taskinstance.py", line 3005, in _run_raw_task
    return _run_raw_task(
           ^^^^^^^^^^^^^^
  File "/home/airflow/.local/lib/python3.12/site-packages/airflow/models/taskinstance.py", line 273, in _run_raw_task
    TaskInstance._execute_task_with_callbacks(
  File "/home/airflow/.local/lib/python3.12/site-packages/airflow/models/taskinstance.py", line 3159, in _execute_task_with_callbacks
    result = self._execute_task(context, task_orig)
             ^^^^^^^^^^^^^^^^^^^^^^^^^^^^^^^^^^^^^^
  File "/home/airflow/.local/lib/python3.12/site-packages/airflow/models/taskinstance.py", line 3183, in _execute_task
    return _execute_task(self, context, task_orig)
           ^^^^^^^^^^^^^^^^^^^^^^^^^^^^^^^^^^^^^^^
  File "/home/airflow/.local/lib/python3.12/site-packages/airflow/models/taskinstance.py", line 767, in _execute_task
    result = _execute_callable(context=context, **execute_callable_kwargs)
             ^^^^^^^^^^^^^^^^^^^^^^^^^^^^^^^^^^^^^^^^^^^^^^^^^^^^^^^^^^^^^
  File "/home/airflow/.local/lib/python3.12/site-packages/airflow/models/taskinstance.py", line 733, in _execute_callable
    return ExecutionCallableRunner(
           ^^^^^^^^^^^^^^^^^^^^^^^^
  File "/home/airflow/.local/lib/python3.12/site-packages/airflow/utils/operator_helpers.py", line 252, in run
    return self.func(*args, **kwargs)
           ^^^^^^^^^^^^^^^^^^^^^^^^^^
  File "/home/airflow/.local/lib/python3.12/site-packages/airflow/models/baseoperator.py", line 422, in wrapper
    return func(self, *args, **kwargs)
           ^^^^^^^^^^^^^^^^^^^^^^^^^^^
  File "/home/airflow/.local/lib/python3.12/site-packages/airflow/providers/common/sql/operators/sql.py", line 284, in execute
    output = hook.run(
             ^^^^^^^^^
  File "/home/airflow/.local/lib/python3.12/site-packages/airflow/providers/common/sql/hooks/sql.py", line 498, in run
    self._run_command(cur, sql_statement, parameters)
  File "/home/airflow/.local/lib/python3.12/site-packages/airflow/providers/common/sql/hooks/sql.py", line 558, in _run_command
    cur.execute(sql_statement)
psycopg2.errors.InsufficientPrivilege: permission denied for schema public
LINE 2:     CREATE TABLE IF NOT EXISTS ebooks (
                                       ^

[2025-01-26T07:22:41.837+0000] {local_task_job_runner.py:266} INFO - Task exited with return code 1
[2025-01-26T07:22:42.069+0000] {taskinstance.py:3895} INFO - 0 downstream tasks scheduled from follow-on schedule check
[2025-01-26T07:22:42.135+0000] {local_task_job_runner.py:245} INFO - ::endgroup::
[2025-01-26T07:47:55.000+0000] {local_task_job_runner.py:123} INFO - ::group::Pre task execution logs
[2025-01-26T07:47:55.107+0000] {taskinstance.py:2613} INFO - Dependencies all met for dep_context=non-requeueable deps ti=<TaskInstance: fetch_and_store_ebooks.create_table scheduled__2025-01-02T00:00:00+00:00 [queued]>
[2025-01-26T07:47:55.155+0000] {taskinstance.py:2613} INFO - Dependencies all met for dep_context=requeueable deps ti=<TaskInstance: fetch_and_store_ebooks.create_table scheduled__2025-01-02T00:00:00+00:00 [queued]>
[2025-01-26T07:47:55.160+0000] {taskinstance.py:2866} INFO - Starting attempt 1 of 2
[2025-01-26T07:47:55.305+0000] {taskinstance.py:2889} INFO - Executing <Task(PostgresOperator): create_table> on 2025-01-02 00:00:00+00:00
[2025-01-26T07:47:55.371+0000] {warnings.py:112} WARNING - /home/***/.local/lib/python3.12/site-packages/***/task/task_runner/standard_task_runner.py:70: DeprecationWarning: This process (pid=1941) is multi-threaded, use of fork() may lead to deadlocks in the child.
  pid = os.fork()

[2025-01-26T07:47:55.382+0000] {standard_task_runner.py:72} INFO - Started process 1987 to run task
[2025-01-26T07:47:55.467+0000] {standard_task_runner.py:104} INFO - Running: ['***', 'tasks', 'run', 'fetch_and_store_ebooks', 'create_table', 'scheduled__2025-01-02T00:00:00+00:00', '--job-id', '727', '--raw', '--subdir', 'DAGS_FOLDER/app.py', '--cfg-path', '/tmp/tmpmvq24aqv']
[2025-01-26T07:47:55.481+0000] {standard_task_runner.py:105} INFO - Job 727: Subtask create_table
[2025-01-26T07:47:56.060+0000] {task_command.py:467} INFO - Running <TaskInstance: fetch_and_store_ebooks.create_table scheduled__2025-01-02T00:00:00+00:00 [running]> on host 34edd304782d
[2025-01-26T07:47:57.344+0000] {taskinstance.py:3132} INFO - Exporting env vars: AIRFLOW_CTX_DAG_OWNER='***' AIRFLOW_CTX_DAG_ID='fetch_and_store_ebooks' AIRFLOW_CTX_TASK_ID='create_table' AIRFLOW_CTX_EXECUTION_DATE='2025-01-02T00:00:00+00:00' AIRFLOW_CTX_TRY_NUMBER='1' AIRFLOW_CTX_DAG_RUN_ID='scheduled__2025-01-02T00:00:00+00:00'
[2025-01-26T07:47:57.360+0000] {logging_mixin.py:190} INFO - Task instance is in running state
[2025-01-26T07:47:57.415+0000] {logging_mixin.py:190} INFO -  Previous state of the Task instance: queued
[2025-01-26T07:47:57.417+0000] {logging_mixin.py:190} INFO - Current task name:create_table state:running start_date:2025-01-26 07:47:55.112767+00:00
[2025-01-26T07:47:57.421+0000] {logging_mixin.py:190} INFO - Dag name:fetch_and_store_ebooks and current dag run status:running
[2025-01-26T07:47:57.454+0000] {taskinstance.py:731} INFO - ::endgroup::
[2025-01-26T07:47:57.493+0000] {sql.py:278} INFO - Executing: 
    CREATE TABLE IF NOT EXISTS ebooks (
        id SERIAL PRIMARY KEY,
        judul TEXT NOT NULL,
        penulis TEXT,
        link TEXT
    );
    
[2025-01-26T07:47:57.630+0000] {base.py:84} INFO - Retrieving connection 'ebooks_connection'
[2025-01-26T07:47:57.690+0000] {base.py:84} INFO - Retrieving connection 'ebooks_connection'
[2025-01-26T07:47:58.146+0000] {sql.py:553} INFO - Running statement: 
    CREATE TABLE IF NOT EXISTS ebooks (
        id SERIAL PRIMARY KEY,
        judul TEXT NOT NULL,
        penulis TEXT,
        link TEXT
    );
    , parameters: None
[2025-01-26T07:47:58.162+0000] {taskinstance.py:3311} ERROR - Task failed with exception
Traceback (most recent call last):
  File "/home/airflow/.local/lib/python3.12/site-packages/airflow/models/taskinstance.py", line 767, in _execute_task
    result = _execute_callable(context=context, **execute_callable_kwargs)
             ^^^^^^^^^^^^^^^^^^^^^^^^^^^^^^^^^^^^^^^^^^^^^^^^^^^^^^^^^^^^^
  File "/home/airflow/.local/lib/python3.12/site-packages/airflow/models/taskinstance.py", line 733, in _execute_callable
    return ExecutionCallableRunner(
           ^^^^^^^^^^^^^^^^^^^^^^^^
  File "/home/airflow/.local/lib/python3.12/site-packages/airflow/utils/operator_helpers.py", line 252, in run
    return self.func(*args, **kwargs)
           ^^^^^^^^^^^^^^^^^^^^^^^^^^
  File "/home/airflow/.local/lib/python3.12/site-packages/airflow/models/baseoperator.py", line 422, in wrapper
    return func(self, *args, **kwargs)
           ^^^^^^^^^^^^^^^^^^^^^^^^^^^
  File "/home/airflow/.local/lib/python3.12/site-packages/airflow/providers/common/sql/operators/sql.py", line 284, in execute
    output = hook.run(
             ^^^^^^^^^
  File "/home/airflow/.local/lib/python3.12/site-packages/airflow/providers/common/sql/hooks/sql.py", line 498, in run
    self._run_command(cur, sql_statement, parameters)
  File "/home/airflow/.local/lib/python3.12/site-packages/airflow/providers/common/sql/hooks/sql.py", line 558, in _run_command
    cur.execute(sql_statement)
psycopg2.errors.InsufficientPrivilege: permission denied for schema public
LINE 2:     CREATE TABLE IF NOT EXISTS ebooks (
                                       ^

[2025-01-26T07:47:58.426+0000] {logging_mixin.py:190} INFO - Task instance in failure state
[2025-01-26T07:47:58.442+0000] {logging_mixin.py:190} INFO - Task start:2025-01-26 07:47:55.112767+00:00 end:2025-01-26 07:47:58.423563+00:00 duration:3.310796
[2025-01-26T07:47:58.448+0000] {logging_mixin.py:190} INFO - Task:<Task(PostgresOperator): create_table> dag:<DAG: fetch_and_store_ebooks> dagrun:<DagRun fetch_and_store_ebooks @ 2025-01-02 00:00:00+00:00: scheduled__2025-01-02T00:00:00+00:00, state:running, queued_at: 2025-01-26 07:46:48.859807+00:00. externally triggered: False>
[2025-01-26T07:47:58.461+0000] {logging_mixin.py:190} INFO - Failure caused by permission denied for schema public
LINE 2:     CREATE TABLE IF NOT EXISTS ebooks (
                                       ^
[2025-01-26T07:47:58.469+0000] {taskinstance.py:1225} INFO - Marking task as UP_FOR_RETRY. dag_id=fetch_and_store_ebooks, task_id=create_table, run_id=scheduled__2025-01-02T00:00:00+00:00, execution_date=20250102T000000, start_date=20250126T074755, end_date=20250126T074758
[2025-01-26T07:47:58.690+0000] {taskinstance.py:340} INFO - ::group::Post task execution logs
[2025-01-26T07:47:58.706+0000] {standard_task_runner.py:124} ERROR - Failed to execute job 727 for task create_table (permission denied for schema public
LINE 2:     CREATE TABLE IF NOT EXISTS ebooks (
                                       ^
; 1987)
Traceback (most recent call last):
  File "/home/airflow/.local/lib/python3.12/site-packages/airflow/task/task_runner/standard_task_runner.py", line 117, in _start_by_fork
    ret = args.func(args, dag=self.dag)
          ^^^^^^^^^^^^^^^^^^^^^^^^^^^^^
  File "/home/airflow/.local/lib/python3.12/site-packages/airflow/cli/cli_config.py", line 49, in command
    return func(*args, **kwargs)
           ^^^^^^^^^^^^^^^^^^^^^
  File "/home/airflow/.local/lib/python3.12/site-packages/airflow/utils/cli.py", line 116, in wrapper
    return f(*args, **kwargs)
           ^^^^^^^^^^^^^^^^^^
  File "/home/airflow/.local/lib/python3.12/site-packages/airflow/cli/commands/task_command.py", line 483, in task_run
    task_return_code = _run_task_by_selected_method(args, _dag, ti)
                       ^^^^^^^^^^^^^^^^^^^^^^^^^^^^^^^^^^^^^^^^^^^^
  File "/home/airflow/.local/lib/python3.12/site-packages/airflow/cli/commands/task_command.py", line 256, in _run_task_by_selected_method
    return _run_raw_task(args, ti)
           ^^^^^^^^^^^^^^^^^^^^^^^
  File "/home/airflow/.local/lib/python3.12/site-packages/airflow/cli/commands/task_command.py", line 341, in _run_raw_task
    return ti._run_raw_task(
           ^^^^^^^^^^^^^^^^^
  File "/home/airflow/.local/lib/python3.12/site-packages/airflow/utils/session.py", line 97, in wrapper
    return func(*args, session=session, **kwargs)
           ^^^^^^^^^^^^^^^^^^^^^^^^^^^^^^^^^^^^^^
  File "/home/airflow/.local/lib/python3.12/site-packages/airflow/models/taskinstance.py", line 3005, in _run_raw_task
    return _run_raw_task(
           ^^^^^^^^^^^^^^
  File "/home/airflow/.local/lib/python3.12/site-packages/airflow/models/taskinstance.py", line 273, in _run_raw_task
    TaskInstance._execute_task_with_callbacks(
  File "/home/airflow/.local/lib/python3.12/site-packages/airflow/models/taskinstance.py", line 3159, in _execute_task_with_callbacks
    result = self._execute_task(context, task_orig)
             ^^^^^^^^^^^^^^^^^^^^^^^^^^^^^^^^^^^^^^
  File "/home/airflow/.local/lib/python3.12/site-packages/airflow/models/taskinstance.py", line 3183, in _execute_task
    return _execute_task(self, context, task_orig)
           ^^^^^^^^^^^^^^^^^^^^^^^^^^^^^^^^^^^^^^^
  File "/home/airflow/.local/lib/python3.12/site-packages/airflow/models/taskinstance.py", line 767, in _execute_task
    result = _execute_callable(context=context, **execute_callable_kwargs)
             ^^^^^^^^^^^^^^^^^^^^^^^^^^^^^^^^^^^^^^^^^^^^^^^^^^^^^^^^^^^^^
  File "/home/airflow/.local/lib/python3.12/site-packages/airflow/models/taskinstance.py", line 733, in _execute_callable
    return ExecutionCallableRunner(
           ^^^^^^^^^^^^^^^^^^^^^^^^
  File "/home/airflow/.local/lib/python3.12/site-packages/airflow/utils/operator_helpers.py", line 252, in run
    return self.func(*args, **kwargs)
           ^^^^^^^^^^^^^^^^^^^^^^^^^^
  File "/home/airflow/.local/lib/python3.12/site-packages/airflow/models/baseoperator.py", line 422, in wrapper
    return func(self, *args, **kwargs)
           ^^^^^^^^^^^^^^^^^^^^^^^^^^^
  File "/home/airflow/.local/lib/python3.12/site-packages/airflow/providers/common/sql/operators/sql.py", line 284, in execute
    output = hook.run(
             ^^^^^^^^^
  File "/home/airflow/.local/lib/python3.12/site-packages/airflow/providers/common/sql/hooks/sql.py", line 498, in run
    self._run_command(cur, sql_statement, parameters)
  File "/home/airflow/.local/lib/python3.12/site-packages/airflow/providers/common/sql/hooks/sql.py", line 558, in _run_command
    cur.execute(sql_statement)
psycopg2.errors.InsufficientPrivilege: permission denied for schema public
LINE 2:     CREATE TABLE IF NOT EXISTS ebooks (
                                       ^

[2025-01-26T07:47:58.826+0000] {local_task_job_runner.py:266} INFO - Task exited with return code 1
[2025-01-26T07:47:59.081+0000] {taskinstance.py:3895} INFO - 0 downstream tasks scheduled from follow-on schedule check
[2025-01-26T07:47:59.100+0000] {local_task_job_runner.py:245} INFO - ::endgroup::
[2025-01-26T08:52:22.280+0000] {local_task_job_runner.py:123} INFO - ::group::Pre task execution logs
[2025-01-26T08:52:22.732+0000] {taskinstance.py:2613} INFO - Dependencies all met for dep_context=non-requeueable deps ti=<TaskInstance: fetch_and_store_ebooks.create_table scheduled__2025-01-02T00:00:00+00:00 [queued]>
[2025-01-26T08:52:22.922+0000] {taskinstance.py:2613} INFO - Dependencies all met for dep_context=requeueable deps ti=<TaskInstance: fetch_and_store_ebooks.create_table scheduled__2025-01-02T00:00:00+00:00 [queued]>
[2025-01-26T08:52:22.936+0000] {taskinstance.py:2866} INFO - Starting attempt 1 of 2
[2025-01-26T08:52:23.288+0000] {taskinstance.py:2889} INFO - Executing <Task(PostgresOperator): create_table> on 2025-01-02 00:00:00+00:00
[2025-01-26T08:52:23.385+0000] {warnings.py:112} WARNING - /home/***/.local/lib/python3.12/site-packages/***/task/task_runner/standard_task_runner.py:70: DeprecationWarning: This process (pid=3258) is multi-threaded, use of fork() may lead to deadlocks in the child.
  pid = os.fork()

[2025-01-26T08:52:23.455+0000] {standard_task_runner.py:72} INFO - Started process 3303 to run task
[2025-01-26T08:52:23.507+0000] {standard_task_runner.py:104} INFO - Running: ['***', 'tasks', 'run', 'fetch_and_store_ebooks', 'create_table', 'scheduled__2025-01-02T00:00:00+00:00', '--job-id', '890', '--raw', '--subdir', 'DAGS_FOLDER/app.py', '--cfg-path', '/tmp/tmpmqophlis']
[2025-01-26T08:52:23.539+0000] {standard_task_runner.py:105} INFO - Job 890: Subtask create_table
[2025-01-26T08:52:25.052+0000] {task_command.py:467} INFO - Running <TaskInstance: fetch_and_store_ebooks.create_table scheduled__2025-01-02T00:00:00+00:00 [running]> on host 34edd304782d
[2025-01-26T08:52:26.471+0000] {taskinstance.py:3132} INFO - Exporting env vars: AIRFLOW_CTX_DAG_OWNER='***' AIRFLOW_CTX_DAG_ID='fetch_and_store_ebooks' AIRFLOW_CTX_TASK_ID='create_table' AIRFLOW_CTX_EXECUTION_DATE='2025-01-02T00:00:00+00:00' AIRFLOW_CTX_TRY_NUMBER='1' AIRFLOW_CTX_DAG_RUN_ID='scheduled__2025-01-02T00:00:00+00:00'
[2025-01-26T08:52:26.516+0000] {logging_mixin.py:190} INFO - Task instance is in running state
[2025-01-26T08:52:26.578+0000] {logging_mixin.py:190} INFO -  Previous state of the Task instance: queued
[2025-01-26T08:52:26.595+0000] {logging_mixin.py:190} INFO - Current task name:create_table state:running start_date:2025-01-26 08:52:22.756988+00:00
[2025-01-26T08:52:26.611+0000] {logging_mixin.py:190} INFO - Dag name:fetch_and_store_ebooks and current dag run status:running
[2025-01-26T08:52:26.613+0000] {taskinstance.py:731} INFO - ::endgroup::
[2025-01-26T08:52:26.653+0000] {sql.py:278} INFO - Executing: 
    CREATE TABLE IF NOT EXISTS ebooks (
        id SERIAL PRIMARY KEY,
        judul TEXT NOT NULL,
        penulis TEXT,
        link TEXT
    );
    
[2025-01-26T08:52:27.111+0000] {base.py:84} INFO - Retrieving connection 'ebooks_connection'
[2025-01-26T08:52:27.255+0000] {base.py:84} INFO - Retrieving connection 'ebooks_connection'
[2025-01-26T08:52:27.611+0000] {sql.py:553} INFO - Running statement: 
    CREATE TABLE IF NOT EXISTS ebooks (
        id SERIAL PRIMARY KEY,
        judul TEXT NOT NULL,
        penulis TEXT,
        link TEXT
    );
    , parameters: None
[2025-01-26T08:52:27.641+0000] {taskinstance.py:3311} ERROR - Task failed with exception
Traceback (most recent call last):
  File "/home/airflow/.local/lib/python3.12/site-packages/airflow/models/taskinstance.py", line 767, in _execute_task
    result = _execute_callable(context=context, **execute_callable_kwargs)
             ^^^^^^^^^^^^^^^^^^^^^^^^^^^^^^^^^^^^^^^^^^^^^^^^^^^^^^^^^^^^^
  File "/home/airflow/.local/lib/python3.12/site-packages/airflow/models/taskinstance.py", line 733, in _execute_callable
    return ExecutionCallableRunner(
           ^^^^^^^^^^^^^^^^^^^^^^^^
  File "/home/airflow/.local/lib/python3.12/site-packages/airflow/utils/operator_helpers.py", line 252, in run
    return self.func(*args, **kwargs)
           ^^^^^^^^^^^^^^^^^^^^^^^^^^
  File "/home/airflow/.local/lib/python3.12/site-packages/airflow/models/baseoperator.py", line 422, in wrapper
    return func(self, *args, **kwargs)
           ^^^^^^^^^^^^^^^^^^^^^^^^^^^
  File "/home/airflow/.local/lib/python3.12/site-packages/airflow/providers/common/sql/operators/sql.py", line 284, in execute
    output = hook.run(
             ^^^^^^^^^
  File "/home/airflow/.local/lib/python3.12/site-packages/airflow/providers/common/sql/hooks/sql.py", line 498, in run
    self._run_command(cur, sql_statement, parameters)
  File "/home/airflow/.local/lib/python3.12/site-packages/airflow/providers/common/sql/hooks/sql.py", line 558, in _run_command
    cur.execute(sql_statement)
psycopg2.errors.InsufficientPrivilege: permission denied for schema public
LINE 2:     CREATE TABLE IF NOT EXISTS ebooks (
                                       ^

[2025-01-26T08:52:27.922+0000] {logging_mixin.py:190} INFO - Task instance in failure state
[2025-01-26T08:52:27.939+0000] {logging_mixin.py:190} INFO - Task start:2025-01-26 08:52:22.756988+00:00 end:2025-01-26 08:52:27.919413+00:00 duration:5.162425
[2025-01-26T08:52:27.948+0000] {logging_mixin.py:190} INFO - Task:<Task(PostgresOperator): create_table> dag:<DAG: fetch_and_store_ebooks> dagrun:<DagRun fetch_and_store_ebooks @ 2025-01-02 00:00:00+00:00: scheduled__2025-01-02T00:00:00+00:00, state:running, queued_at: 2025-01-26 08:50:51.168346+00:00. externally triggered: False>
[2025-01-26T08:52:27.978+0000] {logging_mixin.py:190} INFO - Failure caused by permission denied for schema public
LINE 2:     CREATE TABLE IF NOT EXISTS ebooks (
                                       ^
[2025-01-26T08:52:27.980+0000] {taskinstance.py:1225} INFO - Marking task as UP_FOR_RETRY. dag_id=fetch_and_store_ebooks, task_id=create_table, run_id=scheduled__2025-01-02T00:00:00+00:00, execution_date=20250102T000000, start_date=20250126T085222, end_date=20250126T085227
[2025-01-26T08:52:28.255+0000] {taskinstance.py:340} INFO - ::group::Post task execution logs
[2025-01-26T08:52:28.258+0000] {standard_task_runner.py:124} ERROR - Failed to execute job 890 for task create_table (permission denied for schema public
LINE 2:     CREATE TABLE IF NOT EXISTS ebooks (
                                       ^
; 3303)
Traceback (most recent call last):
  File "/home/airflow/.local/lib/python3.12/site-packages/airflow/task/task_runner/standard_task_runner.py", line 117, in _start_by_fork
    ret = args.func(args, dag=self.dag)
          ^^^^^^^^^^^^^^^^^^^^^^^^^^^^^
  File "/home/airflow/.local/lib/python3.12/site-packages/airflow/cli/cli_config.py", line 49, in command
    return func(*args, **kwargs)
           ^^^^^^^^^^^^^^^^^^^^^
  File "/home/airflow/.local/lib/python3.12/site-packages/airflow/utils/cli.py", line 116, in wrapper
    return f(*args, **kwargs)
           ^^^^^^^^^^^^^^^^^^
  File "/home/airflow/.local/lib/python3.12/site-packages/airflow/cli/commands/task_command.py", line 483, in task_run
    task_return_code = _run_task_by_selected_method(args, _dag, ti)
                       ^^^^^^^^^^^^^^^^^^^^^^^^^^^^^^^^^^^^^^^^^^^^
  File "/home/airflow/.local/lib/python3.12/site-packages/airflow/cli/commands/task_command.py", line 256, in _run_task_by_selected_method
    return _run_raw_task(args, ti)
           ^^^^^^^^^^^^^^^^^^^^^^^
  File "/home/airflow/.local/lib/python3.12/site-packages/airflow/cli/commands/task_command.py", line 341, in _run_raw_task
    return ti._run_raw_task(
           ^^^^^^^^^^^^^^^^^
  File "/home/airflow/.local/lib/python3.12/site-packages/airflow/utils/session.py", line 97, in wrapper
    return func(*args, session=session, **kwargs)
           ^^^^^^^^^^^^^^^^^^^^^^^^^^^^^^^^^^^^^^
  File "/home/airflow/.local/lib/python3.12/site-packages/airflow/models/taskinstance.py", line 3005, in _run_raw_task
    return _run_raw_task(
           ^^^^^^^^^^^^^^
  File "/home/airflow/.local/lib/python3.12/site-packages/airflow/models/taskinstance.py", line 273, in _run_raw_task
    TaskInstance._execute_task_with_callbacks(
  File "/home/airflow/.local/lib/python3.12/site-packages/airflow/models/taskinstance.py", line 3159, in _execute_task_with_callbacks
    result = self._execute_task(context, task_orig)
             ^^^^^^^^^^^^^^^^^^^^^^^^^^^^^^^^^^^^^^
  File "/home/airflow/.local/lib/python3.12/site-packages/airflow/models/taskinstance.py", line 3183, in _execute_task
    return _execute_task(self, context, task_orig)
           ^^^^^^^^^^^^^^^^^^^^^^^^^^^^^^^^^^^^^^^
  File "/home/airflow/.local/lib/python3.12/site-packages/airflow/models/taskinstance.py", line 767, in _execute_task
    result = _execute_callable(context=context, **execute_callable_kwargs)
             ^^^^^^^^^^^^^^^^^^^^^^^^^^^^^^^^^^^^^^^^^^^^^^^^^^^^^^^^^^^^^
  File "/home/airflow/.local/lib/python3.12/site-packages/airflow/models/taskinstance.py", line 733, in _execute_callable
    return ExecutionCallableRunner(
           ^^^^^^^^^^^^^^^^^^^^^^^^
  File "/home/airflow/.local/lib/python3.12/site-packages/airflow/utils/operator_helpers.py", line 252, in run
    return self.func(*args, **kwargs)
           ^^^^^^^^^^^^^^^^^^^^^^^^^^
  File "/home/airflow/.local/lib/python3.12/site-packages/airflow/models/baseoperator.py", line 422, in wrapper
    return func(self, *args, **kwargs)
           ^^^^^^^^^^^^^^^^^^^^^^^^^^^
  File "/home/airflow/.local/lib/python3.12/site-packages/airflow/providers/common/sql/operators/sql.py", line 284, in execute
    output = hook.run(
             ^^^^^^^^^
  File "/home/airflow/.local/lib/python3.12/site-packages/airflow/providers/common/sql/hooks/sql.py", line 498, in run
    self._run_command(cur, sql_statement, parameters)
  File "/home/airflow/.local/lib/python3.12/site-packages/airflow/providers/common/sql/hooks/sql.py", line 558, in _run_command
    cur.execute(sql_statement)
psycopg2.errors.InsufficientPrivilege: permission denied for schema public
LINE 2:     CREATE TABLE IF NOT EXISTS ebooks (
                                       ^

[2025-01-26T08:52:28.508+0000] {local_task_job_runner.py:266} INFO - Task exited with return code 1
[2025-01-26T08:52:28.548+0000] {standard_task_runner.py:217} INFO - Process not found (most likely exited), stop collecting metrics
[2025-01-26T08:52:29.028+0000] {taskinstance.py:3895} INFO - 0 downstream tasks scheduled from follow-on schedule check
[2025-01-26T08:52:29.110+0000] {local_task_job_runner.py:245} INFO - ::endgroup::
[2025-01-26T08:59:05.604+0000] {local_task_job_runner.py:123} INFO - ::group::Pre task execution logs
[2025-01-26T08:59:05.834+0000] {taskinstance.py:2613} INFO - Dependencies all met for dep_context=non-requeueable deps ti=<TaskInstance: fetch_and_store_ebooks.create_table scheduled__2025-01-02T00:00:00+00:00 [queued]>
[2025-01-26T08:59:05.987+0000] {taskinstance.py:2613} INFO - Dependencies all met for dep_context=requeueable deps ti=<TaskInstance: fetch_and_store_ebooks.create_table scheduled__2025-01-02T00:00:00+00:00 [queued]>
[2025-01-26T08:59:06.015+0000] {taskinstance.py:2866} INFO - Starting attempt 1 of 2
[2025-01-26T08:59:06.446+0000] {taskinstance.py:2889} INFO - Executing <Task(PostgresOperator): create_table> on 2025-01-02 00:00:00+00:00
[2025-01-26T08:59:06.576+0000] {warnings.py:112} WARNING - /home/***/.local/lib/python3.12/site-packages/***/task/task_runner/standard_task_runner.py:70: DeprecationWarning: This process (pid=3443) is multi-threaded, use of fork() may lead to deadlocks in the child.
  pid = os.fork()

[2025-01-26T08:59:06.534+0000] {standard_task_runner.py:104} INFO - Running: ['***', 'tasks', 'run', 'fetch_and_store_ebooks', 'create_table', 'scheduled__2025-01-02T00:00:00+00:00', '--job-id', '919', '--raw', '--subdir', 'DAGS_FOLDER/app.py', '--cfg-path', '/tmp/tmpvxtg7nq7']
[2025-01-26T08:59:06.617+0000] {standard_task_runner.py:105} INFO - Job 919: Subtask create_table
[2025-01-26T08:59:06.615+0000] {standard_task_runner.py:72} INFO - Started process 3498 to run task
[2025-01-26T08:59:07.371+0000] {task_command.py:467} INFO - Running <TaskInstance: fetch_and_store_ebooks.create_table scheduled__2025-01-02T00:00:00+00:00 [running]> on host 34edd304782d
[2025-01-26T08:59:10.208+0000] {taskinstance.py:3132} INFO - Exporting env vars: AIRFLOW_CTX_DAG_OWNER='***' AIRFLOW_CTX_DAG_ID='fetch_and_store_ebooks' AIRFLOW_CTX_TASK_ID='create_table' AIRFLOW_CTX_EXECUTION_DATE='2025-01-02T00:00:00+00:00' AIRFLOW_CTX_TRY_NUMBER='1' AIRFLOW_CTX_DAG_RUN_ID='scheduled__2025-01-02T00:00:00+00:00'
[2025-01-26T08:59:10.229+0000] {logging_mixin.py:190} INFO - Task instance is in running state
[2025-01-26T08:59:10.245+0000] {logging_mixin.py:190} INFO -  Previous state of the Task instance: queued
[2025-01-26T08:59:10.255+0000] {logging_mixin.py:190} INFO - Current task name:create_table state:running start_date:2025-01-26 08:59:05.843331+00:00
[2025-01-26T08:59:10.257+0000] {logging_mixin.py:190} INFO - Dag name:fetch_and_store_ebooks and current dag run status:running
[2025-01-26T08:59:10.259+0000] {taskinstance.py:731} INFO - ::endgroup::
[2025-01-26T08:59:10.261+0000] {sql.py:278} INFO - Executing: 
    CREATE TABLE IF NOT EXISTS ebooks (
        id SERIAL PRIMARY KEY,
        judul TEXT NOT NULL,
        penulis TEXT,
        link TEXT
    );
    
[2025-01-26T08:59:10.364+0000] {base.py:84} INFO - Retrieving connection 'ebooks_connection'
[2025-01-26T08:59:10.479+0000] {base.py:84} INFO - Retrieving connection 'ebooks_connection'
[2025-01-26T08:59:10.718+0000] {sql.py:553} INFO - Running statement: 
    CREATE TABLE IF NOT EXISTS ebooks (
        id SERIAL PRIMARY KEY,
        judul TEXT NOT NULL,
        penulis TEXT,
        link TEXT
    );
    , parameters: None
[2025-01-26T08:59:10.753+0000] {taskinstance.py:3311} ERROR - Task failed with exception
Traceback (most recent call last):
  File "/home/airflow/.local/lib/python3.12/site-packages/airflow/models/taskinstance.py", line 767, in _execute_task
    result = _execute_callable(context=context, **execute_callable_kwargs)
             ^^^^^^^^^^^^^^^^^^^^^^^^^^^^^^^^^^^^^^^^^^^^^^^^^^^^^^^^^^^^^
  File "/home/airflow/.local/lib/python3.12/site-packages/airflow/models/taskinstance.py", line 733, in _execute_callable
    return ExecutionCallableRunner(
           ^^^^^^^^^^^^^^^^^^^^^^^^
  File "/home/airflow/.local/lib/python3.12/site-packages/airflow/utils/operator_helpers.py", line 252, in run
    return self.func(*args, **kwargs)
           ^^^^^^^^^^^^^^^^^^^^^^^^^^
  File "/home/airflow/.local/lib/python3.12/site-packages/airflow/models/baseoperator.py", line 422, in wrapper
    return func(self, *args, **kwargs)
           ^^^^^^^^^^^^^^^^^^^^^^^^^^^
  File "/home/airflow/.local/lib/python3.12/site-packages/airflow/providers/common/sql/operators/sql.py", line 284, in execute
    output = hook.run(
             ^^^^^^^^^
  File "/home/airflow/.local/lib/python3.12/site-packages/airflow/providers/common/sql/hooks/sql.py", line 498, in run
    self._run_command(cur, sql_statement, parameters)
  File "/home/airflow/.local/lib/python3.12/site-packages/airflow/providers/common/sql/hooks/sql.py", line 558, in _run_command
    cur.execute(sql_statement)
psycopg2.errors.InsufficientPrivilege: permission denied for schema public
LINE 2:     CREATE TABLE IF NOT EXISTS ebooks (
                                       ^

[2025-01-26T08:59:10.943+0000] {logging_mixin.py:190} INFO - Task instance in failure state
[2025-01-26T08:59:10.953+0000] {logging_mixin.py:190} INFO - Task start:2025-01-26 08:59:05.843331+00:00 end:2025-01-26 08:59:10.938078+00:00 duration:5.094747
[2025-01-26T08:59:10.978+0000] {logging_mixin.py:190} INFO - Task:<Task(PostgresOperator): create_table> dag:<DAG: fetch_and_store_ebooks> dagrun:<DagRun fetch_and_store_ebooks @ 2025-01-02 00:00:00+00:00: scheduled__2025-01-02T00:00:00+00:00, state:running, queued_at: 2025-01-26 08:57:44.404093+00:00. externally triggered: False>
[2025-01-26T08:59:10.982+0000] {logging_mixin.py:190} INFO - Failure caused by permission denied for schema public
LINE 2:     CREATE TABLE IF NOT EXISTS ebooks (
                                       ^
[2025-01-26T08:59:10.990+0000] {taskinstance.py:1225} INFO - Marking task as UP_FOR_RETRY. dag_id=fetch_and_store_ebooks, task_id=create_table, run_id=scheduled__2025-01-02T00:00:00+00:00, execution_date=20250102T000000, start_date=20250126T085905, end_date=20250126T085910
[2025-01-26T08:59:11.695+0000] {taskinstance.py:340} INFO - ::group::Post task execution logs
[2025-01-26T08:59:11.711+0000] {standard_task_runner.py:124} ERROR - Failed to execute job 919 for task create_table (permission denied for schema public
LINE 2:     CREATE TABLE IF NOT EXISTS ebooks (
                                       ^
; 3498)
Traceback (most recent call last):
  File "/home/airflow/.local/lib/python3.12/site-packages/airflow/task/task_runner/standard_task_runner.py", line 117, in _start_by_fork
    ret = args.func(args, dag=self.dag)
          ^^^^^^^^^^^^^^^^^^^^^^^^^^^^^
  File "/home/airflow/.local/lib/python3.12/site-packages/airflow/cli/cli_config.py", line 49, in command
    return func(*args, **kwargs)
           ^^^^^^^^^^^^^^^^^^^^^
  File "/home/airflow/.local/lib/python3.12/site-packages/airflow/utils/cli.py", line 116, in wrapper
    return f(*args, **kwargs)
           ^^^^^^^^^^^^^^^^^^
  File "/home/airflow/.local/lib/python3.12/site-packages/airflow/cli/commands/task_command.py", line 483, in task_run
    task_return_code = _run_task_by_selected_method(args, _dag, ti)
                       ^^^^^^^^^^^^^^^^^^^^^^^^^^^^^^^^^^^^^^^^^^^^
  File "/home/airflow/.local/lib/python3.12/site-packages/airflow/cli/commands/task_command.py", line 256, in _run_task_by_selected_method
    return _run_raw_task(args, ti)
           ^^^^^^^^^^^^^^^^^^^^^^^
  File "/home/airflow/.local/lib/python3.12/site-packages/airflow/cli/commands/task_command.py", line 341, in _run_raw_task
    return ti._run_raw_task(
           ^^^^^^^^^^^^^^^^^
  File "/home/airflow/.local/lib/python3.12/site-packages/airflow/utils/session.py", line 97, in wrapper
    return func(*args, session=session, **kwargs)
           ^^^^^^^^^^^^^^^^^^^^^^^^^^^^^^^^^^^^^^
  File "/home/airflow/.local/lib/python3.12/site-packages/airflow/models/taskinstance.py", line 3005, in _run_raw_task
    return _run_raw_task(
           ^^^^^^^^^^^^^^
  File "/home/airflow/.local/lib/python3.12/site-packages/airflow/models/taskinstance.py", line 273, in _run_raw_task
    TaskInstance._execute_task_with_callbacks(
  File "/home/airflow/.local/lib/python3.12/site-packages/airflow/models/taskinstance.py", line 3159, in _execute_task_with_callbacks
    result = self._execute_task(context, task_orig)
             ^^^^^^^^^^^^^^^^^^^^^^^^^^^^^^^^^^^^^^
  File "/home/airflow/.local/lib/python3.12/site-packages/airflow/models/taskinstance.py", line 3183, in _execute_task
    return _execute_task(self, context, task_orig)
           ^^^^^^^^^^^^^^^^^^^^^^^^^^^^^^^^^^^^^^^
  File "/home/airflow/.local/lib/python3.12/site-packages/airflow/models/taskinstance.py", line 767, in _execute_task
    result = _execute_callable(context=context, **execute_callable_kwargs)
             ^^^^^^^^^^^^^^^^^^^^^^^^^^^^^^^^^^^^^^^^^^^^^^^^^^^^^^^^^^^^^
  File "/home/airflow/.local/lib/python3.12/site-packages/airflow/models/taskinstance.py", line 733, in _execute_callable
    return ExecutionCallableRunner(
           ^^^^^^^^^^^^^^^^^^^^^^^^
  File "/home/airflow/.local/lib/python3.12/site-packages/airflow/utils/operator_helpers.py", line 252, in run
    return self.func(*args, **kwargs)
           ^^^^^^^^^^^^^^^^^^^^^^^^^^
  File "/home/airflow/.local/lib/python3.12/site-packages/airflow/models/baseoperator.py", line 422, in wrapper
    return func(self, *args, **kwargs)
           ^^^^^^^^^^^^^^^^^^^^^^^^^^^
  File "/home/airflow/.local/lib/python3.12/site-packages/airflow/providers/common/sql/operators/sql.py", line 284, in execute
    output = hook.run(
             ^^^^^^^^^
  File "/home/airflow/.local/lib/python3.12/site-packages/airflow/providers/common/sql/hooks/sql.py", line 498, in run
    self._run_command(cur, sql_statement, parameters)
  File "/home/airflow/.local/lib/python3.12/site-packages/airflow/providers/common/sql/hooks/sql.py", line 558, in _run_command
    cur.execute(sql_statement)
psycopg2.errors.InsufficientPrivilege: permission denied for schema public
LINE 2:     CREATE TABLE IF NOT EXISTS ebooks (
                                       ^

[2025-01-26T08:59:12.137+0000] {local_task_job_runner.py:266} INFO - Task exited with return code 1
[2025-01-26T08:59:12.311+0000] {taskinstance.py:3895} INFO - 0 downstream tasks scheduled from follow-on schedule check
[2025-01-26T08:59:12.343+0000] {local_task_job_runner.py:245} INFO - ::endgroup::
[2025-01-26T09:06:08.905+0000] {local_task_job_runner.py:123} INFO - ::group::Pre task execution logs
[2025-01-26T09:06:09.074+0000] {taskinstance.py:2613} INFO - Dependencies all met for dep_context=non-requeueable deps ti=<TaskInstance: fetch_and_store_ebooks.create_table scheduled__2025-01-02T00:00:00+00:00 [queued]>
[2025-01-26T09:06:09.138+0000] {taskinstance.py:2613} INFO - Dependencies all met for dep_context=requeueable deps ti=<TaskInstance: fetch_and_store_ebooks.create_table scheduled__2025-01-02T00:00:00+00:00 [queued]>
[2025-01-26T09:06:09.156+0000] {taskinstance.py:2866} INFO - Starting attempt 1 of 2
[2025-01-26T09:06:09.465+0000] {taskinstance.py:2889} INFO - Executing <Task(PostgresOperator): create_table> on 2025-01-02 00:00:00+00:00
[2025-01-26T09:06:09.575+0000] {warnings.py:112} WARNING - /home/***/.local/lib/python3.12/site-packages/***/task/task_runner/standard_task_runner.py:70: DeprecationWarning: This process (pid=3652) is multi-threaded, use of fork() may lead to deadlocks in the child.
  pid = os.fork()

[2025-01-26T09:06:09.595+0000] {standard_task_runner.py:72} INFO - Started process 3697 to run task
[2025-01-26T09:06:09.621+0000] {standard_task_runner.py:104} INFO - Running: ['***', 'tasks', 'run', 'fetch_and_store_ebooks', 'create_table', 'scheduled__2025-01-02T00:00:00+00:00', '--job-id', '951', '--raw', '--subdir', 'DAGS_FOLDER/app.py', '--cfg-path', '/tmp/tmpletxsc7x']
[2025-01-26T09:06:09.674+0000] {standard_task_runner.py:105} INFO - Job 951: Subtask create_table
[2025-01-26T09:06:10.319+0000] {task_command.py:467} INFO - Running <TaskInstance: fetch_and_store_ebooks.create_table scheduled__2025-01-02T00:00:00+00:00 [running]> on host 34edd304782d
[2025-01-26T09:06:11.545+0000] {taskinstance.py:3132} INFO - Exporting env vars: AIRFLOW_CTX_DAG_OWNER='***' AIRFLOW_CTX_DAG_ID='fetch_and_store_ebooks' AIRFLOW_CTX_TASK_ID='create_table' AIRFLOW_CTX_EXECUTION_DATE='2025-01-02T00:00:00+00:00' AIRFLOW_CTX_TRY_NUMBER='1' AIRFLOW_CTX_DAG_RUN_ID='scheduled__2025-01-02T00:00:00+00:00'
[2025-01-26T09:06:11.552+0000] {logging_mixin.py:190} INFO - Task instance is in running state
[2025-01-26T09:06:11.564+0000] {logging_mixin.py:190} INFO -  Previous state of the Task instance: queued
[2025-01-26T09:06:11.567+0000] {logging_mixin.py:190} INFO - Current task name:create_table state:running start_date:2025-01-26 09:06:09.078479+00:00
[2025-01-26T09:06:11.569+0000] {logging_mixin.py:190} INFO - Dag name:fetch_and_store_ebooks and current dag run status:running
[2025-01-26T09:06:11.578+0000] {taskinstance.py:731} INFO - ::endgroup::
[2025-01-26T09:06:11.581+0000] {sql.py:278} INFO - Executing: 
    CREATE TABLE IF NOT EXISTS ebooks (
        id SERIAL PRIMARY KEY,
        judul TEXT NOT NULL,
        penulis TEXT,
        link TEXT
    );
    
[2025-01-26T09:06:11.704+0000] {base.py:84} INFO - Retrieving connection 'ebooks_connection'
[2025-01-26T09:06:11.746+0000] {base.py:84} INFO - Retrieving connection 'ebooks_connection'
[2025-01-26T09:06:12.014+0000] {sql.py:553} INFO - Running statement: 
    CREATE TABLE IF NOT EXISTS ebooks (
        id SERIAL PRIMARY KEY,
        judul TEXT NOT NULL,
        penulis TEXT,
        link TEXT
    );
    , parameters: None
[2025-01-26T09:06:12.026+0000] {taskinstance.py:3311} ERROR - Task failed with exception
Traceback (most recent call last):
  File "/home/airflow/.local/lib/python3.12/site-packages/airflow/models/taskinstance.py", line 767, in _execute_task
    result = _execute_callable(context=context, **execute_callable_kwargs)
             ^^^^^^^^^^^^^^^^^^^^^^^^^^^^^^^^^^^^^^^^^^^^^^^^^^^^^^^^^^^^^
  File "/home/airflow/.local/lib/python3.12/site-packages/airflow/models/taskinstance.py", line 733, in _execute_callable
    return ExecutionCallableRunner(
           ^^^^^^^^^^^^^^^^^^^^^^^^
  File "/home/airflow/.local/lib/python3.12/site-packages/airflow/utils/operator_helpers.py", line 252, in run
    return self.func(*args, **kwargs)
           ^^^^^^^^^^^^^^^^^^^^^^^^^^
  File "/home/airflow/.local/lib/python3.12/site-packages/airflow/models/baseoperator.py", line 422, in wrapper
    return func(self, *args, **kwargs)
           ^^^^^^^^^^^^^^^^^^^^^^^^^^^
  File "/home/airflow/.local/lib/python3.12/site-packages/airflow/providers/common/sql/operators/sql.py", line 284, in execute
    output = hook.run(
             ^^^^^^^^^
  File "/home/airflow/.local/lib/python3.12/site-packages/airflow/providers/common/sql/hooks/sql.py", line 498, in run
    self._run_command(cur, sql_statement, parameters)
  File "/home/airflow/.local/lib/python3.12/site-packages/airflow/providers/common/sql/hooks/sql.py", line 558, in _run_command
    cur.execute(sql_statement)
psycopg2.errors.InsufficientPrivilege: permission denied for schema public
LINE 2:     CREATE TABLE IF NOT EXISTS ebooks (
                                       ^

[2025-01-26T09:06:12.127+0000] {logging_mixin.py:190} INFO - Task instance in failure state
[2025-01-26T09:06:12.145+0000] {logging_mixin.py:190} INFO - Task start:2025-01-26 09:06:09.078479+00:00 end:2025-01-26 09:06:12.119809+00:00 duration:3.04133
[2025-01-26T09:06:12.151+0000] {logging_mixin.py:190} INFO - Task:<Task(PostgresOperator): create_table> dag:<DAG: fetch_and_store_ebooks> dagrun:<DagRun fetch_and_store_ebooks @ 2025-01-02 00:00:00+00:00: scheduled__2025-01-02T00:00:00+00:00, state:running, queued_at: 2025-01-26 09:04:51.553939+00:00. externally triggered: False>
[2025-01-26T09:06:12.153+0000] {logging_mixin.py:190} INFO - Failure caused by permission denied for schema public
LINE 2:     CREATE TABLE IF NOT EXISTS ebooks (
                                       ^
[2025-01-26T09:06:12.155+0000] {taskinstance.py:1225} INFO - Marking task as UP_FOR_RETRY. dag_id=fetch_and_store_ebooks, task_id=create_table, run_id=scheduled__2025-01-02T00:00:00+00:00, execution_date=20250102T000000, start_date=20250126T090609, end_date=20250126T090612
[2025-01-26T09:06:12.927+0000] {taskinstance.py:340} INFO - ::group::Post task execution logs
[2025-01-26T09:06:12.929+0000] {standard_task_runner.py:124} ERROR - Failed to execute job 951 for task create_table (permission denied for schema public
LINE 2:     CREATE TABLE IF NOT EXISTS ebooks (
                                       ^
; 3697)
Traceback (most recent call last):
  File "/home/airflow/.local/lib/python3.12/site-packages/airflow/task/task_runner/standard_task_runner.py", line 117, in _start_by_fork
    ret = args.func(args, dag=self.dag)
          ^^^^^^^^^^^^^^^^^^^^^^^^^^^^^
  File "/home/airflow/.local/lib/python3.12/site-packages/airflow/cli/cli_config.py", line 49, in command
    return func(*args, **kwargs)
           ^^^^^^^^^^^^^^^^^^^^^
  File "/home/airflow/.local/lib/python3.12/site-packages/airflow/utils/cli.py", line 116, in wrapper
    return f(*args, **kwargs)
           ^^^^^^^^^^^^^^^^^^
  File "/home/airflow/.local/lib/python3.12/site-packages/airflow/cli/commands/task_command.py", line 483, in task_run
    task_return_code = _run_task_by_selected_method(args, _dag, ti)
                       ^^^^^^^^^^^^^^^^^^^^^^^^^^^^^^^^^^^^^^^^^^^^
  File "/home/airflow/.local/lib/python3.12/site-packages/airflow/cli/commands/task_command.py", line 256, in _run_task_by_selected_method
    return _run_raw_task(args, ti)
           ^^^^^^^^^^^^^^^^^^^^^^^
  File "/home/airflow/.local/lib/python3.12/site-packages/airflow/cli/commands/task_command.py", line 341, in _run_raw_task
    return ti._run_raw_task(
           ^^^^^^^^^^^^^^^^^
  File "/home/airflow/.local/lib/python3.12/site-packages/airflow/utils/session.py", line 97, in wrapper
    return func(*args, session=session, **kwargs)
           ^^^^^^^^^^^^^^^^^^^^^^^^^^^^^^^^^^^^^^
  File "/home/airflow/.local/lib/python3.12/site-packages/airflow/models/taskinstance.py", line 3005, in _run_raw_task
    return _run_raw_task(
           ^^^^^^^^^^^^^^
  File "/home/airflow/.local/lib/python3.12/site-packages/airflow/models/taskinstance.py", line 273, in _run_raw_task
    TaskInstance._execute_task_with_callbacks(
  File "/home/airflow/.local/lib/python3.12/site-packages/airflow/models/taskinstance.py", line 3159, in _execute_task_with_callbacks
    result = self._execute_task(context, task_orig)
             ^^^^^^^^^^^^^^^^^^^^^^^^^^^^^^^^^^^^^^
  File "/home/airflow/.local/lib/python3.12/site-packages/airflow/models/taskinstance.py", line 3183, in _execute_task
    return _execute_task(self, context, task_orig)
           ^^^^^^^^^^^^^^^^^^^^^^^^^^^^^^^^^^^^^^^
  File "/home/airflow/.local/lib/python3.12/site-packages/airflow/models/taskinstance.py", line 767, in _execute_task
    result = _execute_callable(context=context, **execute_callable_kwargs)
             ^^^^^^^^^^^^^^^^^^^^^^^^^^^^^^^^^^^^^^^^^^^^^^^^^^^^^^^^^^^^^
  File "/home/airflow/.local/lib/python3.12/site-packages/airflow/models/taskinstance.py", line 733, in _execute_callable
    return ExecutionCallableRunner(
           ^^^^^^^^^^^^^^^^^^^^^^^^
  File "/home/airflow/.local/lib/python3.12/site-packages/airflow/utils/operator_helpers.py", line 252, in run
    return self.func(*args, **kwargs)
           ^^^^^^^^^^^^^^^^^^^^^^^^^^
  File "/home/airflow/.local/lib/python3.12/site-packages/airflow/models/baseoperator.py", line 422, in wrapper
    return func(self, *args, **kwargs)
           ^^^^^^^^^^^^^^^^^^^^^^^^^^^
  File "/home/airflow/.local/lib/python3.12/site-packages/airflow/providers/common/sql/operators/sql.py", line 284, in execute
    output = hook.run(
             ^^^^^^^^^
  File "/home/airflow/.local/lib/python3.12/site-packages/airflow/providers/common/sql/hooks/sql.py", line 498, in run
    self._run_command(cur, sql_statement, parameters)
  File "/home/airflow/.local/lib/python3.12/site-packages/airflow/providers/common/sql/hooks/sql.py", line 558, in _run_command
    cur.execute(sql_statement)
psycopg2.errors.InsufficientPrivilege: permission denied for schema public
LINE 2:     CREATE TABLE IF NOT EXISTS ebooks (
                                       ^

[2025-01-26T09:06:13.026+0000] {local_task_job_runner.py:266} INFO - Task exited with return code 1
[2025-01-26T09:06:13.240+0000] {taskinstance.py:3895} INFO - 0 downstream tasks scheduled from follow-on schedule check
[2025-01-26T09:06:13.265+0000] {local_task_job_runner.py:245} INFO - ::endgroup::
[2025-01-26T09:27:40.491+0000] {local_task_job_runner.py:123} INFO - ::group::Pre task execution logs
[2025-01-26T09:27:40.970+0000] {taskinstance.py:2613} INFO - Dependencies all met for dep_context=non-requeueable deps ti=<TaskInstance: fetch_and_store_ebooks.create_table scheduled__2025-01-02T00:00:00+00:00 [queued]>
[2025-01-26T09:27:41.168+0000] {taskinstance.py:2613} INFO - Dependencies all met for dep_context=requeueable deps ti=<TaskInstance: fetch_and_store_ebooks.create_table scheduled__2025-01-02T00:00:00+00:00 [queued]>
[2025-01-26T09:27:41.177+0000] {taskinstance.py:2866} INFO - Starting attempt 1 of 2
[2025-01-26T09:27:41.530+0000] {taskinstance.py:2889} INFO - Executing <Task(PostgresOperator): create_table> on 2025-01-02 00:00:00+00:00
[2025-01-26T09:27:41.648+0000] {standard_task_runner.py:104} INFO - Running: ['***', 'tasks', 'run', 'fetch_and_store_ebooks', 'create_table', 'scheduled__2025-01-02T00:00:00+00:00', '--job-id', '1072', '--raw', '--subdir', 'DAGS_FOLDER/app.py', '--cfg-path', '/tmp/tmpcp5ehz9g']
[2025-01-26T09:27:41.698+0000] {standard_task_runner.py:105} INFO - Job 1072: Subtask create_table
[2025-01-26T09:27:41.646+0000] {warnings.py:112} WARNING - /home/***/.local/lib/python3.12/site-packages/***/task/task_runner/standard_task_runner.py:70: DeprecationWarning: This process (pid=4371) is multi-threaded, use of fork() may lead to deadlocks in the child.
  pid = os.fork()

[2025-01-26T09:27:41.722+0000] {standard_task_runner.py:72} INFO - Started process 4424 to run task
[2025-01-26T09:27:43.111+0000] {task_command.py:467} INFO - Running <TaskInstance: fetch_and_store_ebooks.create_table scheduled__2025-01-02T00:00:00+00:00 [running]> on host 34edd304782d
[2025-01-26T09:27:44.697+0000] {taskinstance.py:3132} INFO - Exporting env vars: AIRFLOW_CTX_DAG_OWNER='***' AIRFLOW_CTX_DAG_ID='fetch_and_store_ebooks' AIRFLOW_CTX_TASK_ID='create_table' AIRFLOW_CTX_EXECUTION_DATE='2025-01-02T00:00:00+00:00' AIRFLOW_CTX_TRY_NUMBER='1' AIRFLOW_CTX_DAG_RUN_ID='scheduled__2025-01-02T00:00:00+00:00'
[2025-01-26T09:27:44.713+0000] {logging_mixin.py:190} INFO - Task instance is in running state
[2025-01-26T09:27:44.715+0000] {logging_mixin.py:190} INFO -  Previous state of the Task instance: queued
[2025-01-26T09:27:44.720+0000] {logging_mixin.py:190} INFO - Current task name:create_table state:running start_date:2025-01-26 09:27:41.032192+00:00
[2025-01-26T09:27:44.724+0000] {logging_mixin.py:190} INFO - Dag name:fetch_and_store_ebooks and current dag run status:running
[2025-01-26T09:27:44.727+0000] {taskinstance.py:731} INFO - ::endgroup::
[2025-01-26T09:27:44.730+0000] {sql.py:278} INFO - Executing: 
    CREATE TABLE IF NOT EXISTS public.ebooks (
        id SERIAL PRIMARY KEY,
        judul TEXT NOT NULL,
        penulis TEXT,
        link TEXT
    );
    
[2025-01-26T09:27:44.819+0000] {base.py:84} INFO - Retrieving connection 'ebooks_connection'
[2025-01-26T09:27:44.942+0000] {base.py:84} INFO - Retrieving connection 'ebooks_connection'
[2025-01-26T09:27:45.212+0000] {sql.py:553} INFO - Running statement: 
    CREATE TABLE IF NOT EXISTS public.ebooks (
        id SERIAL PRIMARY KEY,
        judul TEXT NOT NULL,
        penulis TEXT,
        link TEXT
    );
    , parameters: None
[2025-01-26T09:27:45.417+0000] {taskinstance.py:340} INFO - ::group::Post task execution logs
[2025-01-26T09:27:45.429+0000] {taskinstance.py:352} INFO - Marking task as SUCCESS. dag_id=fetch_and_store_ebooks, task_id=create_table, run_id=scheduled__2025-01-02T00:00:00+00:00, execution_date=20250102T000000, start_date=20250126T092741, end_date=20250126T092745
[2025-01-26T09:27:45.597+0000] {logging_mixin.py:190} INFO - Task instance in success state
[2025-01-26T09:27:45.626+0000] {logging_mixin.py:190} INFO -  Previous state of the Task instance: running
[2025-01-26T09:27:45.640+0000] {logging_mixin.py:190} INFO - Dag name:fetch_and_store_ebooks queued_at:2025-01-26 09:26:14.800771+00:00
[2025-01-26T09:27:45.642+0000] {logging_mixin.py:190} INFO - Task hostname:34edd304782d operator:PostgresOperator
[2025-01-26T09:27:45.814+0000] {local_task_job_runner.py:266} INFO - Task exited with return code 0
[2025-01-26T09:27:45.973+0000] {taskinstance.py:3895} INFO - 1 downstream tasks scheduled from follow-on schedule check
[2025-01-26T09:27:46.002+0000] {local_task_job_runner.py:245} INFO - ::endgroup::
